Workbook
Name AgeRange: RetNorm_Engine!$C$3:INDEX(RetNorm_Engine!$C$3:$XFD$3, COUNTA(RetNorm_Engine!$C$3:$XFD$3))
Name buffer: Inputs!$B$159
Name ChartCash_Early: RetEarly_Engine!$C$201:INDEX(RetEarly_Engine!$C$201:$XFD$201, COUNTA(RetEarly_Engine!$C$201:$XFD$201))
Name ChartCash_Norm: RetNorm_Engine!$C$201:INDEX(RetNorm_Engine!$C$201:$XFD$201, COUNTA(RetNorm_Engine!$C$201:$XFD$201))
Name ChartNW_Early: RetEarly_Engine!$C$202:INDEX(RetEarly_Engine!$C$202:$XFD$202, COUNTA(RetEarly_Engine!$C$202:$XFD$202))
Name ChartNW_Norm: RetNorm_Engine!$C$202:INDEX(RetNorm_Engine!$C$202:$XFD$202, COUNTA(RetNorm_Engine!$C$202:$XFD$202))
Name EndAge: Inputs!$B$134
Name inf: Inputs!$B$145
Name princ: Inputs!$B$147
Name RetAge: Inputs!$B$19
Name rinc: Inputs!$B$155
Name sincr: Inputs!$B$153
Name stinc: Inputs!$B$151

Sheet Inputs
B1: User inputs | D1: User Tooltips | E1: UI Notes | F1: Excel helpers
A2: QUICK START
A4: Your age | B4: 47 | D4: Must be entered
A6: Current net annual income | B6: 60000 | D6: Net of tax, from employment or self-employment
A8: Total cash balances | B8: 200000 | D8: current and savings accounts, bonds, term deposits
A10: Stock market investments | B10: 50000 | D10: Current market value of equity portfolio
A12: Home current market value | B12: 500000 | D12: Leave blank if not a home owner
A14: Home loan (mortgage)
A15: Balance | B15: 120000 | D15: Leave blank if no mortgage | F15: Months remaining | G15: =IFERROR(NPER(B16/12,-B17,B15),"") -> 188.23636
A16: Interest rate | B16: 0.03 | F16: Years remaining | G16: =IFERROR(G15/12,"") -> 15.686363
A17: Monthly repayment | B17: 800
A19: Statutory retirement age | B19: 65 | D19: Year at which pension starts
A21: Annual pension at retirement | B21: 18000 | D21: Net annual state pension entitlement
A23: Housing rent | D23: if not a home owner | E23: show only if not a home owner (B12="")
A25: Annual living expenses | B25: 50000
A28: DEEPER DIVE | E28: Activated only if user wants to
A30: Dependents
A32: Dependent 1
A33: Name | D33: Leave blank if none
A34: Annual cost | D34: Food, education, healthcare, etc. | E34: Hide until user enters dependent name
A35: Years to support | D35: Years from now | E35: Hide until user enters dependent name
A37: Dependent 2
A38: Name | D38: Leave blank if none
A39: Annual cost | D39: Food, education, healthcare, etc. | E39: Hide until user enters dependent name
A40: Years to support | D40: Years from now | E40: Hide until user enters dependent name
A42: Dependent 3
A43: Name | D43: Leave blank if none
A44: Annual cost | D44: Food, education, healthcare, etc. | E44: Hide until user enters dependent name
A45: Years to support | D45: Years from now | E45: Hide until user enters dependent name
A47: Investment Properties
A49: Property 1
A50: Name | B50: Sliema | D50: Leave blank if none
A51: Market value | B51: 300000 | E51: Hide until user enters property name
A52: Annual costs | B52: 500 | D52: Repairs, maintenance, etc. | E52: Hide until user enters property name
A54: Property 2
A55: Name | D55: Leave blank if none
A56: Market value | E56: Hide until user enters property name
A57: Annual costs | D57: Repairs, maintenance, etc. | E57: Hide until user enters property name
A59: Property 3
A60: Name | D60: Leave blank if none
...

Sheet Output
V2: Retire at | AA2: ="Retire at "&RetEarly_Engine!B3 -> Retire at 59
V3: =RetEarly_Engine!B3 -> 59 | AA3: ="Retire at "&RetAge -> Retire at 65

Sheet RetNorm_Engine
B1: 0 | C1: 1 | D1: =C1+1 -> 2 | E1: =D1+1 -> 3 | F1: =E1+1 -> 4 | G1: =F1+1 -> 5 | H1: =G1+1 -> 6 | I1: =H1+1 -> 7 | J1: =I1+1 -> 8 | K1: =J1+1 -> 9 | ... AW1: =AV1+1 -> 47
B2: Year | C2: =YEAR(TODAY())+1 -> 2027 | D2: =C2+1 -> 2028 | E2: =D2+1 -> 2029 | F2: =E2+1 -> 2030 | G2: =F2+1 -> 2031 | H2: =G2+1 -> 2032 | I2: =H2+1 -> 2033 | J2: =I2+1 -> 2034 | K2: =J2+1 -> 2035 | ... AW2: =AV2+1 -> 2073
B3: =Inputs!B19 -> 65 | C3: =Inputs!B4+1 -> 48 | D3: =C3+1 -> 49 | E3: =D3+1 -> 50 | F3: =E3+1 -> 51 | G3: =F3+1 -> 52 | H3: =G3+1 -> 53 | I3: =H3+1 -> 54 | J3: =I3+1 -> 55 | K3: =J3+1 -> 56 | ... AW3: =AV3+1 -> 94
A4: Inflows
A5: Net employment / self-employment income | C5: =IF(AND(Inputs!$B$19>C3,$B$3>C3),Inputs!$B$6*(1+sincr)^B1,0) -> 60000 | D5: =IF(AND(Inputs!$B$19>D3,$B$3>D3),Inputs!$B$6*(1+sincr)^C1,0) -> 61800 | E5: =IF(AND(Inputs!$B$19>E3,$B$3>E3),Inputs!$B$6*(1+sincr)^D1,0) -> 63654 | F5: =IF(AND(Inputs!$B$19>F3,$B$3>F3),Inputs!$B$6*(1+sincr)^E1,0) -> 65563.62 | G5: =IF(AND(Inputs!$B$19>G3,$B$3>G3),Inputs!$B$6*(1+sincr)^F1,0) -> 67530.529 | H5: =IF(AND(Inputs!$B$19>H3,$B$3>H3),Inputs!$B$6*(1+sincr)^G1,0) -> 69556.444 | I5: =IF(AND(Inputs!$B$19>I3,$B$3>I3),Inputs!$B$6*(1+sincr)^H1,0) -> 71643.138 | J5: =IF(AND(Inputs!$B$19>J3,$B$3>J3),Inputs!$B$6*(1+sincr)^I1,0) -> 73792.432 | ... AW5: =IF(AND(Inputs!$B$19>AW3,$B$3>AW3),Inputs!$B$6*(1+sincr)^AV1,0) -> 0
A6: Net from other work | C6: =IF(C$3<=Inputs!$B$71,Inputs!$B$70,0)*(1+inf)^B$1 -> 0 | D6: =IF(D$3<=Inputs!$B$71,Inputs!$B$70,0)*(1+inf)^C$1 -> 0 | E6: =IF(E$3<=Inputs!$B$71,Inputs!$B$70,0)*(1+inf)^D$1 -> 0 | F6: =IF(F$3<=Inputs!$B$71,Inputs!$B$70,0)*(1+inf)^E$1 -> 0 | G6: =IF(G$3<=Inputs!$B$71,Inputs!$B$70,0)*(1+inf)^F$1 -> 0 | H6: =IF(H$3<=Inputs!$B$71,Inputs!$B$70,0)*(1+inf)^G$1 -> 0 | I6: =IF(I$3<=Inputs!$B$71,Inputs!$B$70,0)*(1+inf)^H$1 -> 0 | J6: =IF(J$3<=Inputs!$B$71,Inputs!$B$70,0)*(1+inf)^I$1 -> 0 | ... AW6: =IF(AW$3<=Inputs!$B$71,Inputs!$B$70,0)*(1+inf)^AV$1 -> 0
A7: Net rental income from other properties
A8: =TEXT(Inputs!$B$50,"") -> Sliema | C8: =Inputs!B66 -> 0 | D8: =C8*(1+rinc) -> 0 | E8: =D8*(1+rinc) -> 0 | F8: =E8*(1+rinc) -> 0 | G8: =F8*(1+rinc) -> 0 | H8: =G8*(1+rinc) -> 0 | I8: =H8*(1+rinc) -> 0 | J8: =I8*(1+rinc) -> 0 | K8: =J8*(1+rinc) -> 0 | ... AW8: =AV8*(1+rinc) -> 0
A9: =TEXT(Inputs!$B$55,"") | C9: =Inputs!B67 -> 0 | D9: =C9*(1+rinc) -> 0 | E9: =D9*(1+rinc) -> 0 | F9: =E9*(1+rinc) -> 0 | G9: =F9*(1+rinc) -> 0 | H9: =G9*(1+rinc) -> 0 | I9: =H9*(1+rinc) -> 0 | J9: =I9*(1+rinc) -> 0 | K9: =J9*(1+rinc) -> 0 | ... AW9: =AV9*(1+rinc) -> 0
A10: =TEXT(Inputs!$B$60,"") | C10: =Inputs!B68 -> 0 | D10: =C10*(1+rinc) -> 0 | E10: =D10*(1+rinc) -> 0 | F10: =E10*(1+rinc) -> 0 | G10: =F10*(1+rinc) -> 0 | H10: =G10*(1+rinc) -> 0 | I10: =H10*(1+rinc) -> 0 | J10: =I10*(1+rinc) -> 0 | K10: =J10*(1+rinc) -> 0 | ... AW10: =AV10*(1+rinc) -> 0
A11: Full pension | C11: =IF(C$3<Inputs!$B$19,0,Inputs!$B$21)*(1+inf)^B$1 -> 0 | D11: =IF(D$3<Inputs!$B$19,0,Inputs!$B$21)*(1+inf)^C$1 -> 0 | E11: =IF(E$3<Inputs!$B$19,0,Inputs!$B$21)*(1+inf)^D$1 -> 0 | F11: =IF(F$3<Inputs!$B$19,0,Inputs!$B$21)*(1+inf)^E$1 -> 0 | G11: =IF(G$3<Inputs!$B$19,0,Inputs!$B$21)*(1+inf)^F$1 -> 0 | H11: =IF(H$3<Inputs!$B$19,0,Inputs!$B$21)*(1+inf)^G$1 -> 0 | I11: =IF(I$3<Inputs!$B$19,0,Inputs!$B$21)*(1+inf)^H$1 -> 0 | J11: =IF(J$3<Inputs!$B$19,0,Inputs!$B$21)*(1+inf)^I$1 -> 0 | ... AW11: =IF(AW$3<Inputs!$B$19,0,Inputs!$B$21)*(1+inf)^AV$1 -> 56049.315
A12: Pension reduction from early retirement | C12: =MIN(0,MAX(-IF(C11=0,0,(Inputs!$B$19-INDEX(3:3,MATCH(0,5:5,0))))*Inputs!$B$157*(1+inf)^B$1,-C11)) -> 0 | D12: =MIN(0,MAX(-IF(D11=0,0,(Inputs!$B$19-INDEX(3:3,MATCH(0,5:5,0))))*Inputs!$B$157*(1+inf)^C$1,-D11)) -> 0 | E12: =MIN(0,MAX(-IF(E11=0,0,(Inputs!$B$19-INDEX(3:3,MATCH(0,5:5,0))))*Inputs!$B$157*(1+inf)^D$1,-E11)) -> 0 | F12: =MIN(0,MAX(-IF(F11=0,0,(Inputs!$B$19-INDEX(3:3,MATCH(0,5:5,0))))*Inputs!$B$157*(1+inf)^E$1,-F11)) -> 0 | G12: =MIN(0,MAX(-IF(G11=0,0,(Inputs!$B$19-INDEX(3:3,MATCH(0,5:5,0))))*Inputs!$B$157*(1+inf)^F$1,-G11)) -> 0 | H12: =MIN(0,MAX(-IF(H11=0,0,(Inputs!$B$19-INDEX(3:3,MATCH(0,5:5,0))))*Inputs!$B$157*(1+inf)^G$1,-H11)) -> 0 | I12: =MIN(0,MAX(-IF(I11=0,0,(Inputs!$B$19-INDEX(3:3,MATCH(0,5:5,0))))*Inputs!$B$157*(1+inf)^H$1,-I11)) -> 0 | J12: =MIN(0,MAX(-IF(J11=0,0,(Inputs!$B$19-INDEX(3:3,MATCH(0,5:5,0))))*Inputs!$B$157*(1+inf)^I$1,-J11)) -> 0 | ... AW12: =MIN(0,MAX(-IF(AW11=0,0,(Inputs!$B$19-INDEX(3:3,MATCH(0,5:5,0))))*Inputs!$B$157*(1+inf)^AV$1,-AW11)) -> 0
A13: Other post-retirement income | C13: =IF(AND(C$3>=Inputs!$B$142,C$3<=Inputs!$B$143),Inputs!$B$141*(1+inf)^B$1,0) -> 0 | D13: =IF(AND(D$3>=Inputs!$B$142,D$3<=Inputs!$B$143),Inputs!$B$141*(1+inf)^C$1,0) -> 0 | E13: =IF(AND(E$3>=Inputs!$B$142,E$3<=Inputs!$B$143),Inputs!$B$141*(1+inf)^D$1,0) -> 0 | F13: =IF(AND(F$3>=Inputs!$B$142,F$3<=Inputs!$B$143),Inputs!$B$141*(1+inf)^E$1,0) -> 0 | G13: =IF(AND(G$3>=Inputs!$B$142,G$3<=Inputs!$B$143),Inputs!$B$141*(1+inf)^F$1,0) -> 0 | H13: =IF(AND(H$3>=Inputs!$B$142,H$3<=Inputs!$B$143),Inputs!$B$141*(1+inf)^G$1,0) -> 0 | I13: =IF(AND(I$3>=Inputs!$B$142,I$3<=Inputs!$B$143),Inputs!$B$141*(1+inf)^H$1,0) -> 0 | J13: =IF(AND(J$3>=Inputs!$B$142,J$3<=Inputs!$B$143),Inputs!$B$141*(1+inf)^I$1,0) -> 0 | ... AW13: =IF(AND(AW$3>=Inputs!$B$142,AW$3<=Inputs!$B$143),Inputs!$B$141*(1+inf)^AV$1,0) -> 0
A14: Major one-off income events
A15: =TEXT(Inputs!B100,"") | C15: =IF(C$2=Inputs!$B102,Inputs!$B101,0)*(1+inf)^B$1 -> 0 | D15: =IF(D$2=Inputs!$B102,Inputs!$B101,0)*(1+inf)^C$1 -> 0 | E15: =IF(E$2=Inputs!$B102,Inputs!$B101,0)*(1+inf)^D$1 -> 0 | F15: =IF(F$2=Inputs!$B102,Inputs!$B101,0)*(1+inf)^E$1 -> 0 | G15: =IF(G$2=Inputs!$B102,Inputs!$B101,0)*(1+inf)^F$1 -> 0 | H15: =IF(H$2=Inputs!$B102,Inputs!$B101,0)*(1+inf)^G$1 -> 0 | I15: =IF(I$2=Inputs!$B102,Inputs!$B101,0)*(1+inf)^H$1 -> 0 | J15: =IF(J$2=Inputs!$B102,Inputs!$B101,0)*(1+inf)^I$1 -> 0 | ... AW15: =IF(AW$2=Inputs!$B102,Inputs!$B101,0)*(1+inf)^AV$1 -> 0
A16: =TEXT(Inputs!B105,"") | C16: =IF(C$2=Inputs!$B107,Inputs!$B106,0)*(1+inf)^B$1 -> 0 | D16: =IF(D$2=Inputs!$B107,Inputs!$B106,0)*(1+inf)^C$1 -> 0 | E16: =IF(E$2=Inputs!$B107,Inputs!$B106,0)*(1+inf)^D$1 -> 0 | F16: =IF(F$2=Inputs!$B107,Inputs!$B106,0)*(1+inf)^E$1 -> 0 | G16: =IF(G$2=Inputs!$B107,Inputs!$B106,0)*(1+inf)^F$1 -> 0 | H16: =IF(H$2=Inputs!$B107,Inputs!$B106,0)*(1+inf)^G$1 -> 0 | I16: =IF(I$2=Inputs!$B107,Inputs!$B106,0)*(1+inf)^H$1 -> 0 | J16: =IF(J$2=Inputs!$B107,Inputs!$B106,0)*(1+inf)^I$1 -> 0 | ... AW16: =IF(AW$2=Inputs!$B107,Inputs!$B106,0)*(1+inf)^AV$1 -> 0
A17: =TEXT(Inputs!B110,"") | C17: =IF(C$2=Inputs!$B112,Inputs!$B111,0)*(1+inf)^B$1 -> 0 | D17: =IF(D$2=Inputs!$B112,Inputs!$B111,0)*(1+inf)^C$1 -> 0 | E17: =IF(E$2=Inputs!$B112,Inputs!$B111,0)*(1+inf)^D$1 -> 0 | F17: =IF(F$2=Inputs!$B112,Inputs!$B111,0)*(1+inf)^E$1 -> 0 | G17: =IF(G$2=Inputs!$B112,Inputs!$B111,0)*(1+inf)^F$1 -> 0 | H17: =IF(H$2=Inputs!$B112,Inputs!$B111,0)*(1+inf)^G$1 -> 0 | I17: =IF(I$2=Inputs!$B112,Inputs!$B111,0)*(1+inf)^H$1 -> 0 | J17: =IF(J$2=Inputs!$B112,Inputs!$B111,0)*(1+inf)^I$1 -> 0 | ... AW17: =IF(AW$2=Inputs!$B112,Inputs!$B111,0)*(1+inf)^AV$1 -> 0
A18: Interest on cash balances | C18: =MAX(AVERAGE(C49,C49+SUM(C5:C17)-C46)*Inputs!$B$149,0) -> 4998.75 | D18: =MAX(AVERAGE(D49,D49+SUM(D5:D17)-D46)*Inputs!$B$149,0) -> 5127.9375 | E18: =MAX(AVERAGE(E49,E49+SUM(E5:E17)-E46)*Inputs!$B$149,0) -> 5274.0727 | F18: =MAX(AVERAGE(F49,F49+SUM(F5:F17)-F46)*Inputs!$B$149,0) -> 5438.1505 | G18: =MAX(AVERAGE(G49,G49+SUM(G5:G17)-G46)*Inputs!$B$149,0) -> 5621.212 | H18: =MAX(AVERAGE(H49,H49+SUM(H5:H17)-H46)*Inputs!$B$149,0) -> 5824.3462 | I18: =MAX(AVERAGE(I49,I49+SUM(I5:I17)-I46)*Inputs!$B$149,0) -> 6048.6917 | J18: =MAX(AVERAGE(J49,J49+SUM(J5:J17)-J46)*Inputs!$B$149,0) -> 6295.4392 | ... AW18: =MAX(AVERAGE(AW49,AW49+SUM(AW5:AW17)-AW46)*Inputs!$B$149,0) -> 0
C19: =SUM(C4:C18) -> 64998.75 | D19: =SUM(D4:D18) -> 66927.938 | E19: =SUM(E4:E18) -> 68928.073 | F19: =SUM(F4:F18) -> 71001.77 | G19: =SUM(G4:G18) -> 73151.741 | H19: =SUM(H4:H18) -> 75380.791 | I19: =SUM(I4:I18) -> 77691.829 | J19: =SUM(J4:J18) -> 80087.871 | ... AW19: =SUM(AW4:AW18) -> 56049.315
A20: Outflows
A21: Credit cards cleared | C21: =Inputs!B75 -> 0 | D21: 0 | E21: 0 | F21: 0 | G21: 0 | H21: 0 | I21: 0 | J21: 0 | K21: 0 | L21: 0 | M21: 0 | N21: 0 | O21: 0 | P21: 0 | Q21: 0 | R21: 0 | S21: 0 | T21: 0 | U21: 0 | V21: 0 | W21: 0 | X21: 0 | Y21: 0 | Z21: 0 | AA21: 0 | AB21: 0 | AC21: 0 | AD21: 0 | AE21: 0 | AF21: 0 | AG21: 0 | AH21: 0 | AI21: 0 | AJ21: 0 | AK21: 0 | AL21: 0 | AM21: 0 | AN21: 0 | AO21: 0 | AP21: 0 | AQ21: 0 | AR21: 0 | AS21: 0 | AT21: 0 | AU21: 0 | AV21: 0 | AW21: 0
A22: Home loan repayment | C22: =MAX(IF(C$1*12<=Inputs!$G$15,12,(Inputs!$G$15-B$1*12)),0)*Inputs!$B$17 -> 9600 | D22: =MAX(IF(D$1*12<=Inputs!$G$15,12,(Inputs!$G$15-C$1*12)),0)*Inputs!$B$17 -> 9600 | E22: =MAX(IF(E$1*12<=Inputs!$G$15,12,(Inputs!$G$15-D$1*12)),0)*Inputs!$B$17 -> 9600 | F22: =MAX(IF(F$1*12<=Inputs!$G$15,12,(Inputs!$G$15-E$1*12)),0)*Inputs!$B$17 -> 9600 | G22: =MAX(IF(G$1*12<=Inputs!$G$15,12,(Inputs!$G$15-F$1*12)),0)*Inputs!$B$17 -> 9600 | H22: =MAX(IF(H$1*12<=Inputs!$G$15,12,(Inputs!$G$15-G$1*12)),0)*Inputs!$B$17 -> 9600 | I22: =MAX(IF(I$1*12<=Inputs!$G$15,12,(Inputs!$G$15-H$1*12)),0)*Inputs!$B$17 -> 9600 | J22: =MAX(IF(J$1*12<=Inputs!$G$15,12,(Inputs!$G$15-I$1*12)),0)*Inputs!$B$17 -> 9600 | ... AW22: =MAX(IF(AW$1*12<=Inputs!$G$15,12,(Inputs!$G$15-AV$1*12)),0)*Inputs!$B$17 -> 0
A23: Other property loans repayments
A24: =TEXT(Inputs!$B$50,"") -> Sliema | C24: =MAX(IF(C$1*12<=Inputs!$G$78,12,(Inputs!$G$78-B$1*12)),0)*Inputs!$B$80 -> 0 | D24: =MAX(IF(D$1*12<=Inputs!$G$78,12,(Inputs!$G$78-C$1*12)),0)*Inputs!$B$80 -> 0 | E24: =MAX(IF(E$1*12<=Inputs!$G$78,12,(Inputs!$G$78-D$1*12)),0)*Inputs!$B$80 -> 0 | F24: =MAX(IF(F$1*12<=Inputs!$G$78,12,(Inputs!$G$78-E$1*12)),0)*Inputs!$B$80 -> 0 | G24: =MAX(IF(G$1*12<=Inputs!$G$78,12,(Inputs!$G$78-F$1*12)),0)*Inputs!$B$80 -> 0 | H24: =MAX(IF(H$1*12<=Inputs!$G$78,12,(Inputs!$G$78-G$1*12)),0)*Inputs!$B$80 -> 0 | I24: =MAX(IF(I$1*12<=Inputs!$G$78,12,(Inputs!$G$78-H$1*12)),0)*Inputs!$B$80 -> 0 | J24: =MAX(IF(J$1*12<=Inputs!$G$78,12,(Inputs!$G$78-I$1*12)),0)*Inputs!$B$80 -> 0 | ... AW24: =MAX(IF(AW$1*12<=Inputs!$G$78,12,(Inputs!$G$78-AV$1*12)),0)*Inputs!$B$80 -> 0
A25: =TEXT(Inputs!$B$55,"") | C25: =MAX(IF(C$1*12<=Inputs!$G$83,12,(Inputs!$G$83-B$1*12)),0)*Inputs!$B$85 -> 0 | D25: =MAX(IF(D$1*12<=Inputs!$G$83,12,(Inputs!$G$83-C$1*12)),0)*Inputs!$B$85 -> 0 | E25: =MAX(IF(E$1*12<=Inputs!$G$83,12,(Inputs!$G$83-D$1*12)),0)*Inputs!$B$85 -> 0 | F25: =MAX(IF(F$1*12<=Inputs!$G$83,12,(Inputs!$G$83-E$1*12)),0)*Inputs!$B$85 -> 0 | G25: =MAX(IF(G$1*12<=Inputs!$G$83,12,(Inputs!$G$83-F$1*12)),0)*Inputs!$B$85 -> 0 | H25: =MAX(IF(H$1*12<=Inputs!$G$83,12,(Inputs!$G$83-G$1*12)),0)*Inputs!$B$85 -> 0 | I25: =MAX(IF(I$1*12<=Inputs!$G$83,12,(Inputs!$G$83-H$1*12)),0)*Inputs!$B$85 -> 0 | J25: =MAX(IF(J$1*12<=Inputs!$G$83,12,(Inputs!$G$83-I$1*12)),0)*Inputs!$B$85 -> 0 | ... AW25: =MAX(IF(AW$1*12<=Inputs!$G$83,12,(Inputs!$G$83-AV$1*12)),0)*Inputs!$B$85 -> 0
A26: =TEXT(Inputs!$B$60,"") | C26: =MAX(IF(C$1*12<=Inputs!$G$88,12,(Inputs!$G$88-B$1*12)),0)*Inputs!$B$90 -> 0 | D26: =MAX(IF(D$1*12<=Inputs!$G$88,12,(Inputs!$G$88-C$1*12)),0)*Inputs!$B$90 -> 0 | E26: =MAX(IF(E$1*12<=Inputs!$G$88,12,(Inputs!$G$88-D$1*12)),0)*Inputs!$B$90 -> 0 | F26: =MAX(IF(F$1*12<=Inputs!$G$88,12,(Inputs!$G$88-E$1*12)),0)*Inputs!$B$90 -> 0 | G26: =MAX(IF(G$1*12<=Inputs!$G$88,12,(Inputs!$G$88-F$1*12)),0)*Inputs!$B$90 -> 0 | H26: =MAX(IF(H$1*12<=Inputs!$G$88,12,(Inputs!$G$88-G$1*12)),0)*Inputs!$B$90 -> 0 | I26: =MAX(IF(I$1*12<=Inputs!$G$88,12,(Inputs!$G$88-H$1*12)),0)*Inputs!$B$90 -> 0 | J26: =MAX(IF(J$1*12<=Inputs!$G$88,12,(Inputs!$G$88-I$1*12)),0)*Inputs!$B$90 -> 0 | ... AW26: =MAX(IF(AW$1*12<=Inputs!$G$88,12,(Inputs!$G$88-AV$1*12)),0)*Inputs!$B$90 -> 0
A27: Other loan repayment | C27: =MAX(IF(C$1*12<=Inputs!$G$93,12,(Inputs!$G$93-B$1*12)),0)*Inputs!$B$95 -> 0 | D27: =MAX(IF(D$1*12<=Inputs!$G$93,12,(Inputs!$G$93-C$1*12)),0)*Inputs!$B$95 -> 0 | E27: =MAX(IF(E$1*12<=Inputs!$G$93,12,(Inputs!$G$93-D$1*12)),0)*Inputs!$B$95 -> 0 | F27: =MAX(IF(F$1*12<=Inputs!$G$93,12,(Inputs!$G$93-E$1*12)),0)*Inputs!$B$95 -> 0 | G27: =MAX(IF(G$1*12<=Inputs!$G$93,12,(Inputs!$G$93-F$1*12)),0)*Inputs!$B$95 -> 0 | H27: =MAX(IF(H$1*12<=Inputs!$G$93,12,(Inputs!$G$93-G$1*12)),0)*Inputs!$B$95 -> 0 | I27: =MAX(IF(I$1*12<=Inputs!$G$93,12,(Inputs!$G$93-H$1*12)),0)*Inputs!$B$95 -> 0 | J27: =MAX(IF(J$1*12<=Inputs!$G$93,12,(Inputs!$G$93-I$1*12)),0)*Inputs!$B$95 -> 0 | ... AW27: =MAX(IF(AW$1*12<=Inputs!$G$93,12,(Inputs!$G$93-AV$1*12)),0)*Inputs!$B$95 -> 0
A28: Dependents cost
A29: =TEXT(Inputs!B33,"") | C29: =IF(Inputs!$B$35>=C$1,Inputs!$B$34,0)*(1+inf)^B$1 -> 0 | D29: =IF(Inputs!$B$35>=D$1,Inputs!$B$34,0)*(1+inf)^C$1 -> 0 | E29: =IF(Inputs!$B$35>=E$1,Inputs!$B$34,0)*(1+inf)^D$1 -> 0 | F29: =IF(Inputs!$B$35>=F$1,Inputs!$B$34,0)*(1+inf)^E$1 -> 0 | G29: =IF(Inputs!$B$35>=G$1,Inputs!$B$34,0)*(1+inf)^F$1 -> 0 | H29: =IF(Inputs!$B$35>=H$1,Inputs!$B$34,0)*(1+inf)^G$1 -> 0 | I29: =IF(Inputs!$B$35>=I$1,Inputs!$B$34,0)*(1+inf)^H$1 -> 0 | J29: =IF(Inputs!$B$35>=J$1,Inputs!$B$34,0)*(1+inf)^I$1 -> 0 | ... AW29: =IF(Inputs!$B$35>=AW$1,Inputs!$B$34,0)*(1+inf)^AV$1 -> 0
A30: =TEXT(Inputs!B38,"") | C30: =IF(Inputs!$B$40>=C$1,Inputs!$B$39,0)*(1+inf)^B$1 -> 0 | D30: =IF(Inputs!$B$40>=D$1,Inputs!$B$39,0)*(1+inf)^C$1 -> 0 | E30: =IF(Inputs!$B$40>=E$1,Inputs!$B$39,0)*(1+inf)^D$1 -> 0 | F30: =IF(Inputs!$B$40>=F$1,Inputs!$B$39,0)*(1+inf)^E$1 -> 0 | G30: =IF(Inputs!$B$40>=G$1,Inputs!$B$39,0)*(1+inf)^F$1 -> 0 | H30: =IF(Inputs!$B$40>=H$1,Inputs!$B$39,0)*(1+inf)^G$1 -> 0 | I30: =IF(Inputs!$B$40>=I$1,Inputs!$B$39,0)*(1+inf)^H$1 -> 0 | J30: =IF(Inputs!$B$40>=J$1,Inputs!$B$39,0)*(1+inf)^I$1 -> 0 | ... AW30: =IF(Inputs!$B$40>=AW$1,Inputs!$B$39,0)*(1+inf)^AV$1 -> 0
A31: =TEXT(Inputs!B43,"") | C31: =IF(Inputs!$B$45>=C$1,Inputs!$B$44,0)*(1+inf)^B$1 -> 0 | D31: =IF(Inputs!$B$45>=D$1,Inputs!$B$44,0)*(1+inf)^C$1 -> 0 | E31: =IF(Inputs!$B$45>=E$1,Inputs!$B$44,0)*(1+inf)^D$1 -> 0 | F31: =IF(Inputs!$B$45>=F$1,Inputs!$B$44,0)*(1+inf)^E$1 -> 0 | G31: =IF(Inputs!$B$45>=G$1,Inputs!$B$44,0)*(1+inf)^F$1 -> 0 | H31: =IF(Inputs!$B$45>=H$1,Inputs!$B$44,0)*(1+inf)^G$1 -> 0 | I31: =IF(Inputs!$B$45>=I$1,Inputs!$B$44,0)*(1+inf)^H$1 -> 0 | J31: =IF(Inputs!$B$45>=J$1,Inputs!$B$44,0)*(1+inf)^I$1 -> 0 | ... AW31: =IF(Inputs!$B$45>=AW$1,Inputs!$B$44,0)*(1+inf)^AV$1 -> 0
A32: Housing rent | C32: =Inputs!$B$23*(1+inf)^B$1 -> 0 | D32: =Inputs!$B$23*(1+inf)^C$1 -> 0 | E32: =Inputs!$B$23*(1+inf)^D$1 -> 0 | F32: =Inputs!$B$23*(1+inf)^E$1 -> 0 | G32: =Inputs!$B$23*(1+inf)^F$1 -> 0 | H32: =Inputs!$B$23*(1+inf)^G$1 -> 0 | I32: =Inputs!$B$23*(1+inf)^H$1 -> 0 | J32: =Inputs!$B$23*(1+inf)^I$1 -> 0 | ... AW32: =Inputs!$B$23*(1+inf)^AV$1 -> 0
A33: Other property costs
A34: =TEXT(Inputs!$B$50,"") -> Sliema | C34: =Inputs!$B52*(1+inf)^B$1 -> 500 | D34: =Inputs!$B52*(1+inf)^C$1 -> 512.5 | E34: =Inputs!$B52*(1+inf)^D$1 -> 525.3125 | F34: =Inputs!$B52*(1+inf)^E$1 -> 538.44531 | G34: =Inputs!$B52*(1+inf)^F$1 -> 551.90645 | H34: =Inputs!$B52*(1+inf)^G$1 -> 565.70411 | I34: =Inputs!$B52*(1+inf)^H$1 -> 579.84671 | J34: =Inputs!$B52*(1+inf)^I$1 -> 594.34288 | ... AW34: =Inputs!$B52*(1+inf)^AV$1 -> 1556.9254
A35: =TEXT(Inputs!$B$55,"") | C35: =Inputs!$B57*(1+inf)^B$1 -> 0 | D35: =Inputs!$B57*(1+inf)^C$1 -> 0 | E35: =Inputs!$B57*(1+inf)^D$1 -> 0 | F35: =Inputs!$B57*(1+inf)^E$1 -> 0 | G35: =Inputs!$B57*(1+inf)^F$1 -> 0 | H35: =Inputs!$B57*(1+inf)^G$1 -> 0 | I35: =Inputs!$B57*(1+inf)^H$1 -> 0 | J35: =Inputs!$B57*(1+inf)^I$1 -> 0 | ... AW35: =Inputs!$B57*(1+inf)^AV$1 -> 0
A36: =TEXT(Inputs!$B$60,"") | C36: =Inputs!$B62*(1+inf)^B$1 -> 0 | D36: =Inputs!$B62*(1+inf)^C$1 -> 0 | E36: =Inputs!$B62*(1+inf)^D$1 -> 0 | F36: =Inputs!$B62*(1+inf)^E$1 -> 0 | G36: =Inputs!$B62*(1+inf)^F$1 -> 0 | H36: =Inputs!$B62*(1+inf)^G$1 -> 0 | I36: =Inputs!$B62*(1+inf)^H$1 -> 0 | J36: =Inputs!$B62*(1+inf)^I$1 -> 0 | ... AW36: =Inputs!$B62*(1+inf)^AV$1 -> 0
A37: Living expenses
A38: Current baseline | C38: =Inputs!$B$25*(1+inf)^B$1 -> 50000 | D38: =Inputs!$B$25*(1+inf)^C$1 -> 51250 | E38: =Inputs!$B$25*(1+inf)^D$1 -> 52531.25 | F38: =Inputs!$B$25*(1+inf)^E$1 -> 53844.531 | G38: =Inputs!$B$25*(1+inf)^F$1 -> 55190.645 | H38: =Inputs!$B$25*(1+inf)^G$1 -> 56570.411 | I38: =Inputs!$B$25*(1+inf)^H$1 -> 57984.671 | J38: =Inputs!$B$25*(1+inf)^I$1 -> 59434.288 | ... AW38: =Inputs!$B$25*(1+inf)^AV$1 -> 155692.54
A39: ="Adjustment "&Inputs!A137 -> Adjustment from now to 65 | C39: =IF(C$3<=65,Inputs!$B$137*C$38,0) -> 0 | D39: =IF(D$3<=65,Inputs!$B$137*D$38,0) -> 0 | E39: =IF(E$3<=65,Inputs!$B$137*E$38,0) -> 0 | F39: =IF(F$3<=65,Inputs!$B$137*F$38,0) -> 0 | G39: =IF(G$3<=65,Inputs!$B$137*G$38,0) -> 0 | H39: =IF(H$3<=65,Inputs!$B$137*H$38,0) -> 0 | I39: =IF(I$3<=65,Inputs!$B$137*I$38,0) -> 0 | J39: =IF(J$3<=65,Inputs!$B$137*J$38,0) -> 0 | ... AW39: =IF(AW$3<=65,Inputs!$B$137*AW$38,0) -> 0
A40: ="Adjustment "&Inputs!A138 -> Adjustment from 66-75 | C40: =IF(AND(C$3>65,C$3<=75),Inputs!$B$138*C38,0) -> 0 | D40: =IF(AND(D$3>65,D$3<=75),Inputs!$B$138*D38,0) -> 0 | E40: =IF(AND(E$3>65,E$3<=75),Inputs!$B$138*E38,0) -> 0 | F40: =IF(AND(F$3>65,F$3<=75),Inputs!$B$138*F38,0) -> 0 | G40: =IF(AND(G$3>65,G$3<=75),Inputs!$B$138*G38,0) -> 0 | H40: =IF(AND(H$3>65,H$3<=75),Inputs!$B$138*H38,0) -> 0 | I40: =IF(AND(I$3>65,I$3<=75),Inputs!$B$138*I38,0) -> 0 | J40: =IF(AND(J$3>65,J$3<=75),Inputs!$B$138*J38,0) -> 0 | ... AW40: =IF(AND(AW$3>65,AW$3<=75),Inputs!$B$138*AW38,0) -> 0
...

Sheet RetEarly_Engine
B1: 0 | C1: 1 | D1: =C1+1 -> 2 | E1: =D1+1 -> 3 | F1: =E1+1 -> 4 | G1: =F1+1 -> 5 | H1: =G1+1 -> 6 | I1: =H1+1 -> 7 | J1: =I1+1 -> 8 | K1: =J1+1 -> 9 | ... AW1: =AV1+1 -> 47
B2: Year | C2: =YEAR(TODAY())+1 -> 2027 | D2: =C2+1 -> 2028 | E2: =D2+1 -> 2029 | F2: =E2+1 -> 2030 | G2: =F2+1 -> 2031 | H2: =G2+1 -> 2032 | I2: =H2+1 -> 2033 | J2: =I2+1 -> 2034 | K2: =J2+1 -> 2035 | ... AW2: =AV2+1 -> 2073
B3: 59 | C3: =Inputs!B4+1 -> 48 | D3: =C3+1 -> 49 | E3: =D3+1 -> 50 | F3: =E3+1 -> 51 | G3: =F3+1 -> 52 | H3: =G3+1 -> 53 | I3: =H3+1 -> 54 | J3: =I3+1 -> 55 | K3: =J3+1 -> 56 | ... AW3: =AV3+1 -> 94
A4: Inflows
A5: Net employment / self-employment income | C5: =IF(AND(Inputs!$B$19>C3,$B$3>C3),Inputs!$B$6*(1+sincr)^B1,0) -> 60000 | D5: =IF(AND(Inputs!$B$19>D3,$B$3>D3),Inputs!$B$6*(1+sincr)^C1,0) -> 61800 | E5: =IF(AND(Inputs!$B$19>E3,$B$3>E3),Inputs!$B$6*(1+sincr)^D1,0) -> 63654 | F5: =IF(AND(Inputs!$B$19>F3,$B$3>F3),Inputs!$B$6*(1+sincr)^E1,0) -> 65563.62 | G5: =IF(AND(Inputs!$B$19>G3,$B$3>G3),Inputs!$B$6*(1+sincr)^F1,0) -> 67530.529 | H5: =IF(AND(Inputs!$B$19>H3,$B$3>H3),Inputs!$B$6*(1+sincr)^G1,0) -> 69556.444 | I5: =IF(AND(Inputs!$B$19>I3,$B$3>I3),Inputs!$B$6*(1+sincr)^H1,0) -> 71643.138 | J5: =IF(AND(Inputs!$B$19>J3,$B$3>J3),Inputs!$B$6*(1+sincr)^I1,0) -> 73792.432 | ... AW5: =IF(AND(Inputs!$B$19>AW3,$B$3>AW3),Inputs!$B$6*(1+sincr)^AV1,0) -> 0
A6: Net from other work | C6: =IF(C$3<=Inputs!$B$71,Inputs!$B$70,0)*(1+inf)^B$1 -> 0 | D6: =IF(D$3<=Inputs!$B$71,Inputs!$B$70,0)*(1+inf)^C$1 -> 0 | E6: =IF(E$3<=Inputs!$B$71,Inputs!$B$70,0)*(1+inf)^D$1 -> 0 | F6: =IF(F$3<=Inputs!$B$71,Inputs!$B$70,0)*(1+inf)^E$1 -> 0 | G6: =IF(G$3<=Inputs!$B$71,Inputs!$B$70,0)*(1+inf)^F$1 -> 0 | H6: =IF(H$3<=Inputs!$B$71,Inputs!$B$70,0)*(1+inf)^G$1 -> 0 | I6: =IF(I$3<=Inputs!$B$71,Inputs!$B$70,0)*(1+inf)^H$1 -> 0 | J6: =IF(J$3<=Inputs!$B$71,Inputs!$B$70,0)*(1+inf)^I$1 -> 0 | ... AW6: =IF(AW$3<=Inputs!$B$71,Inputs!$B$70,0)*(1+inf)^AV$1 -> 0
A7: Net rental income from other properties
A8: =TEXT(Inputs!$B$50,"") -> Sliema | C8: =Inputs!B66 -> 0 | D8: =C8*(1+rinc) -> 0 | E8: =D8*(1+rinc) -> 0 | F8: =E8*(1+rinc) -> 0 | G8: =F8*(1+rinc) -> 0 | H8: =G8*(1+rinc) -> 0 | I8: =H8*(1+rinc) -> 0 | J8: =I8*(1+rinc) -> 0 | K8: =J8*(1+rinc) -> 0 | ... AW8: =AV8*(1+rinc) -> 0
A9: =TEXT(Inputs!$B$55,"") | C9: =Inputs!B67 -> 0 | D9: =C9*(1+rinc) -> 0 | E9: =D9*(1+rinc) -> 0 | F9: =E9*(1+rinc) -> 0 | G9: =F9*(1+rinc) -> 0 | H9: =G9*(1+rinc) -> 0 | I9: =H9*(1+rinc) -> 0 | J9: =I9*(1+rinc) -> 0 | K9: =J9*(1+rinc) -> 0 | ... AW9: =AV9*(1+rinc) -> 0
A10: =TEXT(Inputs!$B$60,"") | C10: =Inputs!B68 -> 0 | D10: =C10*(1+rinc) -> 0 | E10: =D10*(1+rinc) -> 0 | F10: =E10*(1+rinc) -> 0 | G10: =F10*(1+rinc) -> 0 | H10: =G10*(1+rinc) -> 0 | I10: =H10*(1+rinc) -> 0 | J10: =I10*(1+rinc) -> 0 | K10: =J10*(1+rinc) -> 0 | ... AW10: =AV10*(1+rinc) -> 0
A11: Full pension | C11: =IF(C$3<Inputs!$B$19,0,Inputs!$B$21)*(1+inf)^B$1 -> 0 | D11: =IF(D$3<Inputs!$B$19,0,Inputs!$B$21)*(1+inf)^C$1 -> 0 | E11: =IF(E$3<Inputs!$B$19,0,Inputs!$B$21)*(1+inf)^D$1 -> 0 | F11: =IF(F$3<Inputs!$B$19,0,Inputs!$B$21)*(1+inf)^E$1 -> 0 | G11: =IF(G$3<Inputs!$B$19,0,Inputs!$B$21)*(1+inf)^F$1 -> 0 | H11: =IF(H$3<Inputs!$B$19,0,Inputs!$B$21)*(1+inf)^G$1 -> 0 | I11: =IF(I$3<Inputs!$B$19,0,Inputs!$B$21)*(1+inf)^H$1 -> 0 | J11: =IF(J$3<Inputs!$B$19,0,Inputs!$B$21)*(1+inf)^I$1 -> 0 | ... AW11: =IF(AW$3<Inputs!$B$19,0,Inputs!$B$21)*(1+inf)^AV$1 -> 56049.315
A12: Pension reduction from early retirement | C12: =MIN(0,MAX(-IF(C11=0,0,(Inputs!$B$19-INDEX(3:3,MATCH(0,5:5,0))))*Inputs!$B$157*(1+inf)^B$1,-C11)) -> 0 | D12: =MIN(0,MAX(-IF(D11=0,0,(Inputs!$B$19-INDEX(3:3,MATCH(0,5:5,0))))*Inputs!$B$157*(1+inf)^C$1,-D11)) -> 0 | E12: =MIN(0,MAX(-IF(E11=0,0,(Inputs!$B$19-INDEX(3:3,MATCH(0,5:5,0))))*Inputs!$B$157*(1+inf)^D$1,-E11)) -> 0 | F12: =MIN(0,MAX(-IF(F11=0,0,(Inputs!$B$19-INDEX(3:3,MATCH(0,5:5,0))))*Inputs!$B$157*(1+inf)^E$1,-F11)) -> 0 | G12: =MIN(0,MAX(-IF(G11=0,0,(Inputs!$B$19-INDEX(3:3,MATCH(0,5:5,0))))*Inputs!$B$157*(1+inf)^F$1,-G11)) -> 0 | H12: =MIN(0,MAX(-IF(H11=0,0,(Inputs!$B$19-INDEX(3:3,MATCH(0,5:5,0))))*Inputs!$B$157*(1+inf)^G$1,-H11)) -> 0 | I12: =MIN(0,MAX(-IF(I11=0,0,(Inputs!$B$19-INDEX(3:3,MATCH(0,5:5,0))))*Inputs!$B$157*(1+inf)^H$1,-I11)) -> 0 | J12: =MIN(0,MAX(-IF(J11=0,0,(Inputs!$B$19-INDEX(3:3,MATCH(0,5:5,0))))*Inputs!$B$157*(1+inf)^I$1,-J11)) -> 0 | ... AW12: =MIN(0,MAX(-IF(AW11=0,0,(Inputs!$B$19-INDEX(3:3,MATCH(0,5:5,0))))*Inputs!$B$157*(1+inf)^AV$1,-AW11)) -> -5604.9315
A13: Other post-retirement income | C13: =IF(AND(C$3>=Inputs!$B$142,C$3<=Inputs!$B$143),Inputs!$B$141*(1+inf)^B$1,0) -> 0 | D13: =IF(AND(D$3>=Inputs!$B$142,D$3<=Inputs!$B$143),Inputs!$B$141*(1+inf)^C$1,0) -> 0 | E13: =IF(AND(E$3>=Inputs!$B$142,E$3<=Inputs!$B$143),Inputs!$B$141*(1+inf)^D$1,0) -> 0 | F13: =IF(AND(F$3>=Inputs!$B$142,F$3<=Inputs!$B$143),Inputs!$B$141*(1+inf)^E$1,0) -> 0 | G13: =IF(AND(G$3>=Inputs!$B$142,G$3<=Inputs!$B$143),Inputs!$B$141*(1+inf)^F$1,0) -> 0 | H13: =IF(AND(H$3>=Inputs!$B$142,H$3<=Inputs!$B$143),Inputs!$B$141*(1+inf)^G$1,0) -> 0 | I13: =IF(AND(I$3>=Inputs!$B$142,I$3<=Inputs!$B$143),Inputs!$B$141*(1+inf)^H$1,0) -> 0 | J13: =IF(AND(J$3>=Inputs!$B$142,J$3<=Inputs!$B$143),Inputs!$B$141*(1+inf)^I$1,0) -> 0 | ... AW13: =IF(AND(AW$3>=Inputs!$B$142,AW$3<=Inputs!$B$143),Inputs!$B$141*(1+inf)^AV$1,0) -> 0
A14: Major one-off income events
A15: =TEXT(Inputs!B100,"") | C15: =IF(C$2=Inputs!$B102,Inputs!$B101,0)*(1+inf)^B$1 -> 0 | D15: =IF(D$2=Inputs!$B102,Inputs!$B101,0)*(1+inf)^C$1 -> 0 | E15: =IF(E$2=Inputs!$B102,Inputs!$B101,0)*(1+inf)^D$1 -> 0 | F15: =IF(F$2=Inputs!$B102,Inputs!$B101,0)*(1+inf)^E$1 -> 0 | G15: =IF(G$2=Inputs!$B102,Inputs!$B101,0)*(1+inf)^F$1 -> 0 | H15: =IF(H$2=Inputs!$B102,Inputs!$B101,0)*(1+inf)^G$1 -> 0 | I15: =IF(I$2=Inputs!$B102,Inputs!$B101,0)*(1+inf)^H$1 -> 0 | J15: =IF(J$2=Inputs!$B102,Inputs!$B101,0)*(1+inf)^I$1 -> 0 | ... AW15: =IF(AW$2=Inputs!$B102,Inputs!$B101,0)*(1+inf)^AV$1 -> 0
A16: =TEXT(Inputs!B105,"") | C16: =IF(C$2=Inputs!$B107,Inputs!$B106,0)*(1+inf)^B$1 -> 0 | D16: =IF(D$2=Inputs!$B107,Inputs!$B106,0)*(1+inf)^C$1 -> 0 | E16: =IF(E$2=Inputs!$B107,Inputs!$B106,0)*(1+inf)^D$1 -> 0 | F16: =IF(F$2=Inputs!$B107,Inputs!$B106,0)*(1+inf)^E$1 -> 0 | G16: =IF(G$2=Inputs!$B107,Inputs!$B106,0)*(1+inf)^F$1 -> 0 | H16: =IF(H$2=Inputs!$B107,Inputs!$B106,0)*(1+inf)^G$1 -> 0 | I16: =IF(I$2=Inputs!$B107,Inputs!$B106,0)*(1+inf)^H$1 -> 0 | J16: =IF(J$2=Inputs!$B107,Inputs!$B106,0)*(1+inf)^I$1 -> 0 | ... AW16: =IF(AW$2=Inputs!$B107,Inputs!$B106,0)*(1+inf)^AV$1 -> 0
A17: =TEXT(Inputs!B110,"") | C17: =IF(C$2=Inputs!$B112,Inputs!$B111,0)*(1+inf)^B$1 -> 0 | D17: =IF(D$2=Inputs!$B112,Inputs!$B111,0)*(1+inf)^C$1 -> 0 | E17: =IF(E$2=Inputs!$B112,Inputs!$B111,0)*(1+inf)^D$1 -> 0 | F17: =IF(F$2=Inputs!$B112,Inputs!$B111,0)*(1+inf)^E$1 -> 0 | G17: =IF(G$2=Inputs!$B112,Inputs!$B111,0)*(1+inf)^F$1 -> 0 | H17: =IF(H$2=Inputs!$B112,Inputs!$B111,0)*(1+inf)^G$1 -> 0 | I17: =IF(I$2=Inputs!$B112,Inputs!$B111,0)*(1+inf)^H$1 -> 0 | J17: =IF(J$2=Inputs!$B112,Inputs!$B111,0)*(1+inf)^I$1 -> 0 | ... AW17: =IF(AW$2=Inputs!$B112,Inputs!$B111,0)*(1+inf)^AV$1 -> 0
A18: Interest on cash balances | C18: =MAX(AVERAGE(C49,C49+SUM(C5:C17)-C46)*Inputs!$B$149,0) -> 4998.75 | D18: =MAX(AVERAGE(D49,D49+SUM(D5:D17)-D46)*Inputs!$B$149,0) -> 5127.9375 | E18: =MAX(AVERAGE(E49,E49+SUM(E5:E17)-E46)*Inputs!$B$149,0) -> 5274.0727 | F18: =MAX(AVERAGE(F49,F49+SUM(F5:F17)-F46)*Inputs!$B$149,0) -> 5438.1505 | G18: =MAX(AVERAGE(G49,G49+SUM(G5:G17)-G46)*Inputs!$B$149,0) -> 5621.212 | H18: =MAX(AVERAGE(H49,H49+SUM(H5:H17)-H46)*Inputs!$B$149,0) -> 5824.3462 | I18: =MAX(AVERAGE(I49,I49+SUM(I5:I17)-I46)*Inputs!$B$149,0) -> 6048.6917 | J18: =MAX(AVERAGE(J49,J49+SUM(J5:J17)-J46)*Inputs!$B$149,0) -> 6295.4392 | ... AW18: =MAX(AVERAGE(AW49,AW49+SUM(AW5:AW17)-AW46)*Inputs!$B$149,0) -> 0
C19: =SUM(C4:C18) -> 64998.75 | D19: =SUM(D4:D18) -> 66927.938 | E19: =SUM(E4:E18) -> 68928.073 | F19: =SUM(F4:F18) -> 71001.77 | G19: =SUM(G4:G18) -> 73151.741 | H19: =SUM(H4:H18) -> 75380.791 | I19: =SUM(I4:I18) -> 77691.829 | J19: =SUM(J4:J18) -> 80087.871 | ... AW19: =SUM(AW4:AW18) -> 50444.384
A20: Outflows
A21: Credit cards cleared | C21: =Inputs!B75 -> 0 | D21: 0 | E21: 0 | F21: 0 | G21: 0 | H21: 0 | I21: 0 | J21: 0 | K21: 0 | L21: 0 | M21: 0 | N21: 0 | O21: 0 | P21: 0 | Q21: 0 | R21: 0 | S21: 0 | T21: 0 | U21: 0 | V21: 0 | W21: 0 | X21: 0 | Y21: 0 | Z21: 0 | AA21: 0 | AB21: 0 | AC21: 0 | AD21: 0 | AE21: 0 | AF21: 0 | AG21: 0 | AH21: 0 | AI21: 0 | AJ21: 0 | AK21: 0 | AL21: 0 | AM21: 0 | AN21: 0 | AO21: 0 | AP21: 0 | AQ21: 0 | AR21: 0 | AS21: 0 | AT21: 0 | AU21: 0 | AV21: 0 | AW21: 0
A22: Home loan repayment | C22: =MAX(IF(C$1*12<=Inputs!$G$15,12,(Inputs!$G$15-B$1*12)),0)*Inputs!$B$17 -> 9600 | D22: =MAX(IF(D$1*12<=Inputs!$G$15,12,(Inputs!$G$15-C$1*12)),0)*Inputs!$B$17 -> 9600 | E22: =MAX(IF(E$1*12<=Inputs!$G$15,12,(Inputs!$G$15-D$1*12)),0)*Inputs!$B$17 -> 9600 | F22: =MAX(IF(F$1*12<=Inputs!$G$15,12,(Inputs!$G$15-E$1*12)),0)*Inputs!$B$17 -> 9600 | G22: =MAX(IF(G$1*12<=Inputs!$G$15,12,(Inputs!$G$15-F$1*12)),0)*Inputs!$B$17 -> 9600 | H22: =MAX(IF(H$1*12<=Inputs!$G$15,12,(Inputs!$G$15-G$1*12)),0)*Inputs!$B$17 -> 9600 | I22: =MAX(IF(I$1*12<=Inputs!$G$15,12,(Inputs!$G$15-H$1*12)),0)*Inputs!$B$17 -> 9600 | J22: =MAX(IF(J$1*12<=Inputs!$G$15,12,(Inputs!$G$15-I$1*12)),0)*Inputs!$B$17 -> 9600 | ... AW22: =MAX(IF(AW$1*12<=Inputs!$G$15,12,(Inputs!$G$15-AV$1*12)),0)*Inputs!$B$17 -> 0
A23: Other property loans repayments
A24: =TEXT(Inputs!$B$50,"") -> Sliema | C24: =MAX(IF(C$1*12<=Inputs!$G$78,12,(Inputs!$G$78-B$1*12)),0)*Inputs!$B$80 -> 0 | D24: =MAX(IF(D$1*12<=Inputs!$G$78,12,(Inputs!$G$78-C$1*12)),0)*Inputs!$B$80 -> 0 | E24: =MAX(IF(E$1*12<=Inputs!$G$78,12,(Inputs!$G$78-D$1*12)),0)*Inputs!$B$80 -> 0 | F24: =MAX(IF(F$1*12<=Inputs!$G$78,12,(Inputs!$G$78-E$1*12)),0)*Inputs!$B$80 -> 0 | G24: =MAX(IF(G$1*12<=Inputs!$G$78,12,(Inputs!$G$78-F$1*12)),0)*Inputs!$B$80 -> 0 | H24: =MAX(IF(H$1*12<=Inputs!$G$78,12,(Inputs!$G$78-G$1*12)),0)*Inputs!$B$80 -> 0 | I24: =MAX(IF(I$1*12<=Inputs!$G$78,12,(Inputs!$G$78-H$1*12)),0)*Inputs!$B$80 -> 0 | J24: =MAX(IF(J$1*12<=Inputs!$G$78,12,(Inputs!$G$78-I$1*12)),0)*Inputs!$B$80 -> 0 | ... AW24: =MAX(IF(AW$1*12<=Inputs!$G$78,12,(Inputs!$G$78-AV$1*12)),0)*Inputs!$B$80 -> 0
A25: =TEXT(Inputs!$B$55,"") | C25: =MAX(IF(C$1*12<=Inputs!$G$83,12,(Inputs!$G$83-B$1*12)),0)*Inputs!$B$85 -> 0 | D25: =MAX(IF(D$1*12<=Inputs!$G$83,12,(Inputs!$G$83-C$1*12)),0)*Inputs!$B$85 -> 0 | E25: =MAX(IF(E$1*12<=Inputs!$G$83,12,(Inputs!$G$83-D$1*12)),0)*Inputs!$B$85 -> 0 | F25: =MAX(IF(F$1*12<=Inputs!$G$83,12,(Inputs!$G$83-E$1*12)),0)*Inputs!$B$85 -> 0 | G25: =MAX(IF(G$1*12<=Inputs!$G$83,12,(Inputs!$G$83-F$1*12)),0)*Inputs!$B$85 -> 0 | H25: =MAX(IF(H$1*12<=Inputs!$G$83,12,(Inputs!$G$83-G$1*12)),0)*Inputs!$B$85 -> 0 | I25: =MAX(IF(I$1*12<=Inputs!$G$83,12,(Inputs!$G$83-H$1*12)),0)*Inputs!$B$85 -> 0 | J25: =MAX(IF(J$1*12<=Inputs!$G$83,12,(Inputs!$G$83-I$1*12)),0)*Inputs!$B$85 -> 0 | ... AW25: =MAX(IF(AW$1*12<=Inputs!$G$83,12,(Inputs!$G$83-AV$1*12)),0)*Inputs!$B$85 -> 0
A26: =TEXT(Inputs!$B$60,"") | C26: =MAX(IF(C$1*12<=Inputs!$G$88,12,(Inputs!$G$88-B$1*12)),0)*Inputs!$B$90 -> 0 | D26: =MAX(IF(D$1*12<=Inputs!$G$88,12,(Inputs!$G$88-C$1*12)),0)*Inputs!$B$90 -> 0 | E26: =MAX(IF(E$1*12<=Inputs!$G$88,12,(Inputs!$G$88-D$1*12)),0)*Inputs!$B$90 -> 0 | F26: =MAX(IF(F$1*12<=Inputs!$G$88,12,(Inputs!$G$88-E$1*12)),0)*Inputs!$B$90 -> 0 | G26: =MAX(IF(G$1*12<=Inputs!$G$88,12,(Inputs!$G$88-F$1*12)),0)*Inputs!$B$90 -> 0 | H26: =MAX(IF(H$1*12<=Inputs!$G$88,12,(Inputs!$G$88-G$1*12)),0)*Inputs!$B$90 -> 0 | I26: =MAX(IF(I$1*12<=Inputs!$G$88,12,(Inputs!$G$88-H$1*12)),0)*Inputs!$B$90 -> 0 | J26: =MAX(IF(J$1*12<=Inputs!$G$88,12,(Inputs!$G$88-I$1*12)),0)*Inputs!$B$90 -> 0 | ... AW26: =MAX(IF(AW$1*12<=Inputs!$G$88,12,(Inputs!$G$88-AV$1*12)),0)*Inputs!$B$90 -> 0
A27: Other loan repayment | C27: =MAX(IF(C$1*12<=Inputs!$G$93,12,(Inputs!$G$93-B$1*12)),0)*Inputs!$B$95 -> 0 | D27: =MAX(IF(D$1*12<=Inputs!$G$93,12,(Inputs!$G$93-C$1*12)),0)*Inputs!$B$95 -> 0 | E27: =MAX(IF(E$1*12<=Inputs!$G$93,12,(Inputs!$G$93-D$1*12)),0)*Inputs!$B$95 -> 0 | F27: =MAX(IF(F$1*12<=Inputs!$G$93,12,(Inputs!$G$93-E$1*12)),0)*Inputs!$B$95 -> 0 | G27: =MAX(IF(G$1*12<=Inputs!$G$93,12,(Inputs!$G$93-F$1*12)),0)*Inputs!$B$95 -> 0 | H27: =MAX(IF(H$1*12<=Inputs!$G$93,12,(Inputs!$G$93-G$1*12)),0)*Inputs!$B$95 -> 0 | I27: =MAX(IF(I$1*12<=Inputs!$G$93,12,(Inputs!$G$93-H$1*12)),0)*Inputs!$B$95 -> 0 | J27: =MAX(IF(J$1*12<=Inputs!$G$93,12,(Inputs!$G$93-I$1*12)),0)*Inputs!$B$95 -> 0 | ... AW27: =MAX(IF(AW$1*12<=Inputs!$G$93,12,(Inputs!$G$93-AV$1*12)),0)*Inputs!$B$95 -> 0
A28: Dependents cost
A29: =TEXT(Inputs!B33,"") | C29: =IF(Inputs!$B$35>=C$1,Inputs!$B$34,0)*(1+inf)^B$1 -> 0 | D29: =IF(Inputs!$B$35>=D$1,Inputs!$B$34,0)*(1+inf)^C$1 -> 0 | E29: =IF(Inputs!$B$35>=E$1,Inputs!$B$34,0)*(1+inf)^D$1 -> 0 | F29: =IF(Inputs!$B$35>=F$1,Inputs!$B$34,0)*(1+inf)^E$1 -> 0 | G29: =IF(Inputs!$B$35>=G$1,Inputs!$B$34,0)*(1+inf)^F$1 -> 0 | H29: =IF(Inputs!$B$35>=H$1,Inputs!$B$34,0)*(1+inf)^G$1 -> 0 | I29: =IF(Inputs!$B$35>=I$1,Inputs!$B$34,0)*(1+inf)^H$1 -> 0 | J29: =IF(Inputs!$B$35>=J$1,Inputs!$B$34,0)*(1+inf)^I$1 -> 0 | ... AW29: =IF(Inputs!$B$35>=AW$1,Inputs!$B$34,0)*(1+inf)^AV$1 -> 0
A30: =TEXT(Inputs!B38,"") | C30: =IF(Inputs!$B$40>=C$1,Inputs!$B$39,0)*(1+inf)^B$1 -> 0 | D30: =IF(Inputs!$B$40>=D$1,Inputs!$B$39,0)*(1+inf)^C$1 -> 0 | E30: =IF(Inputs!$B$40>=E$1,Inputs!$B$39,0)*(1+inf)^D$1 -> 0 | F30: =IF(Inputs!$B$40>=F$1,Inputs!$B$39,0)*(1+inf)^E$1 -> 0 | G30: =IF(Inputs!$B$40>=G$1,Inputs!$B$39,0)*(1+inf)^F$1 -> 0 | H30: =IF(Inputs!$B$40>=H$1,Inputs!$B$39,0)*(1+inf)^G$1 -> 0 | I30: =IF(Inputs!$B$40>=I$1,Inputs!$B$39,0)*(1+inf)^H$1 -> 0 | J30: =IF(Inputs!$B$40>=J$1,Inputs!$B$39,0)*(1+inf)^I$1 -> 0 | ... AW30: =IF(Inputs!$B$40>=AW$1,Inputs!$B$39,0)*(1+inf)^AV$1 -> 0
A31: =TEXT(Inputs!B43,"") | C31: =IF(Inputs!$B$45>=C$1,Inputs!$B$44,0)*(1+inf)^B$1 -> 0 | D31: =IF(Inputs!$B$45>=D$1,Inputs!$B$44,0)*(1+inf)^C$1 -> 0 | E31: =IF(Inputs!$B$45>=E$1,Inputs!$B$44,0)*(1+inf)^D$1 -> 0 | F31: =IF(Inputs!$B$45>=F$1,Inputs!$B$44,0)*(1+inf)^E$1 -> 0 | G31: =IF(Inputs!$B$45>=G$1,Inputs!$B$44,0)*(1+inf)^F$1 -> 0 | H31: =IF(Inputs!$B$45>=H$1,Inputs!$B$44,0)*(1+inf)^G$1 -> 0 | I31: =IF(Inputs!$B$45>=I$1,Inputs!$B$44,0)*(1+inf)^H$1 -> 0 | J31: =IF(Inputs!$B$45>=J$1,Inputs!$B$44,0)*(1+inf)^I$1 -> 0 | ... AW31: =IF(Inputs!$B$45>=AW$1,Inputs!$B$44,0)*(1+inf)^AV$1 -> 0
A32: Housing rent | C32: =Inputs!$B$23*(1+inf)^B$1 -> 0 | D32: =Inputs!$B$23*(1+inf)^C$1 -> 0 | E32: =Inputs!$B$23*(1+inf)^D$1 -> 0 | F32: =Inputs!$B$23*(1+inf)^E$1 -> 0 | G32: =Inputs!$B$23*(1+inf)^F$1 -> 0 | H32: =Inputs!$B$23*(1+inf)^G$1 -> 0 | I32: =Inputs!$B$23*(1+inf)^H$1 -> 0 | J32: =Inputs!$B$23*(1+inf)^I$1 -> 0 | ... AW32: =Inputs!$B$23*(1+inf)^AV$1 -> 0
A33: Other property costs
A34: =TEXT(Inputs!$B$50,"") -> Sliema | C34: =Inputs!$B52*(1+inf)^B$1 -> 500 | D34: =Inputs!$B52*(1+inf)^C$1 -> 512.5 | E34: =Inputs!$B52*(1+inf)^D$1 -> 525.3125 | F34: =Inputs!$B52*(1+inf)^E$1 -> 538.44531 | G34: =Inputs!$B52*(1+inf)^F$1 -> 551.90645 | H34: =Inputs!$B52*(1+inf)^G$1 -> 565.70411 | I34: =Inputs!$B52*(1+inf)^H$1 -> 579.84671 | J34: =Inputs!$B52*(1+inf)^I$1 -> 594.34288 | ... AW34: =Inputs!$B52*(1+inf)^AV$1 -> 1556.9254
A35: =TEXT(Inputs!$B$55,"") | C35: =Inputs!$B57*(1+inf)^B$1 -> 0 | D35: =Inputs!$B57*(1+inf)^C$1 -> 0 | E35: =Inputs!$B57*(1+inf)^D$1 -> 0 | F35: =Inputs!$B57*(1+inf)^E$1 -> 0 | G35: =Inputs!$B57*(1+inf)^F$1 -> 0 | H35: =Inputs!$B57*(1+inf)^G$1 -> 0 | I35: =Inputs!$B57*(1+inf)^H$1 -> 0 | J35: =Inputs!$B57*(1+inf)^I$1 -> 0 | ... AW35: =Inputs!$B57*(1+inf)^AV$1 -> 0
A36: =TEXT(Inputs!$B$60,"") | C36: =Inputs!$B62*(1+inf)^B$1 -> 0 | D36: =Inputs!$B62*(1+inf)^C$1 -> 0 | E36: =Inputs!$B62*(1+inf)^D$1 -> 0 | F36: =Inputs!$B62*(1+inf)^E$1 -> 0 | G36: =Inputs!$B62*(1+inf)^F$1 -> 0 | H36: =Inputs!$B62*(1+inf)^G$1 -> 0 | I36: =Inputs!$B62*(1+inf)^H$1 -> 0 | J36: =Inputs!$B62*(1+inf)^I$1 -> 0 | ... AW36: =Inputs!$B62*(1+inf)^AV$1 -> 0
A37: Living expenses
A38: Current baseline | C38: =Inputs!$B$25*(1+inf)^B$1 -> 50000 | D38: =Inputs!$B$25*(1+inf)^C$1 -> 51250 | E38: =Inputs!$B$25*(1+inf)^D$1 -> 52531.25 | F38: =Inputs!$B$25*(1+inf)^E$1 -> 53844.531 | G38: =Inputs!$B$25*(1+inf)^F$1 -> 55190.645 | H38: =Inputs!$B$25*(1+inf)^G$1 -> 56570.411 | I38: =Inputs!$B$25*(1+inf)^H$1 -> 57984.671 | J38: =Inputs!$B$25*(1+inf)^I$1 -> 59434.288 | ... AW38: =Inputs!$B$25*(1+inf)^AV$1 -> 155692.54
A39: ="Adjustment "&Inputs!A137 -> Adjustment from now to 65 | C39: =IF(C$3<=65,Inputs!$B$137*C$38,0) -> 0 | D39: =IF(D$3<=65,Inputs!$B$137*D$38,0) -> 0 | E39: =IF(E$3<=65,Inputs!$B$137*E$38,0) -> 0 | F39: =IF(F$3<=65,Inputs!$B$137*F$38,0) -> 0 | G39: =IF(G$3<=65,Inputs!$B$137*G$38,0) -> 0 | H39: =IF(H$3<=65,Inputs!$B$137*H$38,0) -> 0 | I39: =IF(I$3<=65,Inputs!$B$137*I$38,0) -> 0 | J39: =IF(J$3<=65,Inputs!$B$137*J$38,0) -> 0 | ... AW39: =IF(AW$3<=65,Inputs!$B$137*AW$38,0) -> 0
A40: ="Adjustment "&Inputs!A138 -> Adjustment from 66-75 | C40: =IF(AND(C$3>65,C$3<=75),Inputs!$B$138*C38,0) -> 0 | D40: =IF(AND(D$3>65,D$3<=75),Inputs!$B$138*D38,0) -> 0 | E40: =IF(AND(E$3>65,E$3<=75),Inputs!$B$138*E38,0) -> 0 | F40: =IF(AND(F$3>65,F$3<=75),Inputs!$B$138*F38,0) -> 0 | G40: =IF(AND(G$3>65,G$3<=75),Inputs!$B$138*G38,0) -> 0 | H40: =IF(AND(H$3>65,H$3<=75),Inputs!$B$138*H38,0) -> 0 | I40: =IF(AND(I$3>65,I$3<=75),Inputs!$B$138*I38,0) -> 0 | J40: =IF(AND(J$3>65,J$3<=75),Inputs!$B$138*J38,0) -> 0 | ... AW40: =IF(AND(AW$3>65,AW$3<=75),Inputs!$B$138*AW38,0) -> 0
...
