Workbook
Name AgeRange: RetNorm_Engine!$C$3:INDEX(RetNorm_Engine!$C$3:$XFD$3, COUNTA(RetNorm_Engine!$C$3:$XFD$3))
Name buffer: Inputs!$B$159
Name ChartCash_Early: RetEarly_Engine!$C$201:INDEX(RetEarly_Engine!$C$201:$XFD$201, COUNTA(RetEarly_Engine!$C$201:$XFD$201))
Name ChartCash_Norm: RetNorm_Engine!$C$201:INDEX(RetNorm_Engine!$C$201:$XFD$201, COUNTA(RetNorm_Engine!$C$201:$XFD$201))
Name ChartNW_Early: RetEarly_Engine!$C$202:INDEX(RetEarly_Engine!$C$202:$XFD$202, COUNTA(RetEarly_Engine!$C$202:$XFD$202))
Name ChartNW_Norm: RetNorm_Engine!$C$202:INDEX(RetNorm_Engine!$C$202:$XFD$202, COUNTA(RetNorm_Engine!$C$202:$XFD$202))
Name EndAge: Inputs!$B$134
Name inf: Inputs!$B$145
Name princ: Inputs!$B$147
Name RetAge: Inputs!$B$19
Name rinc: Inputs!$B$155
Name sincr: Inputs!$B$153
Name stinc: Inputs!$B$151

Sheet Inputs
B1: User inputs | D1: User Tooltips | E1: UI Notes | F1: Excel helpers
A2: QUICK START
A4: Your age | B4: 48 | D4: Must be entered
A6: Current net annual income | B6: 80000 | D6: Net of tax, from employment or self-employment
A8: Total cash balances | B8: 50000 | D8: current and savings accounts, bonds, term deposits
A10: Stock market investments | B10: 30000 | D10: Current market value of equity portfolio
A12: Home current market value | B12: 600000 | D12: Leave blank if not a home owner
A14: Home loan (mortgage)
A15: Balance | B15: 50000 | D15: Leave blank if no mortgage | F15: Months remaining | G15: =IFERROR(NPER(B16/12,-B17,B15),"") -> 68.044529
A16: Interest rate | B16: 0.03 | F16: Years remaining | G16: =IFERROR(G15/12,"") -> 5.6703774
A17: Monthly repayment | B17: 800
A19: Statutory retirement age | B19: 65 | D19: Year at which pension starts
A21: Annual pension at retirement | B21: 16000 | D21: Net annual state pension entitlement
A23: Housing rent | D23: if not a home owner | E23: show only if not a home owner (B12="")
A25: Annual living expenses | B25: 50000
A28: DEEPER DIVE | E28: Activated only if user wants to
A30: Dependents
A32: Dependent 1
A33: Name | B33: John | D33: Leave blank if none
A34: Annual cost | B34: 2000 | D34: Food, education, healthcare, etc. | E34: Hide until user enters dependent name
A35: Years to support | B35: 3 | D35: Years from now | E35: Hide until user enters dependent name
A37: Dependent 2
A38: Name | B38: Jack | D38: Leave blank if none
A39: Annual cost | B39: 1000 | D39: Food, education, healthcare, etc. | E39: Hide until user enters dependent name
A40: Years to support | B40: 5 | D40: Years from now | E40: Hide until user enters dependent name
A42: Dependent 3
A43: Name | B43: Bill | D43: Leave blank if none
A44: Annual cost | B44: 4000 | D44: Food, education, healthcare, etc. | E44: Hide until user enters dependent name
A45: Years to support | B45: 2 | D45: Years from now | E45: Hide until user enters dependent name
A47: Investment Properties
A49: Property 1
A50: Name | B50: Sliema | D50: Leave blank if none
A51: Market value | B51: 300000 | E51: Hide until user enters property name
A52: Annual costs | B52: 5000 | D52: Repairs, maintenance, etc. | E52: Hide until user enters property name
A54: Property 2
A55: Name | B55: Gzira | D55: Leave blank if none
A56: Market value | B56: 150000 | E56: Hide until user enters property name
A57: Annual costs | B57: 2000 | D57: Repairs, maintenance, etc. | E57: Hide until user enters property name
A59: Property 3
A60: Name | B60: Qormi | D60: Leave blank if none
...

Sheet Output
V2: Retire at | AA2: ="Retire at "&RetEarly_Engine!B3 -> Retire at 55
V3: =RetEarly_Engine!B3 -> 55 | AA3: ="Retire at "&RetAge -> Retire at 65

Sheet RetNorm_Engine
B1: 0 | C1: 1 | D1: =C1+1 -> 2 | E1: =D1+1 -> 3 | F1: =E1+1 -> 4 | G1: =F1+1 -> 5 | H1: =G1+1 -> 6 | I1: =H1+1 -> 7 | J1: =I1+1 -> 8 | K1: =J1+1 -> 9 | ... AM1: =AL1+1 -> 37
B2: Year | C2: =YEAR(TODAY())+1 -> 2027 | D2: =C2+1 -> 2028 | E2: =D2+1 -> 2029 | F2: =E2+1 -> 2030 | G2: =F2+1 -> 2031 | H2: =G2+1 -> 2032 | I2: =H2+1 -> 2033 | J2: =I2+1 -> 2034 | K2: =J2+1 -> 2035 | ... AM2: =AL2+1 -> 2063
B3: =Inputs!B19 -> 65 | C3: =Inputs!B4+1 -> 49 | D3: =C3+1 -> 50 | E3: =D3+1 -> 51 | F3: =E3+1 -> 52 | G3: =F3+1 -> 53 | H3: =G3+1 -> 54 | I3: =H3+1 -> 55 | J3: =I3+1 -> 56 | K3: =J3+1 -> 57 | ... AM3: =AL3+1 -> 85
A4: Inflows
A5: Net employment / self-employment income | C5: =IF(AND(Inputs!$B$19>C3,$B$3>C3),Inputs!$B$6*(1+sincr)^B1,0) -> 80000 | D5: =IF(AND(Inputs!$B$19>D3,$B$3>D3),Inputs!$B$6*(1+sincr)^C1,0) -> 82400 | E5: =IF(AND(Inputs!$B$19>E3,$B$3>E3),Inputs!$B$6*(1+sincr)^D1,0) -> 84872 | F5: =IF(AND(Inputs!$B$19>F3,$B$3>F3),Inputs!$B$6*(1+sincr)^E1,0) -> 87418.16 | G5: =IF(AND(Inputs!$B$19>G3,$B$3>G3),Inputs!$B$6*(1+sincr)^F1,0) -> 90040.705 | H5: =IF(AND(Inputs!$B$19>H3,$B$3>H3),Inputs!$B$6*(1+sincr)^G1,0) -> 92741.926 | I5: =IF(AND(Inputs!$B$19>I3,$B$3>I3),Inputs!$B$6*(1+sincr)^H1,0) -> 95524.184 | J5: =IF(AND(Inputs!$B$19>J3,$B$3>J3),Inputs!$B$6*(1+sincr)^I1,0) -> 98389.909 | ... AM5: =IF(AND(Inputs!$B$19>AM3,$B$3>AM3),Inputs!$B$6*(1+sincr)^AL1,0) -> 0
A6: Net from other work | C6: =IF(C$3<=Inputs!$B$71,Inputs!$B$70,0)*(1+inf)^B$1 -> 2000 | D6: =IF(D$3<=Inputs!$B$71,Inputs!$B$70,0)*(1+inf)^C$1 -> 2050 | E6: =IF(E$3<=Inputs!$B$71,Inputs!$B$70,0)*(1+inf)^D$1 -> 2101.25 | F6: =IF(F$3<=Inputs!$B$71,Inputs!$B$70,0)*(1+inf)^E$1 -> 2153.7812 | G6: =IF(G$3<=Inputs!$B$71,Inputs!$B$70,0)*(1+inf)^F$1 -> 2207.6258 | H6: =IF(H$3<=Inputs!$B$71,Inputs!$B$70,0)*(1+inf)^G$1 -> 2262.8164 | I6: =IF(I$3<=Inputs!$B$71,Inputs!$B$70,0)*(1+inf)^H$1 -> 2319.3868 | J6: =IF(J$3<=Inputs!$B$71,Inputs!$B$70,0)*(1+inf)^I$1 -> 2377.3715 | ... AM6: =IF(AM$3<=Inputs!$B$71,Inputs!$B$70,0)*(1+inf)^AL$1 -> 0
A7: Net rental income from other properties
A8: =TEXT(Inputs!$B$50,"") -> Sliema | C8: =Inputs!B66 -> 12000 | D8: =C8*(1+rinc) -> 12360 | E8: =D8*(1+rinc) -> 12730.8 | F8: =E8*(1+rinc) -> 13112.724 | G8: =F8*(1+rinc) -> 13506.106 | H8: =G8*(1+rinc) -> 13911.289 | I8: =H8*(1+rinc) -> 14328.628 | J8: =I8*(1+rinc) -> 14758.486 | K8: =J8*(1+rinc) -> 15201.241 | ... AM8: =AL8*(1+rinc) -> 34779.34
A9: =TEXT(Inputs!$B$55,"") -> Gzira | C9: =Inputs!B67 -> 10000 | D9: =C9*(1+rinc) -> 10300 | E9: =D9*(1+rinc) -> 10609 | F9: =E9*(1+rinc) -> 10927.27 | G9: =F9*(1+rinc) -> 11255.088 | H9: =G9*(1+rinc) -> 11592.741 | I9: =H9*(1+rinc) -> 11940.523 | J9: =I9*(1+rinc) -> 12298.739 | K9: =J9*(1+rinc) -> 12667.701 | ... AM9: =AL9*(1+rinc) -> 28982.783
A10: =TEXT(Inputs!$B$60,"") -> Qormi | C10: =Inputs!B68 -> 8000 | D10: =C10*(1+rinc) -> 8240 | E10: =D10*(1+rinc) -> 8487.2 | F10: =E10*(1+rinc) -> 8741.816 | G10: =F10*(1+rinc) -> 9004.0705 | H10: =G10*(1+rinc) -> 9274.1926 | I10: =H10*(1+rinc) -> 9552.4184 | J10: =I10*(1+rinc) -> 9838.9909 | K10: =J10*(1+rinc) -> 10134.161 | ... AM10: =AL10*(1+rinc) -> 23186.227
A11: Full pension | C11: =IF(C$3<Inputs!$B$19,0,Inputs!$B$21)*(1+inf)^B$1 -> 0 | D11: =IF(D$3<Inputs!$B$19,0,Inputs!$B$21)*(1+inf)^C$1 -> 0 | E11: =IF(E$3<Inputs!$B$19,0,Inputs!$B$21)*(1+inf)^D$1 -> 0 | F11: =IF(F$3<Inputs!$B$19,0,Inputs!$B$21)*(1+inf)^E$1 -> 0 | G11: =IF(G$3<Inputs!$B$19,0,Inputs!$B$21)*(1+inf)^F$1 -> 0 | H11: =IF(H$3<Inputs!$B$19,0,Inputs!$B$21)*(1+inf)^G$1 -> 0 | I11: =IF(I$3<Inputs!$B$19,0,Inputs!$B$21)*(1+inf)^H$1 -> 0 | J11: =IF(J$3<Inputs!$B$19,0,Inputs!$B$21)*(1+inf)^I$1 -> 0 | ... AM11: =IF(AM$3<Inputs!$B$19,0,Inputs!$B$21)*(1+inf)^AL$1 -> 38920.565
A12: Pension reduction from early retirement | C12: =MIN(0,MAX(-IF(C11=0,0,(Inputs!$B$19-INDEX(3:3,MATCH(0,5:5,0))))*Inputs!$B$157*(1+inf)^B$1,-C11)) -> 0 | D12: =MIN(0,MAX(-IF(D11=0,0,(Inputs!$B$19-INDEX(3:3,MATCH(0,5:5,0))))*Inputs!$B$157*(1+inf)^C$1,-D11)) -> 0 | E12: =MIN(0,MAX(-IF(E11=0,0,(Inputs!$B$19-INDEX(3:3,MATCH(0,5:5,0))))*Inputs!$B$157*(1+inf)^D$1,-E11)) -> 0 | F12: =MIN(0,MAX(-IF(F11=0,0,(Inputs!$B$19-INDEX(3:3,MATCH(0,5:5,0))))*Inputs!$B$157*(1+inf)^E$1,-F11)) -> 0 | G12: =MIN(0,MAX(-IF(G11=0,0,(Inputs!$B$19-INDEX(3:3,MATCH(0,5:5,0))))*Inputs!$B$157*(1+inf)^F$1,-G11)) -> 0 | H12: =MIN(0,MAX(-IF(H11=0,0,(Inputs!$B$19-INDEX(3:3,MATCH(0,5:5,0))))*Inputs!$B$157*(1+inf)^G$1,-H11)) -> 0 | I12: =MIN(0,MAX(-IF(I11=0,0,(Inputs!$B$19-INDEX(3:3,MATCH(0,5:5,0))))*Inputs!$B$157*(1+inf)^H$1,-I11)) -> 0 | J12: =MIN(0,MAX(-IF(J11=0,0,(Inputs!$B$19-INDEX(3:3,MATCH(0,5:5,0))))*Inputs!$B$157*(1+inf)^I$1,-J11)) -> 0 | ... AM12: =MIN(0,MAX(-IF(AM11=0,0,(Inputs!$B$19-INDEX(3:3,MATCH(0,5:5,0))))*Inputs!$B$157*(1+inf)^AL$1,-AM11)) -> 0
A13: Other post-retirement income | C13: =IF(AND(C$3>=Inputs!$B$142,C$3<=Inputs!$B$143),Inputs!$B$141*(1+inf)^B$1,0) -> 0 | D13: =IF(AND(D$3>=Inputs!$B$142,D$3<=Inputs!$B$143),Inputs!$B$141*(1+inf)^C$1,0) -> 0 | E13: =IF(AND(E$3>=Inputs!$B$142,E$3<=Inputs!$B$143),Inputs!$B$141*(1+inf)^D$1,0) -> 0 | F13: =IF(AND(F$3>=Inputs!$B$142,F$3<=Inputs!$B$143),Inputs!$B$141*(1+inf)^E$1,0) -> 0 | G13: =IF(AND(G$3>=Inputs!$B$142,G$3<=Inputs!$B$143),Inputs!$B$141*(1+inf)^F$1,0) -> 0 | H13: =IF(AND(H$3>=Inputs!$B$142,H$3<=Inputs!$B$143),Inputs!$B$141*(1+inf)^G$1,0) -> 0 | I13: =IF(AND(I$3>=Inputs!$B$142,I$3<=Inputs!$B$143),Inputs!$B$141*(1+inf)^H$1,0) -> 0 | J13: =IF(AND(J$3>=Inputs!$B$142,J$3<=Inputs!$B$143),Inputs!$B$141*(1+inf)^I$1,0) -> 0 | ... AM13: =IF(AND(AM$3>=Inputs!$B$142,AM$3<=Inputs!$B$143),Inputs!$B$141*(1+inf)^AL$1,0) -> 0
A14: Major one-off income events
A15: =TEXT(Inputs!B100,"") -> Inheritance | C15: =IF(C$2=Inputs!$B102,Inputs!$B101,0)*(1+inf)^B$1 -> 0 | D15: =IF(D$2=Inputs!$B102,Inputs!$B101,0)*(1+inf)^C$1 -> 0 | E15: =IF(E$2=Inputs!$B102,Inputs!$B101,0)*(1+inf)^D$1 -> 0 | F15: =IF(F$2=Inputs!$B102,Inputs!$B101,0)*(1+inf)^E$1 -> 0 | G15: =IF(G$2=Inputs!$B102,Inputs!$B101,0)*(1+inf)^F$1 -> 0 | H15: =IF(H$2=Inputs!$B102,Inputs!$B101,0)*(1+inf)^G$1 -> 0 | I15: =IF(I$2=Inputs!$B102,Inputs!$B101,0)*(1+inf)^H$1 -> 0 | J15: =IF(J$2=Inputs!$B102,Inputs!$B101,0)*(1+inf)^I$1 -> 0 | ... AM15: =IF(AM$2=Inputs!$B102,Inputs!$B101,0)*(1+inf)^AL$1 -> 0
A16: =TEXT(Inputs!B105,"") -> Sell Painting | C16: =IF(C$2=Inputs!$B107,Inputs!$B106,0)*(1+inf)^B$1 -> 0 | D16: =IF(D$2=Inputs!$B107,Inputs!$B106,0)*(1+inf)^C$1 -> 0 | E16: =IF(E$2=Inputs!$B107,Inputs!$B106,0)*(1+inf)^D$1 -> 10506.25 | F16: =IF(F$2=Inputs!$B107,Inputs!$B106,0)*(1+inf)^E$1 -> 0 | G16: =IF(G$2=Inputs!$B107,Inputs!$B106,0)*(1+inf)^F$1 -> 0 | H16: =IF(H$2=Inputs!$B107,Inputs!$B106,0)*(1+inf)^G$1 -> 0 | I16: =IF(I$2=Inputs!$B107,Inputs!$B106,0)*(1+inf)^H$1 -> 0 | J16: =IF(J$2=Inputs!$B107,Inputs!$B106,0)*(1+inf)^I$1 -> 0 | ... AM16: =IF(AM$2=Inputs!$B107,Inputs!$B106,0)*(1+inf)^AL$1 -> 0
A17: =TEXT(Inputs!B110,"") -> Sell Jewels | C17: =IF(C$2=Inputs!$B112,Inputs!$B111,0)*(1+inf)^B$1 -> 0 | D17: =IF(D$2=Inputs!$B112,Inputs!$B111,0)*(1+inf)^C$1 -> 0 | E17: =IF(E$2=Inputs!$B112,Inputs!$B111,0)*(1+inf)^D$1 -> 0 | F17: =IF(F$2=Inputs!$B112,Inputs!$B111,0)*(1+inf)^E$1 -> 0 | G17: =IF(G$2=Inputs!$B112,Inputs!$B111,0)*(1+inf)^F$1 -> 0 | H17: =IF(H$2=Inputs!$B112,Inputs!$B111,0)*(1+inf)^G$1 -> 5657.0411 | I17: =IF(I$2=Inputs!$B112,Inputs!$B111,0)*(1+inf)^H$1 -> 0 | J17: =IF(J$2=Inputs!$B112,Inputs!$B111,0)*(1+inf)^I$1 -> 0 | ... AM17: =IF(AM$2=Inputs!$B112,Inputs!$B111,0)*(1+inf)^AL$1 -> 0
A18: Interest on cash balances | C18: =MAX(AVERAGE(C49,C49+SUM(C5:C17)-C46)*Inputs!$B$149,0) -> 1552.5 | D18: =MAX(AVERAGE(D49,D49+SUM(D5:D17)-D46)*Inputs!$B$149,0) -> 2230.3125 | E18: =MAX(AVERAGE(E49,E49+SUM(E5:E17)-E46)*Inputs!$B$149,0) -> 2705.525 | F18: =MAX(AVERAGE(F49,F49+SUM(F5:F17)-F46)*Inputs!$B$149,0) -> 3328.3481 | G18: =MAX(AVERAGE(G49,G49+SUM(G5:G17)-G46)*Inputs!$B$149,0) -> 4402.1355 | H18: =MAX(AVERAGE(H49,H49+SUM(H5:H17)-H46)*Inputs!$B$149,0) -> 5708.7818 | I18: =MAX(AVERAGE(I49,I49+SUM(I5:I17)-I46)*Inputs!$B$149,0) -> 7274.3832 | J18: =MAX(AVERAGE(J49,J49+SUM(J5:J17)-J46)*Inputs!$B$149,0) -> 8751.5263 | ... AM18: =MAX(AVERAGE(AM49,AM49+SUM(AM5:AM17)-AM46)*Inputs!$B$149,0) -> 54592.712
C19: =SUM(C4:C18) -> 113552.5 | D19: =SUM(D4:D18) -> 117580.31 | E19: =SUM(E4:E18) -> 132012.02 | F19: =SUM(F4:F18) -> 125682.1 | G19: =SUM(G4:G18) -> 130415.73 | H19: =SUM(H4:H18) -> 141148.79 | I19: =SUM(I4:I18) -> 140939.52 | J19: =SUM(J4:J18) -> 146415.02 | ... AM19: =SUM(AM4:AM18) -> 180461.63
A20: Outflows
A21: Credit cards cleared | C21: =Inputs!B75 -> 1000 | D21: 0 | E21: 0 | F21: 0 | G21: 0 | H21: 0 | I21: 0 | J21: 0 | K21: 0 | L21: 0 | M21: 0 | N21: 0 | O21: 0 | P21: 0 | Q21: 0 | R21: 0 | S21: 0 | T21: 0 | U21: 0 | V21: 0 | W21: 0 | X21: 0 | Y21: 0 | Z21: 0 | AA21: 0 | AB21: 0 | AC21: 0 | AD21: 0 | AE21: 0 | AF21: 0 | AG21: 0 | AH21: 0 | AI21: 0 | AJ21: 0 | AK21: 0 | AL21: 0 | AM21: 0
A22: Home loan repayment | C22: =MAX(IF(C$1*12<=Inputs!$G$15,12,(Inputs!$G$15-B$1*12)),0)*Inputs!$B$17 -> 9600 | D22: =MAX(IF(D$1*12<=Inputs!$G$15,12,(Inputs!$G$15-C$1*12)),0)*Inputs!$B$17 -> 9600 | E22: =MAX(IF(E$1*12<=Inputs!$G$15,12,(Inputs!$G$15-D$1*12)),0)*Inputs!$B$17 -> 9600 | F22: =MAX(IF(F$1*12<=Inputs!$G$15,12,(Inputs!$G$15-E$1*12)),0)*Inputs!$B$17 -> 9600 | G22: =MAX(IF(G$1*12<=Inputs!$G$15,12,(Inputs!$G$15-F$1*12)),0)*Inputs!$B$17 -> 9600 | H22: =MAX(IF(H$1*12<=Inputs!$G$15,12,(Inputs!$G$15-G$1*12)),0)*Inputs!$B$17 -> 6435.6231 | I22: =MAX(IF(I$1*12<=Inputs!$G$15,12,(Inputs!$G$15-H$1*12)),0)*Inputs!$B$17 -> 0 | J22: =MAX(IF(J$1*12<=Inputs!$G$15,12,(Inputs!$G$15-I$1*12)),0)*Inputs!$B$17 -> 0 | ... AM22: =MAX(IF(AM$1*12<=Inputs!$G$15,12,(Inputs!$G$15-AL$1*12)),0)*Inputs!$B$17 -> 0
A23: Other property loans repayments
A24: =TEXT(Inputs!$B$50,"") -> Sliema | C24: =MAX(IF(C$1*12<=Inputs!$G$78,12,(Inputs!$G$78-B$1*12)),0)*Inputs!$B$80 -> 6000 | D24: =MAX(IF(D$1*12<=Inputs!$G$78,12,(Inputs!$G$78-C$1*12)),0)*Inputs!$B$80 -> 6000 | E24: =MAX(IF(E$1*12<=Inputs!$G$78,12,(Inputs!$G$78-D$1*12)),0)*Inputs!$B$80 -> 6000 | F24: =MAX(IF(F$1*12<=Inputs!$G$78,12,(Inputs!$G$78-E$1*12)),0)*Inputs!$B$80 -> 6000 | G24: =MAX(IF(G$1*12<=Inputs!$G$78,12,(Inputs!$G$78-F$1*12)),0)*Inputs!$B$80 -> 6000 | H24: =MAX(IF(H$1*12<=Inputs!$G$78,12,(Inputs!$G$78-G$1*12)),0)*Inputs!$B$80 -> 6000 | I24: =MAX(IF(I$1*12<=Inputs!$G$78,12,(Inputs!$G$78-H$1*12)),0)*Inputs!$B$80 -> 6000 | J24: =MAX(IF(J$1*12<=Inputs!$G$78,12,(Inputs!$G$78-I$1*12)),0)*Inputs!$B$80 -> 6000 | ... AM24: =MAX(IF(AM$1*12<=Inputs!$G$78,12,(Inputs!$G$78-AL$1*12)),0)*Inputs!$B$80 -> 0
A25: =TEXT(Inputs!$B$55,"") -> Gzira | C25: =MAX(IF(C$1*12<=Inputs!$G$83,12,(Inputs!$G$83-B$1*12)),0)*Inputs!$B$85 -> 2400 | D25: =MAX(IF(D$1*12<=Inputs!$G$83,12,(Inputs!$G$83-C$1*12)),0)*Inputs!$B$85 -> 2400 | E25: =MAX(IF(E$1*12<=Inputs!$G$83,12,(Inputs!$G$83-D$1*12)),0)*Inputs!$B$85 -> 2400 | F25: =MAX(IF(F$1*12<=Inputs!$G$83,12,(Inputs!$G$83-E$1*12)),0)*Inputs!$B$85 -> 1623.4029 | G25: =MAX(IF(G$1*12<=Inputs!$G$83,12,(Inputs!$G$83-F$1*12)),0)*Inputs!$B$85 -> 0 | H25: =MAX(IF(H$1*12<=Inputs!$G$83,12,(Inputs!$G$83-G$1*12)),0)*Inputs!$B$85 -> 0 | I25: =MAX(IF(I$1*12<=Inputs!$G$83,12,(Inputs!$G$83-H$1*12)),0)*Inputs!$B$85 -> 0 | J25: =MAX(IF(J$1*12<=Inputs!$G$83,12,(Inputs!$G$83-I$1*12)),0)*Inputs!$B$85 -> 0 | ... AM25: =MAX(IF(AM$1*12<=Inputs!$G$83,12,(Inputs!$G$83-AL$1*12)),0)*Inputs!$B$85 -> 0
A26: =TEXT(Inputs!$B$60,"") -> Qormi | C26: =MAX(IF(C$1*12<=Inputs!$G$88,12,(Inputs!$G$88-B$1*12)),0)*Inputs!$B$90 -> 3000 | D26: =MAX(IF(D$1*12<=Inputs!$G$88,12,(Inputs!$G$88-C$1*12)),0)*Inputs!$B$90 -> 3000 | E26: =MAX(IF(E$1*12<=Inputs!$G$88,12,(Inputs!$G$88-D$1*12)),0)*Inputs!$B$90 -> 3000 | F26: =MAX(IF(F$1*12<=Inputs!$G$88,12,(Inputs!$G$88-E$1*12)),0)*Inputs!$B$90 -> 3000 | G26: =MAX(IF(G$1*12<=Inputs!$G$88,12,(Inputs!$G$88-F$1*12)),0)*Inputs!$B$90 -> 3000 | H26: =MAX(IF(H$1*12<=Inputs!$G$88,12,(Inputs!$G$88-G$1*12)),0)*Inputs!$B$90 -> 2296.8597 | I26: =MAX(IF(I$1*12<=Inputs!$G$88,12,(Inputs!$G$88-H$1*12)),0)*Inputs!$B$90 -> 0 | J26: =MAX(IF(J$1*12<=Inputs!$G$88,12,(Inputs!$G$88-I$1*12)),0)*Inputs!$B$90 -> 0 | ... AM26: =MAX(IF(AM$1*12<=Inputs!$G$88,12,(Inputs!$G$88-AL$1*12)),0)*Inputs!$B$90 -> 0
A27: Other loan repayment | C27: =MAX(IF(C$1*12<=Inputs!$G$93,12,(Inputs!$G$93-B$1*12)),0)*Inputs!$B$95 -> 600 | D27: =MAX(IF(D$1*12<=Inputs!$G$93,12,(Inputs!$G$93-C$1*12)),0)*Inputs!$B$95 -> 600 | E27: =MAX(IF(E$1*12<=Inputs!$G$93,12,(Inputs!$G$93-D$1*12)),0)*Inputs!$B$95 -> 600 | F27: =MAX(IF(F$1*12<=Inputs!$G$93,12,(Inputs!$G$93-E$1*12)),0)*Inputs!$B$95 -> 600 | G27: =MAX(IF(G$1*12<=Inputs!$G$93,12,(Inputs!$G$93-F$1*12)),0)*Inputs!$B$95 -> 600 | H27: =MAX(IF(H$1*12<=Inputs!$G$93,12,(Inputs!$G$93-G$1*12)),0)*Inputs!$B$95 -> 600 | I27: =MAX(IF(I$1*12<=Inputs!$G$93,12,(Inputs!$G$93-H$1*12)),0)*Inputs!$B$95 -> 600 | J27: =MAX(IF(J$1*12<=Inputs!$G$93,12,(Inputs!$G$93-I$1*12)),0)*Inputs!$B$95 -> 600 | ... AM27: =MAX(IF(AM$1*12<=Inputs!$G$93,12,(Inputs!$G$93-AL$1*12)),0)*Inputs!$B$95 -> 0
A28: Dependents cost
A29: =TEXT(Inputs!B33,"") -> John | C29: =IF(Inputs!$B$35>=C$1,Inputs!$B$34,0)*(1+inf)^B$1 -> 2000 | D29: =IF(Inputs!$B$35>=D$1,Inputs!$B$34,0)*(1+inf)^C$1 -> 2050 | E29: =IF(Inputs!$B$35>=E$1,Inputs!$B$34,0)*(1+inf)^D$1 -> 2101.25 | F29: =IF(Inputs!$B$35>=F$1,Inputs!$B$34,0)*(1+inf)^E$1 -> 0 | G29: =IF(Inputs!$B$35>=G$1,Inputs!$B$34,0)*(1+inf)^F$1 -> 0 | H29: =IF(Inputs!$B$35>=H$1,Inputs!$B$34,0)*(1+inf)^G$1 -> 0 | I29: =IF(Inputs!$B$35>=I$1,Inputs!$B$34,0)*(1+inf)^H$1 -> 0 | J29: =IF(Inputs!$B$35>=J$1,Inputs!$B$34,0)*(1+inf)^I$1 -> 0 | ... AM29: =IF(Inputs!$B$35>=AM$1,Inputs!$B$34,0)*(1+inf)^AL$1 -> 0
A30: =TEXT(Inputs!B38,"") -> Jack | C30: =IF(Inputs!$B$40>=C$1,Inputs!$B$39,0)*(1+inf)^B$1 -> 1000 | D30: =IF(Inputs!$B$40>=D$1,Inputs!$B$39,0)*(1+inf)^C$1 -> 1025 | E30: =IF(Inputs!$B$40>=E$1,Inputs!$B$39,0)*(1+inf)^D$1 -> 1050.625 | F30: =IF(Inputs!$B$40>=F$1,Inputs!$B$39,0)*(1+inf)^E$1 -> 1076.8906 | G30: =IF(Inputs!$B$40>=G$1,Inputs!$B$39,0)*(1+inf)^F$1 -> 1103.8129 | H30: =IF(Inputs!$B$40>=H$1,Inputs!$B$39,0)*(1+inf)^G$1 -> 0 | I30: =IF(Inputs!$B$40>=I$1,Inputs!$B$39,0)*(1+inf)^H$1 -> 0 | J30: =IF(Inputs!$B$40>=J$1,Inputs!$B$39,0)*(1+inf)^I$1 -> 0 | ... AM30: =IF(Inputs!$B$40>=AM$1,Inputs!$B$39,0)*(1+inf)^AL$1 -> 0
A31: =TEXT(Inputs!B43,"") -> Bill | C31: =IF(Inputs!$B$45>=C$1,Inputs!$B$44,0)*(1+inf)^B$1 -> 4000 | D31: =IF(Inputs!$B$45>=D$1,Inputs!$B$44,0)*(1+inf)^C$1 -> 4100 | E31: =IF(Inputs!$B$45>=E$1,Inputs!$B$44,0)*(1+inf)^D$1 -> 0 | F31: =IF(Inputs!$B$45>=F$1,Inputs!$B$44,0)*(1+inf)^E$1 -> 0 | G31: =IF(Inputs!$B$45>=G$1,Inputs!$B$44,0)*(1+inf)^F$1 -> 0 | H31: =IF(Inputs!$B$45>=H$1,Inputs!$B$44,0)*(1+inf)^G$1 -> 0 | I31: =IF(Inputs!$B$45>=I$1,Inputs!$B$44,0)*(1+inf)^H$1 -> 0 | J31: =IF(Inputs!$B$45>=J$1,Inputs!$B$44,0)*(1+inf)^I$1 -> 0 | ... AM31: =IF(Inputs!$B$45>=AM$1,Inputs!$B$44,0)*(1+inf)^AL$1 -> 0
A32: Housing rent | C32: =Inputs!$B$23*(1+inf)^B$1 -> 0 | D32: =Inputs!$B$23*(1+inf)^C$1 -> 0 | E32: =Inputs!$B$23*(1+inf)^D$1 -> 0 | F32: =Inputs!$B$23*(1+inf)^E$1 -> 0 | G32: =Inputs!$B$23*(1+inf)^F$1 -> 0 | H32: =Inputs!$B$23*(1+inf)^G$1 -> 0 | I32: =Inputs!$B$23*(1+inf)^H$1 -> 0 | J32: =Inputs!$B$23*(1+inf)^I$1 -> 0 | ... AM32: =Inputs!$B$23*(1+inf)^AL$1 -> 0
A33: Other property costs
A34: =TEXT(Inputs!$B$50,"") -> Sliema | C34: =Inputs!$B52*(1+inf)^B$1 -> 5000 | D34: =Inputs!$B52*(1+inf)^C$1 -> 5125 | E34: =Inputs!$B52*(1+inf)^D$1 -> 5253.125 | F34: =Inputs!$B52*(1+inf)^E$1 -> 5384.4531 | G34: =Inputs!$B52*(1+inf)^F$1 -> 5519.0645 | H34: =Inputs!$B52*(1+inf)^G$1 -> 5657.0411 | I34: =Inputs!$B52*(1+inf)^H$1 -> 5798.4671 | J34: =Inputs!$B52*(1+inf)^I$1 -> 5943.4288 | ... AM34: =Inputs!$B52*(1+inf)^AL$1 -> 12162.677
A35: =TEXT(Inputs!$B$55,"") -> Gzira | C35: =Inputs!$B57*(1+inf)^B$1 -> 2000 | D35: =Inputs!$B57*(1+inf)^C$1 -> 2050 | E35: =Inputs!$B57*(1+inf)^D$1 -> 2101.25 | F35: =Inputs!$B57*(1+inf)^E$1 -> 2153.7812 | G35: =Inputs!$B57*(1+inf)^F$1 -> 2207.6258 | H35: =Inputs!$B57*(1+inf)^G$1 -> 2262.8164 | I35: =Inputs!$B57*(1+inf)^H$1 -> 2319.3868 | J35: =Inputs!$B57*(1+inf)^I$1 -> 2377.3715 | ... AM35: =Inputs!$B57*(1+inf)^AL$1 -> 4865.0706
A36: =TEXT(Inputs!$B$60,"") -> Qormi | C36: =Inputs!$B62*(1+inf)^B$1 -> 1200 | D36: =Inputs!$B62*(1+inf)^C$1 -> 1230 | E36: =Inputs!$B62*(1+inf)^D$1 -> 1260.75 | F36: =Inputs!$B62*(1+inf)^E$1 -> 1292.2687 | G36: =Inputs!$B62*(1+inf)^F$1 -> 1324.5755 | H36: =Inputs!$B62*(1+inf)^G$1 -> 1357.6899 | I36: =Inputs!$B62*(1+inf)^H$1 -> 1391.6321 | J36: =Inputs!$B62*(1+inf)^I$1 -> 1426.4229 | ... AM36: =Inputs!$B62*(1+inf)^AL$1 -> 2919.0424
A37: Living expenses
A38: Current baseline | C38: =Inputs!$B$25*(1+inf)^B$1 -> 50000 | D38: =Inputs!$B$25*(1+inf)^C$1 -> 51250 | E38: =Inputs!$B$25*(1+inf)^D$1 -> 52531.25 | F38: =Inputs!$B$25*(1+inf)^E$1 -> 53844.531 | G38: =Inputs!$B$25*(1+inf)^F$1 -> 55190.645 | H38: =Inputs!$B$25*(1+inf)^G$1 -> 56570.411 | I38: =Inputs!$B$25*(1+inf)^H$1 -> 57984.671 | J38: =Inputs!$B$25*(1+inf)^I$1 -> 59434.288 | ... AM38: =Inputs!$B$25*(1+inf)^AL$1 -> 121626.77
A39: ="Adjustment "&Inputs!A137 -> Adjustment from now to 65 | C39: =IF(C$3<=65,Inputs!$B$137*C$38,0) -> 0 | D39: =IF(D$3<=65,Inputs!$B$137*D$38,0) -> 0 | E39: =IF(E$3<=65,Inputs!$B$137*E$38,0) -> 0 | F39: =IF(F$3<=65,Inputs!$B$137*F$38,0) -> 0 | G39: =IF(G$3<=65,Inputs!$B$137*G$38,0) -> 0 | H39: =IF(H$3<=65,Inputs!$B$137*H$38,0) -> 0 | I39: =IF(I$3<=65,Inputs!$B$137*I$38,0) -> 0 | J39: =IF(J$3<=65,Inputs!$B$137*J$38,0) -> 0 | ... AM39: =IF(AM$3<=65,Inputs!$B$137*AM$38,0) -> 0
A40: ="Adjustment "&Inputs!A138 -> Adjustment from 66-75 | C40: =IF(AND(C$3>65,C$3<=75),Inputs!$B$138*C38,0) -> 0 | D40: =IF(AND(D$3>65,D$3<=75),Inputs!$B$138*D38,0) -> 0 | E40: =IF(AND(E$3>65,E$3<=75),Inputs!$B$138*E38,0) -> 0 | F40: =IF(AND(F$3>65,F$3<=75),Inputs!$B$138*F38,0) -> 0 | G40: =IF(AND(G$3>65,G$3<=75),Inputs!$B$138*G38,0) -> 0 | H40: =IF(AND(H$3>65,H$3<=75),Inputs!$B$138*H38,0) -> 0 | I40: =IF(AND(I$3>65,I$3<=75),Inputs!$B$138*I38,0) -> 0 | J40: =IF(AND(J$3>65,J$3<=75),Inputs!$B$138*J38,0) -> 0 | ... AM40: =IF(AND(AM$3>65,AM$3<=75),Inputs!$B$138*AM38,0) -> 0
...

Sheet RetEarly_Engine
B1: 0 | C1: 1 | D1: =C1+1 -> 2 | E1: =D1+1 -> 3 | F1: =E1+1 -> 4 | G1: =F1+1 -> 5 | H1: =G1+1 -> 6 | I1: =H1+1 -> 7 | J1: =I1+1 -> 8 | K1: =J1+1 -> 9 | ... AM1: =AL1+1 -> 37
B2: Year | C2: =YEAR(TODAY())+1 -> 2027 | D2: =C2+1 -> 2028 | E2: =D2+1 -> 2029 | F2: =E2+1 -> 2030 | G2: =F2+1 -> 2031 | H2: =G2+1 -> 2032 | I2: =H2+1 -> 2033 | J2: =I2+1 -> 2034 | K2: =J2+1 -> 2035 | ... AM2: =AL2+1 -> 2063
B3: 55 | C3: =Inputs!B4+1 -> 49 | D3: =C3+1 -> 50 | E3: =D3+1 -> 51 | F3: =E3+1 -> 52 | G3: =F3+1 -> 53 | H3: =G3+1 -> 54 | I3: =H3+1 -> 55 | J3: =I3+1 -> 56 | K3: =J3+1 -> 57 | ... AM3: =AL3+1 -> 85
A4: Inflows
A5: Net employment / self-employment income | C5: =IF(AND(Inputs!$B$19>C3,$B$3>C3),Inputs!$B$6*(1+sincr)^B1,0) -> 80000 | D5: =IF(AND(Inputs!$B$19>D3,$B$3>D3),Inputs!$B$6*(1+sincr)^C1,0) -> 82400 | E5: =IF(AND(Inputs!$B$19>E3,$B$3>E3),Inputs!$B$6*(1+sincr)^D1,0) -> 84872 | F5: =IF(AND(Inputs!$B$19>F3,$B$3>F3),Inputs!$B$6*(1+sincr)^E1,0) -> 87418.16 | G5: =IF(AND(Inputs!$B$19>G3,$B$3>G3),Inputs!$B$6*(1+sincr)^F1,0) -> 90040.705 | H5: =IF(AND(Inputs!$B$19>H3,$B$3>H3),Inputs!$B$6*(1+sincr)^G1,0) -> 92741.926 | I5: =IF(AND(Inputs!$B$19>I3,$B$3>I3),Inputs!$B$6*(1+sincr)^H1,0) -> 0 | J5: =IF(AND(Inputs!$B$19>J3,$B$3>J3),Inputs!$B$6*(1+sincr)^I1,0) -> 0 | ... AM5: =IF(AND(Inputs!$B$19>AM3,$B$3>AM3),Inputs!$B$6*(1+sincr)^AL1,0) -> 0
A6: Net from other work | C6: =IF(C$3<=Inputs!$B$71,Inputs!$B$70,0)*(1+inf)^B$1 -> 2000 | D6: =IF(D$3<=Inputs!$B$71,Inputs!$B$70,0)*(1+inf)^C$1 -> 2050 | E6: =IF(E$3<=Inputs!$B$71,Inputs!$B$70,0)*(1+inf)^D$1 -> 2101.25 | F6: =IF(F$3<=Inputs!$B$71,Inputs!$B$70,0)*(1+inf)^E$1 -> 2153.7812 | G6: =IF(G$3<=Inputs!$B$71,Inputs!$B$70,0)*(1+inf)^F$1 -> 2207.6258 | H6: =IF(H$3<=Inputs!$B$71,Inputs!$B$70,0)*(1+inf)^G$1 -> 2262.8164 | I6: =IF(I$3<=Inputs!$B$71,Inputs!$B$70,0)*(1+inf)^H$1 -> 2319.3868 | J6: =IF(J$3<=Inputs!$B$71,Inputs!$B$70,0)*(1+inf)^I$1 -> 2377.3715 | ... AM6: =IF(AM$3<=Inputs!$B$71,Inputs!$B$70,0)*(1+inf)^AL$1 -> 0
A7: Net rental income from other properties
A8: =TEXT(Inputs!$B$50,"") -> Sliema | C8: =Inputs!B66 -> 12000 | D8: =C8*(1+rinc) -> 12360 | E8: =D8*(1+rinc) -> 12730.8 | F8: =E8*(1+rinc) -> 13112.724 | G8: =F8*(1+rinc) -> 13506.106 | H8: =G8*(1+rinc) -> 13911.289 | I8: =H8*(1+rinc) -> 14328.628 | J8: =I8*(1+rinc) -> 14758.486 | K8: =J8*(1+rinc) -> 15201.241 | ... AM8: =AL8*(1+rinc) -> 34779.34
A9: =TEXT(Inputs!$B$55,"") -> Gzira | C9: =Inputs!B67 -> 10000 | D9: =C9*(1+rinc) -> 10300 | E9: =D9*(1+rinc) -> 10609 | F9: =E9*(1+rinc) -> 10927.27 | G9: =F9*(1+rinc) -> 11255.088 | H9: =G9*(1+rinc) -> 11592.741 | I9: =H9*(1+rinc) -> 11940.523 | J9: =I9*(1+rinc) -> 12298.739 | K9: =J9*(1+rinc) -> 12667.701 | ... AM9: =AL9*(1+rinc) -> 28982.783
A10: =TEXT(Inputs!$B$60,"") -> Qormi | C10: =Inputs!B68 -> 8000 | D10: =C10*(1+rinc) -> 8240 | E10: =D10*(1+rinc) -> 8487.2 | F10: =E10*(1+rinc) -> 8741.816 | G10: =F10*(1+rinc) -> 9004.0705 | H10: =G10*(1+rinc) -> 9274.1926 | I10: =H10*(1+rinc) -> 9552.4184 | J10: =I10*(1+rinc) -> 9838.9909 | K10: =J10*(1+rinc) -> 10134.161 | ... AM10: =AL10*(1+rinc) -> 23186.227
A11: Full pension | C11: =IF(C$3<Inputs!$B$19,0,Inputs!$B$21)*(1+inf)^B$1 -> 0 | D11: =IF(D$3<Inputs!$B$19,0,Inputs!$B$21)*(1+inf)^C$1 -> 0 | E11: =IF(E$3<Inputs!$B$19,0,Inputs!$B$21)*(1+inf)^D$1 -> 0 | F11: =IF(F$3<Inputs!$B$19,0,Inputs!$B$21)*(1+inf)^E$1 -> 0 | G11: =IF(G$3<Inputs!$B$19,0,Inputs!$B$21)*(1+inf)^F$1 -> 0 | H11: =IF(H$3<Inputs!$B$19,0,Inputs!$B$21)*(1+inf)^G$1 -> 0 | I11: =IF(I$3<Inputs!$B$19,0,Inputs!$B$21)*(1+inf)^H$1 -> 0 | J11: =IF(J$3<Inputs!$B$19,0,Inputs!$B$21)*(1+inf)^I$1 -> 0 | ... AM11: =IF(AM$3<Inputs!$B$19,0,Inputs!$B$21)*(1+inf)^AL$1 -> 38920.565
A12: Pension reduction from early retirement | C12: =MIN(0,MAX(-IF(C11=0,0,(Inputs!$B$19-INDEX(3:3,MATCH(0,5:5,0))))*Inputs!$B$157*(1+inf)^B$1,-C11)) -> 0 | D12: =MIN(0,MAX(-IF(D11=0,0,(Inputs!$B$19-INDEX(3:3,MATCH(0,5:5,0))))*Inputs!$B$157*(1+inf)^C$1,-D11)) -> 0 | E12: =MIN(0,MAX(-IF(E11=0,0,(Inputs!$B$19-INDEX(3:3,MATCH(0,5:5,0))))*Inputs!$B$157*(1+inf)^D$1,-E11)) -> 0 | F12: =MIN(0,MAX(-IF(F11=0,0,(Inputs!$B$19-INDEX(3:3,MATCH(0,5:5,0))))*Inputs!$B$157*(1+inf)^E$1,-F11)) -> 0 | G12: =MIN(0,MAX(-IF(G11=0,0,(Inputs!$B$19-INDEX(3:3,MATCH(0,5:5,0))))*Inputs!$B$157*(1+inf)^F$1,-G11)) -> 0 | H12: =MIN(0,MAX(-IF(H11=0,0,(Inputs!$B$19-INDEX(3:3,MATCH(0,5:5,0))))*Inputs!$B$157*(1+inf)^G$1,-H11)) -> 0 | I12: =MIN(0,MAX(-IF(I11=0,0,(Inputs!$B$19-INDEX(3:3,MATCH(0,5:5,0))))*Inputs!$B$157*(1+inf)^H$1,-I11)) -> 0 | J12: =MIN(0,MAX(-IF(J11=0,0,(Inputs!$B$19-INDEX(3:3,MATCH(0,5:5,0))))*Inputs!$B$157*(1+inf)^I$1,-J11)) -> 0 | ... AM12: =MIN(0,MAX(-IF(AM11=0,0,(Inputs!$B$19-INDEX(3:3,MATCH(0,5:5,0))))*Inputs!$B$157*(1+inf)^AL$1,-AM11)) -> -7297.6059
A13: Other post-retirement income | C13: =IF(AND(C$3>=Inputs!$B$142,C$3<=Inputs!$B$143),Inputs!$B$141*(1+inf)^B$1,0) -> 0 | D13: =IF(AND(D$3>=Inputs!$B$142,D$3<=Inputs!$B$143),Inputs!$B$141*(1+inf)^C$1,0) -> 0 | E13: =IF(AND(E$3>=Inputs!$B$142,E$3<=Inputs!$B$143),Inputs!$B$141*(1+inf)^D$1,0) -> 0 | F13: =IF(AND(F$3>=Inputs!$B$142,F$3<=Inputs!$B$143),Inputs!$B$141*(1+inf)^E$1,0) -> 0 | G13: =IF(AND(G$3>=Inputs!$B$142,G$3<=Inputs!$B$143),Inputs!$B$141*(1+inf)^F$1,0) -> 0 | H13: =IF(AND(H$3>=Inputs!$B$142,H$3<=Inputs!$B$143),Inputs!$B$141*(1+inf)^G$1,0) -> 0 | I13: =IF(AND(I$3>=Inputs!$B$142,I$3<=Inputs!$B$143),Inputs!$B$141*(1+inf)^H$1,0) -> 0 | J13: =IF(AND(J$3>=Inputs!$B$142,J$3<=Inputs!$B$143),Inputs!$B$141*(1+inf)^I$1,0) -> 0 | ... AM13: =IF(AND(AM$3>=Inputs!$B$142,AM$3<=Inputs!$B$143),Inputs!$B$141*(1+inf)^AL$1,0) -> 0
A14: Major one-off income events
A15: =TEXT(Inputs!B100,"") -> Inheritance | C15: =IF(C$2=Inputs!$B102,Inputs!$B101,0)*(1+inf)^B$1 -> 0 | D15: =IF(D$2=Inputs!$B102,Inputs!$B101,0)*(1+inf)^C$1 -> 0 | E15: =IF(E$2=Inputs!$B102,Inputs!$B101,0)*(1+inf)^D$1 -> 0 | F15: =IF(F$2=Inputs!$B102,Inputs!$B101,0)*(1+inf)^E$1 -> 0 | G15: =IF(G$2=Inputs!$B102,Inputs!$B101,0)*(1+inf)^F$1 -> 0 | H15: =IF(H$2=Inputs!$B102,Inputs!$B101,0)*(1+inf)^G$1 -> 0 | I15: =IF(I$2=Inputs!$B102,Inputs!$B101,0)*(1+inf)^H$1 -> 0 | J15: =IF(J$2=Inputs!$B102,Inputs!$B101,0)*(1+inf)^I$1 -> 0 | ... AM15: =IF(AM$2=Inputs!$B102,Inputs!$B101,0)*(1+inf)^AL$1 -> 0
A16: =TEXT(Inputs!B105,"") -> Sell Painting | C16: =IF(C$2=Inputs!$B107,Inputs!$B106,0)*(1+inf)^B$1 -> 0 | D16: =IF(D$2=Inputs!$B107,Inputs!$B106,0)*(1+inf)^C$1 -> 0 | E16: =IF(E$2=Inputs!$B107,Inputs!$B106,0)*(1+inf)^D$1 -> 10506.25 | F16: =IF(F$2=Inputs!$B107,Inputs!$B106,0)*(1+inf)^E$1 -> 0 | G16: =IF(G$2=Inputs!$B107,Inputs!$B106,0)*(1+inf)^F$1 -> 0 | H16: =IF(H$2=Inputs!$B107,Inputs!$B106,0)*(1+inf)^G$1 -> 0 | I16: =IF(I$2=Inputs!$B107,Inputs!$B106,0)*(1+inf)^H$1 -> 0 | J16: =IF(J$2=Inputs!$B107,Inputs!$B106,0)*(1+inf)^I$1 -> 0 | ... AM16: =IF(AM$2=Inputs!$B107,Inputs!$B106,0)*(1+inf)^AL$1 -> 0
A17: =TEXT(Inputs!B110,"") -> Sell Jewels | C17: =IF(C$2=Inputs!$B112,Inputs!$B111,0)*(1+inf)^B$1 -> 0 | D17: =IF(D$2=Inputs!$B112,Inputs!$B111,0)*(1+inf)^C$1 -> 0 | E17: =IF(E$2=Inputs!$B112,Inputs!$B111,0)*(1+inf)^D$1 -> 0 | F17: =IF(F$2=Inputs!$B112,Inputs!$B111,0)*(1+inf)^E$1 -> 0 | G17: =IF(G$2=Inputs!$B112,Inputs!$B111,0)*(1+inf)^F$1 -> 0 | H17: =IF(H$2=Inputs!$B112,Inputs!$B111,0)*(1+inf)^G$1 -> 5657.0411 | I17: =IF(I$2=Inputs!$B112,Inputs!$B111,0)*(1+inf)^H$1 -> 0 | J17: =IF(J$2=Inputs!$B112,Inputs!$B111,0)*(1+inf)^I$1 -> 0 | ... AM17: =IF(AM$2=Inputs!$B112,Inputs!$B111,0)*(1+inf)^AL$1 -> 0
A18: Interest on cash balances | C18: =MAX(AVERAGE(C49,C49+SUM(C5:C17)-C46)*Inputs!$B$149,0) -> 1552.5 | D18: =MAX(AVERAGE(D49,D49+SUM(D5:D17)-D46)*Inputs!$B$149,0) -> 2230.3125 | E18: =MAX(AVERAGE(E49,E49+SUM(E5:E17)-E46)*Inputs!$B$149,0) -> 2705.525 | F18: =MAX(AVERAGE(F49,F49+SUM(F5:F17)-F46)*Inputs!$B$149,0) -> 3328.3481 | G18: =MAX(AVERAGE(G49,G49+SUM(G5:G17)-G46)*Inputs!$B$149,0) -> 4402.1355 | H18: =MAX(AVERAGE(H49,H49+SUM(H5:H17)-H46)*Inputs!$B$149,0) -> 5708.7818 | I18: =MAX(AVERAGE(I49,I49+SUM(I5:I17)-I46)*Inputs!$B$149,0) -> 6080.3309 | J18: =MAX(AVERAGE(J49,J49+SUM(J5:J17)-J46)*Inputs!$B$149,0) -> 5103.6966 | ... AM18: =MAX(AVERAGE(AM49,AM49+SUM(AM5:AM17)-AM46)*Inputs!$B$149,0) -> 315.53424
C19: =SUM(C4:C18) -> 113552.5 | D19: =SUM(D4:D18) -> 117580.31 | E19: =SUM(E4:E18) -> 132012.02 | F19: =SUM(F4:F18) -> 125682.1 | G19: =SUM(G4:G18) -> 130415.73 | H19: =SUM(H4:H18) -> 141148.79 | I19: =SUM(I4:I18) -> 44221.287 | J19: =SUM(J4:J18) -> 44377.284 | ... AM19: =SUM(AM4:AM18) -> 118886.84
A20: Outflows
A21: Credit cards cleared | C21: =Inputs!B75 -> 1000 | D21: 0 | E21: 0 | F21: 0 | G21: 0 | H21: 0 | I21: 0 | J21: 0 | K21: 0 | L21: 0 | M21: 0 | N21: 0 | O21: 0 | P21: 0 | Q21: 0 | R21: 0 | S21: 0 | T21: 0 | U21: 0 | V21: 0 | W21: 0 | X21: 0 | Y21: 0 | Z21: 0 | AA21: 0 | AB21: 0 | AC21: 0 | AD21: 0 | AE21: 0 | AF21: 0 | AG21: 0 | AH21: 0 | AI21: 0 | AJ21: 0 | AK21: 0 | AL21: 0 | AM21: 0
A22: Home loan repayment | C22: =MAX(IF(C$1*12<=Inputs!$G$15,12,(Inputs!$G$15-B$1*12)),0)*Inputs!$B$17 -> 9600 | D22: =MAX(IF(D$1*12<=Inputs!$G$15,12,(Inputs!$G$15-C$1*12)),0)*Inputs!$B$17 -> 9600 | E22: =MAX(IF(E$1*12<=Inputs!$G$15,12,(Inputs!$G$15-D$1*12)),0)*Inputs!$B$17 -> 9600 | F22: =MAX(IF(F$1*12<=Inputs!$G$15,12,(Inputs!$G$15-E$1*12)),0)*Inputs!$B$17 -> 9600 | G22: =MAX(IF(G$1*12<=Inputs!$G$15,12,(Inputs!$G$15-F$1*12)),0)*Inputs!$B$17 -> 9600 | H22: =MAX(IF(H$1*12<=Inputs!$G$15,12,(Inputs!$G$15-G$1*12)),0)*Inputs!$B$17 -> 6435.6231 | I22: =MAX(IF(I$1*12<=Inputs!$G$15,12,(Inputs!$G$15-H$1*12)),0)*Inputs!$B$17 -> 0 | J22: =MAX(IF(J$1*12<=Inputs!$G$15,12,(Inputs!$G$15-I$1*12)),0)*Inputs!$B$17 -> 0 | ... AM22: =MAX(IF(AM$1*12<=Inputs!$G$15,12,(Inputs!$G$15-AL$1*12)),0)*Inputs!$B$17 -> 0
A23: Other property loans repayments
A24: =TEXT(Inputs!$B$50,"") -> Sliema | C24: =MAX(IF(C$1*12<=Inputs!$G$78,12,(Inputs!$G$78-B$1*12)),0)*Inputs!$B$80 -> 6000 | D24: =MAX(IF(D$1*12<=Inputs!$G$78,12,(Inputs!$G$78-C$1*12)),0)*Inputs!$B$80 -> 6000 | E24: =MAX(IF(E$1*12<=Inputs!$G$78,12,(Inputs!$G$78-D$1*12)),0)*Inputs!$B$80 -> 6000 | F24: =MAX(IF(F$1*12<=Inputs!$G$78,12,(Inputs!$G$78-E$1*12)),0)*Inputs!$B$80 -> 6000 | G24: =MAX(IF(G$1*12<=Inputs!$G$78,12,(Inputs!$G$78-F$1*12)),0)*Inputs!$B$80 -> 6000 | H24: =MAX(IF(H$1*12<=Inputs!$G$78,12,(Inputs!$G$78-G$1*12)),0)*Inputs!$B$80 -> 6000 | I24: =MAX(IF(I$1*12<=Inputs!$G$78,12,(Inputs!$G$78-H$1*12)),0)*Inputs!$B$80 -> 6000 | J24: =MAX(IF(J$1*12<=Inputs!$G$78,12,(Inputs!$G$78-I$1*12)),0)*Inputs!$B$80 -> 6000 | ... AM24: =MAX(IF(AM$1*12<=Inputs!$G$78,12,(Inputs!$G$78-AL$1*12)),0)*Inputs!$B$80 -> 0
A25: =TEXT(Inputs!$B$55,"") -> Gzira | C25: =MAX(IF(C$1*12<=Inputs!$G$83,12,(Inputs!$G$83-B$1*12)),0)*Inputs!$B$85 -> 2400 | D25: =MAX(IF(D$1*12<=Inputs!$G$83,12,(Inputs!$G$83-C$1*12)),0)*Inputs!$B$85 -> 2400 | E25: =MAX(IF(E$1*12<=Inputs!$G$83,12,(Inputs!$G$83-D$1*12)),0)*Inputs!$B$85 -> 2400 | F25: =MAX(IF(F$1*12<=Inputs!$G$83,12,(Inputs!$G$83-E$1*12)),0)*Inputs!$B$85 -> 1623.4029 | G25: =MAX(IF(G$1*12<=Inputs!$G$83,12,(Inputs!$G$83-F$1*12)),0)*Inputs!$B$85 -> 0 | H25: =MAX(IF(H$1*12<=Inputs!$G$83,12,(Inputs!$G$83-G$1*12)),0)*Inputs!$B$85 -> 0 | I25: =MAX(IF(I$1*12<=Inputs!$G$83,12,(Inputs!$G$83-H$1*12)),0)*Inputs!$B$85 -> 0 | J25: =MAX(IF(J$1*12<=Inputs!$G$83,12,(Inputs!$G$83-I$1*12)),0)*Inputs!$B$85 -> 0 | ... AM25: =MAX(IF(AM$1*12<=Inputs!$G$83,12,(Inputs!$G$83-AL$1*12)),0)*Inputs!$B$85 -> 0
A26: =TEXT(Inputs!$B$60,"") -> Qormi | C26: =MAX(IF(C$1*12<=Inputs!$G$88,12,(Inputs!$G$88-B$1*12)),0)*Inputs!$B$90 -> 3000 | D26: =MAX(IF(D$1*12<=Inputs!$G$88,12,(Inputs!$G$88-C$1*12)),0)*Inputs!$B$90 -> 3000 | E26: =MAX(IF(E$1*12<=Inputs!$G$88,12,(Inputs!$G$88-D$1*12)),0)*Inputs!$B$90 -> 3000 | F26: =MAX(IF(F$1*12<=Inputs!$G$88,12,(Inputs!$G$88-E$1*12)),0)*Inputs!$B$90 -> 3000 | G26: =MAX(IF(G$1*12<=Inputs!$G$88,12,(Inputs!$G$88-F$1*12)),0)*Inputs!$B$90 -> 3000 | H26: =MAX(IF(H$1*12<=Inputs!$G$88,12,(Inputs!$G$88-G$1*12)),0)*Inputs!$B$90 -> 2296.8597 | I26: =MAX(IF(I$1*12<=Inputs!$G$88,12,(Inputs!$G$88-H$1*12)),0)*Inputs!$B$90 -> 0 | J26: =MAX(IF(J$1*12<=Inputs!$G$88,12,(Inputs!$G$88-I$1*12)),0)*Inputs!$B$90 -> 0 | ... AM26: =MAX(IF(AM$1*12<=Inputs!$G$88,12,(Inputs!$G$88-AL$1*12)),0)*Inputs!$B$90 -> 0
A27: Other loan repayment | C27: =MAX(IF(C$1*12<=Inputs!$G$93,12,(Inputs!$G$93-B$1*12)),0)*Inputs!$B$95 -> 600 | D27: =MAX(IF(D$1*12<=Inputs!$G$93,12,(Inputs!$G$93-C$1*12)),0)*Inputs!$B$95 -> 600 | E27: =MAX(IF(E$1*12<=Inputs!$G$93,12,(Inputs!$G$93-D$1*12)),0)*Inputs!$B$95 -> 600 | F27: =MAX(IF(F$1*12<=Inputs!$G$93,12,(Inputs!$G$93-E$1*12)),0)*Inputs!$B$95 -> 600 | G27: =MAX(IF(G$1*12<=Inputs!$G$93,12,(Inputs!$G$93-F$1*12)),0)*Inputs!$B$95 -> 600 | H27: =MAX(IF(H$1*12<=Inputs!$G$93,12,(Inputs!$G$93-G$1*12)),0)*Inputs!$B$95 -> 600 | I27: =MAX(IF(I$1*12<=Inputs!$G$93,12,(Inputs!$G$93-H$1*12)),0)*Inputs!$B$95 -> 600 | J27: =MAX(IF(J$1*12<=Inputs!$G$93,12,(Inputs!$G$93-I$1*12)),0)*Inputs!$B$95 -> 600 | ... AM27: =MAX(IF(AM$1*12<=Inputs!$G$93,12,(Inputs!$G$93-AL$1*12)),0)*Inputs!$B$95 -> 0
A28: Dependents cost
A29: =TEXT(Inputs!B33,"") -> John | C29: =IF(Inputs!$B$35>=C$1,Inputs!$B$34,0)*(1+inf)^B$1 -> 2000 | D29: =IF(Inputs!$B$35>=D$1,Inputs!$B$34,0)*(1+inf)^C$1 -> 2050 | E29: =IF(Inputs!$B$35>=E$1,Inputs!$B$34,0)*(1+inf)^D$1 -> 2101.25 | F29: =IF(Inputs!$B$35>=F$1,Inputs!$B$34,0)*(1+inf)^E$1 -> 0 | G29: =IF(Inputs!$B$35>=G$1,Inputs!$B$34,0)*(1+inf)^F$1 -> 0 | H29: =IF(Inputs!$B$35>=H$1,Inputs!$B$34,0)*(1+inf)^G$1 -> 0 | I29: =IF(Inputs!$B$35>=I$1,Inputs!$B$34,0)*(1+inf)^H$1 -> 0 | J29: =IF(Inputs!$B$35>=J$1,Inputs!$B$34,0)*(1+inf)^I$1 -> 0 | ... AM29: =IF(Inputs!$B$35>=AM$1,Inputs!$B$34,0)*(1+inf)^AL$1 -> 0
A30: =TEXT(Inputs!B38,"") -> Jack | C30: =IF(Inputs!$B$40>=C$1,Inputs!$B$39,0)*(1+inf)^B$1 -> 1000 | D30: =IF(Inputs!$B$40>=D$1,Inputs!$B$39,0)*(1+inf)^C$1 -> 1025 | E30: =IF(Inputs!$B$40>=E$1,Inputs!$B$39,0)*(1+inf)^D$1 -> 1050.625 | F30: =IF(Inputs!$B$40>=F$1,Inputs!$B$39,0)*(1+inf)^E$1 -> 1076.8906 | G30: =IF(Inputs!$B$40>=G$1,Inputs!$B$39,0)*(1+inf)^F$1 -> 1103.8129 | H30: =IF(Inputs!$B$40>=H$1,Inputs!$B$39,0)*(1+inf)^G$1 -> 0 | I30: =IF(Inputs!$B$40>=I$1,Inputs!$B$39,0)*(1+inf)^H$1 -> 0 | J30: =IF(Inputs!$B$40>=J$1,Inputs!$B$39,0)*(1+inf)^I$1 -> 0 | ... AM30: =IF(Inputs!$B$40>=AM$1,Inputs!$B$39,0)*(1+inf)^AL$1 -> 0
A31: =TEXT(Inputs!B43,"") -> Bill | C31: =IF(Inputs!$B$45>=C$1,Inputs!$B$44,0)*(1+inf)^B$1 -> 4000 | D31: =IF(Inputs!$B$45>=D$1,Inputs!$B$44,0)*(1+inf)^C$1 -> 4100 | E31: =IF(Inputs!$B$45>=E$1,Inputs!$B$44,0)*(1+inf)^D$1 -> 0 | F31: =IF(Inputs!$B$45>=F$1,Inputs!$B$44,0)*(1+inf)^E$1 -> 0 | G31: =IF(Inputs!$B$45>=G$1,Inputs!$B$44,0)*(1+inf)^F$1 -> 0 | H31: =IF(Inputs!$B$45>=H$1,Inputs!$B$44,0)*(1+inf)^G$1 -> 0 | I31: =IF(Inputs!$B$45>=I$1,Inputs!$B$44,0)*(1+inf)^H$1 -> 0 | J31: =IF(Inputs!$B$45>=J$1,Inputs!$B$44,0)*(1+inf)^I$1 -> 0 | ... AM31: =IF(Inputs!$B$45>=AM$1,Inputs!$B$44,0)*(1+inf)^AL$1 -> 0
A32: Housing rent | C32: =Inputs!$B$23*(1+inf)^B$1 -> 0 | D32: =Inputs!$B$23*(1+inf)^C$1 -> 0 | E32: =Inputs!$B$23*(1+inf)^D$1 -> 0 | F32: =Inputs!$B$23*(1+inf)^E$1 -> 0 | G32: =Inputs!$B$23*(1+inf)^F$1 -> 0 | H32: =Inputs!$B$23*(1+inf)^G$1 -> 0 | I32: =Inputs!$B$23*(1+inf)^H$1 -> 0 | J32: =Inputs!$B$23*(1+inf)^I$1 -> 0 | ... AM32: =Inputs!$B$23*(1+inf)^AL$1 -> 0
A33: Other property costs
A34: =TEXT(Inputs!$B$50,"") -> Sliema | C34: =Inputs!$B52*(1+inf)^B$1 -> 5000 | D34: =Inputs!$B52*(1+inf)^C$1 -> 5125 | E34: =Inputs!$B52*(1+inf)^D$1 -> 5253.125 | F34: =Inputs!$B52*(1+inf)^E$1 -> 5384.4531 | G34: =Inputs!$B52*(1+inf)^F$1 -> 5519.0645 | H34: =Inputs!$B52*(1+inf)^G$1 -> 5657.0411 | I34: =Inputs!$B52*(1+inf)^H$1 -> 5798.4671 | J34: =Inputs!$B52*(1+inf)^I$1 -> 5943.4288 | ... AM34: =Inputs!$B52*(1+inf)^AL$1 -> 12162.677
A35: =TEXT(Inputs!$B$55,"") -> Gzira | C35: =Inputs!$B57*(1+inf)^B$1 -> 2000 | D35: =Inputs!$B57*(1+inf)^C$1 -> 2050 | E35: =Inputs!$B57*(1+inf)^D$1 -> 2101.25 | F35: =Inputs!$B57*(1+inf)^E$1 -> 2153.7812 | G35: =Inputs!$B57*(1+inf)^F$1 -> 2207.6258 | H35: =Inputs!$B57*(1+inf)^G$1 -> 2262.8164 | I35: =Inputs!$B57*(1+inf)^H$1 -> 2319.3868 | J35: =Inputs!$B57*(1+inf)^I$1 -> 2377.3715 | ... AM35: =Inputs!$B57*(1+inf)^AL$1 -> 4865.0706
A36: =TEXT(Inputs!$B$60,"") -> Qormi | C36: =Inputs!$B62*(1+inf)^B$1 -> 1200 | D36: =Inputs!$B62*(1+inf)^C$1 -> 1230 | E36: =Inputs!$B62*(1+inf)^D$1 -> 1260.75 | F36: =Inputs!$B62*(1+inf)^E$1 -> 1292.2687 | G36: =Inputs!$B62*(1+inf)^F$1 -> 1324.5755 | H36: =Inputs!$B62*(1+inf)^G$1 -> 1357.6899 | I36: =Inputs!$B62*(1+inf)^H$1 -> 1391.6321 | J36: =Inputs!$B62*(1+inf)^I$1 -> 1426.4229 | ... AM36: =Inputs!$B62*(1+inf)^AL$1 -> 2919.0424
A37: Living expenses
A38: Current baseline | C38: =Inputs!$B$25*(1+inf)^B$1 -> 50000 | D38: =Inputs!$B$25*(1+inf)^C$1 -> 51250 | E38: =Inputs!$B$25*(1+inf)^D$1 -> 52531.25 | F38: =Inputs!$B$25*(1+inf)^E$1 -> 53844.531 | G38: =Inputs!$B$25*(1+inf)^F$1 -> 55190.645 | H38: =Inputs!$B$25*(1+inf)^G$1 -> 56570.411 | I38: =Inputs!$B$25*(1+inf)^H$1 -> 57984.671 | J38: =Inputs!$B$25*(1+inf)^I$1 -> 59434.288 | ... AM38: =Inputs!$B$25*(1+inf)^AL$1 -> 121626.77
A39: ="Adjustment "&Inputs!A137 -> Adjustment from now to 65 | C39: =IF(C$3<=65,Inputs!$B$137*C$38,0) -> 0 | D39: =IF(D$3<=65,Inputs!$B$137*D$38,0) -> 0 | E39: =IF(E$3<=65,Inputs!$B$137*E$38,0) -> 0 | F39: =IF(F$3<=65,Inputs!$B$137*F$38,0) -> 0 | G39: =IF(G$3<=65,Inputs!$B$137*G$38,0) -> 0 | H39: =IF(H$3<=65,Inputs!$B$137*H$38,0) -> 0 | I39: =IF(I$3<=65,Inputs!$B$137*I$38,0) -> 0 | J39: =IF(J$3<=65,Inputs!$B$137*J$38,0) -> 0 | ... AM39: =IF(AM$3<=65,Inputs!$B$137*AM$38,0) -> 0
A40: ="Adjustment "&Inputs!A138 -> Adjustment from 66-75 | C40: =IF(AND(C$3>65,C$3<=75),Inputs!$B$138*C38,0) -> 0 | D40: =IF(AND(D$3>65,D$3<=75),Inputs!$B$138*D38,0) -> 0 | E40: =IF(AND(E$3>65,E$3<=75),Inputs!$B$138*E38,0) -> 0 | F40: =IF(AND(F$3>65,F$3<=75),Inputs!$B$138*F38,0) -> 0 | G40: =IF(AND(G$3>65,G$3<=75),Inputs!$B$138*G38,0) -> 0 | H40: =IF(AND(H$3>65,H$3<=75),Inputs!$B$138*H38,0) -> 0 | I40: =IF(AND(I$3>65,I$3<=75),Inputs!$B$138*I38,0) -> 0 | J40: =IF(AND(J$3>65,J$3<=75),Inputs!$B$138*J38,0) -> 0 | ... AM40: =IF(AND(AM$3>65,AM$3<=75),Inputs!$B$138*AM38,0) -> 0
...
