Workbook
Name A1inc: Inputs!$B$89
Name A2inc: Inputs!$B$94
Name A3inc: Inputs!$B$99
Name A4inc: Inputs!$B$104
Name A5inc: Inputs!$B$109
Name AgeRange: RetNorm_Engine!$C$3:INDEX(RetNorm_Engine!$C$3:$XFD$3, COUNTA(RetNorm_Engine!$C$3:$XFD$3))
Name AssVar: Inputs!$A$297:$C$306
Name buffer: Inputs!$B$269
Name ChartCash_Early: RetEarly_Engine!$C$379:INDEX(RetEarly_Engine!$C$379:$XFD$379, COUNTA(RetEarly_Engine!$C$379:$XFD$379))
Name ChartCash_Norm: RetNorm_Engine!$C$379:INDEX(RetNorm_Engine!$C$379:$XFD$379, COUNTA(RetNorm_Engine!$C$379:$XFD$379))
Name ChartNW_Early: RetEarly_Engine!$C$380:INDEX(RetEarly_Engine!$C$380:$XFD$380, COUNTA(RetEarly_Engine!$C$380:$XFD$380))
Name ChartNW_Norm: RetNorm_Engine!$C$380:INDEX(RetNorm_Engine!$C$380:$XFD$380, COUNTA(RetNorm_Engine!$C$380:$XFD$380))
Name DCoth: Inputs!$B$277
Name DCprop: Inputs!$B$275
Name EndAge: Inputs!$B$244
Name inf: Inputs!$B$255
Name legacy: Inputs!$B$271
Name MthOff: Inputs!$B$293
Name MthRem: Inputs!$B$292
Name princ: Inputs!$B$257
Name ProRate: Inputs!$B$294
Name RetAge: Inputs!$B$19
Name rinc: Inputs!$B$265
Name sincr: Inputs!$B$263
Name stinc: Inputs!$B$261

Sheet Inputs
B1: User inputs | D1: User Tooltips | E1: UI Notes | F1: Excel helpers
A2: QUICK START
A4: Your age | B4: 48 | D4: Must be entered
A6: Current net annual income | B6: 80000 | D6: Net of tax, from employment or self-employment
A8: Total cash balances | B8: 50000 | D8: current and savings accounts, bonds, term deposits
A10: Stock market investments | B10: 30000 | D10: Current market value of equity portfolio
A12: Home current market value | B12: 600000 | D12: Leave blank if not a home owner
A14: Home loan (mortgage)
A15: Balance | B15: 50000 | D15: Leave blank if no mortgage | F15: Months remaining | G15: =IFERROR(NPER(B16/12,-B17,B15),"") -> 68.044529
A16: Interest rate | B16: 0.03 | F16: Years remaining | G16: =IFERROR(G15/12,"") -> 5.6703774
A17: Monthly repayment | B17: 800
A19: Statutory retirement age | B19: 65 | D19: Year at which pension starts
A21: Annual pension at retirement | B21: 16000 | D21: Net annual state pension entitlement
A23: Housing rent | D23: if not a home owner | E23: show only if not a home owner (B12="")
A25: Annual living expenses | B25: 50000
A28: DEEPER DIVE | E28: Activated only if user wants to
A30: Dependents
A32: Dependent 1
A33: Name | B33: John | D33: Leave blank if none
A34: Annual cost | B34: 2000 | D34: Food, education, healthcare, etc. | E34: Hide until user enters dependent name
A35: Years to support | B35: 3 | D35: Years from now | E35: Hide until user enters dependent name
A37: Dependent 2
A38: Name | B38: Jack | D38: Leave blank if none
A39: Annual cost | B39: 1000 | D39: Food, education, healthcare, etc. | E39: Hide until user enters dependent name
A40: Years to support | B40: 5 | D40: Years from now | E40: Hide until user enters dependent name
A42: Dependent 3
A43: Name | B43: Bill | D43: Leave blank if none
A44: Annual cost | B44: 4000 | D44: Food, education, healthcare, etc. | E44: Hide until user enters dependent name
A45: Years to support | B45: 2 | D45: Years from now | E45: Hide until user enters dependent name
A47: Dependent 4
A48: Name | B48: Stephen | D48: Leave blank if none
A49: Annual cost | B49: 2500 | D49: Food, education, healthcare, etc. | E49: Hide until user enters dependent name
A50: Years to support | B50: 3 | D50: Years from now | E50: Hide until user enters dependent name
A52: Dependent 5
A53: Name | B53: Jane | D53: Leave blank if none
A54: Annual cost | B54: 2860 | D54: Food, education, healthcare, etc. | E54: Hide until user enters dependent name
A55: Years to support | B55: 6 | D55: Years from now | E55: Hide until user enters dependent name
A57: Investment Properties
A59: Property 1
A60: Name | B60: Sliema | D60: Leave blank if none
...

Sheet Output
V2: Retire at | AA2: ="Retire at "&RetEarly_Engine!B3 -> Retire at 51
V3: =RetEarly_Engine!B3 -> 51 | AA3: ="Retire at "&RetAge -> Retire at 65

Sheet RetNorm_Engine
B1: 0 | C1: 1 | D1: =C1+1 -> 2 | E1: =D1+1 -> 3 | F1: =E1+1 -> 4 | G1: =F1+1 -> 5 | H1: =G1+1 -> 6 | I1: =H1+1 -> 7 | J1: =I1+1 -> 8 | K1: =J1+1 -> 9 | ... AM1: =AL1+1 -> 37
B2: Year | C2: =YEAR(TODAY()) -> 2026 | D2: =C2+1 -> 2027 | E2: =D2+1 -> 2028 | F2: =E2+1 -> 2029 | G2: =F2+1 -> 2030 | H2: =G2+1 -> 2031 | I2: =H2+1 -> 2032 | J2: =I2+1 -> 2033 | K2: =J2+1 -> 2034 | ... AM2: =AL2+1 -> 2062
B3: =Inputs!B19 -> 65 | C3: =Inputs!B4 -> 48 | D3: =C3+1 -> 49 | E3: =D3+1 -> 50 | F3: =E3+1 -> 51 | G3: =F3+1 -> 52 | H3: =G3+1 -> 53 | I3: =H3+1 -> 54 | J3: =I3+1 -> 55 | K3: =J3+1 -> 56 | ... AM3: =AL3+1 -> 84
A4: Inflows
A5: Net employment / self-employment income | C5: =IF(AND(Inputs!$B$19>C3,$B$3>C3),Inputs!$B$6*(1+sincr)^B1,0)*ProRate -> 66666.667 | D5: =IF(AND(Inputs!$B$19>D3,$B$3>D3),Inputs!$B$6*(1+sincr)^C1,0) -> 82400 | E5: =IF(AND(Inputs!$B$19>E3,$B$3>E3),Inputs!$B$6*(1+sincr)^D1,0) -> 84872 | F5: =IF(AND(Inputs!$B$19>F3,$B$3>F3),Inputs!$B$6*(1+sincr)^E1,0) -> 87418.16 | G5: =IF(AND(Inputs!$B$19>G3,$B$3>G3),Inputs!$B$6*(1+sincr)^F1,0) -> 90040.705 | H5: =IF(AND(Inputs!$B$19>H3,$B$3>H3),Inputs!$B$6*(1+sincr)^G1,0) -> 92741.926 | I5: =IF(AND(Inputs!$B$19>I3,$B$3>I3),Inputs!$B$6*(1+sincr)^H1,0) -> 95524.184 | J5: =IF(AND(Inputs!$B$19>J3,$B$3>J3),Inputs!$B$6*(1+sincr)^I1,0) -> 98389.909 | K5: =IF(AND(Inputs!$B$19>K3,$B$3>K3),Inputs!$B$6*(1+sincr)^J1,0) -> 101341.61 | ... AM5: =IF(AND(Inputs!$B$19>AM3,$B$3>AM3),Inputs!$B$6*(1+sincr)^AL1,0) -> 0
A6: Net from other work | C6: =IF(C$3<=Inputs!$B$120,Inputs!$B$119,0)*(1+inf)^B$1*ProRate -> 1666.6667 | D6: =IF(D$3<=Inputs!$B$120,Inputs!$B$119,0)*(1+inf)^C$1 -> 2050 | E6: =IF(E$3<=Inputs!$B$120,Inputs!$B$119,0)*(1+inf)^D$1 -> 2101.25 | F6: =IF(F$3<=Inputs!$B$120,Inputs!$B$119,0)*(1+inf)^E$1 -> 2153.7812 | G6: =IF(G$3<=Inputs!$B$120,Inputs!$B$119,0)*(1+inf)^F$1 -> 2207.6258 | H6: =IF(H$3<=Inputs!$B$120,Inputs!$B$119,0)*(1+inf)^G$1 -> 2262.8164 | I6: =IF(I$3<=Inputs!$B$120,Inputs!$B$119,0)*(1+inf)^H$1 -> 2319.3868 | J6: =IF(J$3<=Inputs!$B$120,Inputs!$B$119,0)*(1+inf)^I$1 -> 2377.3715 | K6: =IF(K$3<=Inputs!$B$120,Inputs!$B$119,0)*(1+inf)^J$1 -> 2436.8058 | ... AM6: =IF(AM$3<=Inputs!$B$120,Inputs!$B$119,0)*(1+inf)^AL$1 -> 0
A7: Net rental income from other properties
A8: =TEXT(Inputs!$B$60,"") -> Sliema | C8: =Inputs!B113*ProRate -> 10000 | D8: =C8*(1+rinc) -> 10300 | E8: =D8*(1+rinc) -> 10609 | F8: =E8*(1+rinc) -> 10927.27 | G8: =F8*(1+rinc) -> 11255.088 | H8: =G8*(1+rinc) -> 11592.741 | I8: =H8*(1+rinc) -> 11940.523 | J8: =I8*(1+rinc) -> 12298.739 | K8: =J8*(1+rinc) -> 12667.701 | ... AM8: =AL8*(1+rinc) -> 28982.783
A9: =TEXT(Inputs!$B$65,"") -> Gzira | C9: =Inputs!B114*ProRate -> 8333.3333 | D9: =C9*(1+rinc) -> 8583.3333 | E9: =D9*(1+rinc) -> 8840.8333 | F9: =E9*(1+rinc) -> 9106.0583 | G9: =F9*(1+rinc) -> 9379.2401 | H9: =G9*(1+rinc) -> 9660.6173 | I9: =H9*(1+rinc) -> 9950.4358 | J9: =I9*(1+rinc) -> 10248.949 | K9: =J9*(1+rinc) -> 10556.417 | ... AM9: =AL9*(1+rinc) -> 24152.319
A10: =TEXT(Inputs!$B$70,"") -> Qormi | C10: =Inputs!B115*ProRate -> 6666.6667 | D10: =C10*(1+rinc) -> 6866.6667 | E10: =D10*(1+rinc) -> 7072.6667 | F10: =E10*(1+rinc) -> 7284.8467 | G10: =F10*(1+rinc) -> 7503.3921 | H10: =G10*(1+rinc) -> 7728.4938 | I10: =H10*(1+rinc) -> 7960.3486 | J10: =I10*(1+rinc) -> 8199.1591 | K10: =J10*(1+rinc) -> 8445.1339 | ... AM10: =AL10*(1+rinc) -> 19321.856
A11: =TEXT(Inputs!$B$75,"") -> Gudja | C11: =Inputs!B116*ProRate -> 4166.6667 | D11: =C11*(1+rinc) -> 4291.6667 | E11: =D11*(1+rinc) -> 4420.4167 | F11: =E11*(1+rinc) -> 4553.0292 | G11: =F11*(1+rinc) -> 4689.62 | H11: =G11*(1+rinc) -> 4830.3086 | I11: =H11*(1+rinc) -> 4975.2179 | J11: =I11*(1+rinc) -> 5124.4744 | K11: =J11*(1+rinc) -> 5278.2087 | ... AM11: =AL11*(1+rinc) -> 12076.16
A12: =TEXT(Inputs!$B$80,"") -> Marsa | C12: =Inputs!B117*ProRate -> 5416.6667 | D12: =C12*(1+rinc) -> 5579.1667 | E12: =D12*(1+rinc) -> 5746.5417 | F12: =E12*(1+rinc) -> 5918.9379 | G12: =F12*(1+rinc) -> 6096.5061 | H12: =G12*(1+rinc) -> 6279.4012 | I12: =H12*(1+rinc) -> 6467.7833 | J12: =I12*(1+rinc) -> 6661.8168 | K12: =J12*(1+rinc) -> 6861.6713 | ... AM12: =AL12*(1+rinc) -> 15699.008
A13: Full pension | C13: =IF(C$3<Inputs!$B$19,0,Inputs!$B$21)*(1+inf)^B$1*ProRate -> 0 | D13: =IF(D$3<Inputs!$B$19,0,Inputs!$B$21)*(1+inf)^C$1 -> 0 | E13: =IF(E$3<Inputs!$B$19,0,Inputs!$B$21)*(1+inf)^D$1 -> 0 | F13: =IF(F$3<Inputs!$B$19,0,Inputs!$B$21)*(1+inf)^E$1 -> 0 | G13: =IF(G$3<Inputs!$B$19,0,Inputs!$B$21)*(1+inf)^F$1 -> 0 | H13: =IF(H$3<Inputs!$B$19,0,Inputs!$B$21)*(1+inf)^G$1 -> 0 | I13: =IF(I$3<Inputs!$B$19,0,Inputs!$B$21)*(1+inf)^H$1 -> 0 | J13: =IF(J$3<Inputs!$B$19,0,Inputs!$B$21)*(1+inf)^I$1 -> 0 | K13: =IF(K$3<Inputs!$B$19,0,Inputs!$B$21)*(1+inf)^J$1 -> 0 | ... AM13: =IF(AM$3<Inputs!$B$19,0,Inputs!$B$21)*(1+inf)^AL$1 -> 38920.565
A14: Pension reduction from early retirement | C14: =MIN(0,MAX(-IF(C13=0,0,(Inputs!$B$19-INDEX(3:3,MATCH(0,5:5,0))))*Inputs!$B$267*(1+inf)^B$1*ProRate,-C13)) -> 0 | D14: =MIN(0,MAX(-IF(D13=0,0,(Inputs!$B$19-INDEX(3:3,MATCH(0,5:5,0))))*Inputs!$B$267*(1+inf)^C$1,-D13)) -> 0 | E14: =MIN(0,MAX(-IF(E13=0,0,(Inputs!$B$19-INDEX(3:3,MATCH(0,5:5,0))))*Inputs!$B$267*(1+inf)^D$1,-E13)) -> 0 | F14: =MIN(0,MAX(-IF(F13=0,0,(Inputs!$B$19-INDEX(3:3,MATCH(0,5:5,0))))*Inputs!$B$267*(1+inf)^E$1,-F13)) -> 0 | G14: =MIN(0,MAX(-IF(G13=0,0,(Inputs!$B$19-INDEX(3:3,MATCH(0,5:5,0))))*Inputs!$B$267*(1+inf)^F$1,-G13)) -> 0 | H14: =MIN(0,MAX(-IF(H13=0,0,(Inputs!$B$19-INDEX(3:3,MATCH(0,5:5,0))))*Inputs!$B$267*(1+inf)^G$1,-H13)) -> 0 | I14: =MIN(0,MAX(-IF(I13=0,0,(Inputs!$B$19-INDEX(3:3,MATCH(0,5:5,0))))*Inputs!$B$267*(1+inf)^H$1,-I13)) -> 0 | J14: =MIN(0,MAX(-IF(J13=0,0,(Inputs!$B$19-INDEX(3:3,MATCH(0,5:5,0))))*Inputs!$B$267*(1+inf)^I$1,-J13)) -> 0 | K14: =MIN(0,MAX(-IF(K13=0,0,(Inputs!$B$19-INDEX(3:3,MATCH(0,5:5,0))))*Inputs!$B$267*(1+inf)^J$1,-K13)) -> 0 | ... AM14: =MIN(0,MAX(-IF(AM13=0,0,(Inputs!$B$19-INDEX(3:3,MATCH(0,5:5,0))))*Inputs!$B$267*(1+inf)^AL$1,-AM13)) -> 0
A15: Other post-retirement income | C15: =IF(AND(C$3>=Inputs!$B$252,C$3<=Inputs!$B$253),Inputs!$B$251*(1+inf)^B$1,0)*ProRate -> 0 | D15: =IF(AND(D$3>=Inputs!$B$252,D$3<=Inputs!$B$253),Inputs!$B$251*(1+inf)^C$1,0) -> 0 | E15: =IF(AND(E$3>=Inputs!$B$252,E$3<=Inputs!$B$253),Inputs!$B$251*(1+inf)^D$1,0) -> 0 | F15: =IF(AND(F$3>=Inputs!$B$252,F$3<=Inputs!$B$253),Inputs!$B$251*(1+inf)^E$1,0) -> 0 | G15: =IF(AND(G$3>=Inputs!$B$252,G$3<=Inputs!$B$253),Inputs!$B$251*(1+inf)^F$1,0) -> 0 | H15: =IF(AND(H$3>=Inputs!$B$252,H$3<=Inputs!$B$253),Inputs!$B$251*(1+inf)^G$1,0) -> 0 | I15: =IF(AND(I$3>=Inputs!$B$252,I$3<=Inputs!$B$253),Inputs!$B$251*(1+inf)^H$1,0) -> 0 | J15: =IF(AND(J$3>=Inputs!$B$252,J$3<=Inputs!$B$253),Inputs!$B$251*(1+inf)^I$1,0) -> 0 | K15: =IF(AND(K$3>=Inputs!$B$252,K$3<=Inputs!$B$253),Inputs!$B$251*(1+inf)^J$1,0) -> 0 | ... AM15: =IF(AND(AM$3>=Inputs!$B$252,AM$3<=Inputs!$B$253),Inputs!$B$251*(1+inf)^AL$1,0) -> 0
A16: Major one-off income events
A17: =TEXT(Inputs!B184,"") -> Inheritance | C17: =IF(C$2=Inputs!$B186,Inputs!$B185,0)*(1+inf)^B$1 -> 0 | D17: =IF(D$2=Inputs!$B186,Inputs!$B185,0)*(1+inf)^C$1 -> 0 | E17: =IF(E$2=Inputs!$B186,Inputs!$B185,0)*(1+inf)^D$1 -> 0 | F17: =IF(F$2=Inputs!$B186,Inputs!$B185,0)*(1+inf)^E$1 -> 0 | G17: =IF(G$2=Inputs!$B186,Inputs!$B185,0)*(1+inf)^F$1 -> 0 | H17: =IF(H$2=Inputs!$B186,Inputs!$B185,0)*(1+inf)^G$1 -> 0 | I17: =IF(I$2=Inputs!$B186,Inputs!$B185,0)*(1+inf)^H$1 -> 0 | J17: =IF(J$2=Inputs!$B186,Inputs!$B185,0)*(1+inf)^I$1 -> 0 | ... AM17: =IF(AM$2=Inputs!$B186,Inputs!$B185,0)*(1+inf)^AL$1 -> 0
A18: =TEXT(Inputs!B189,"") -> Sell Painting | C18: =IF(C$2=Inputs!$B191,Inputs!$B190,0)*(1+inf)^B$1 -> 0 | D18: =IF(D$2=Inputs!$B191,Inputs!$B190,0)*(1+inf)^C$1 -> 0 | E18: =IF(E$2=Inputs!$B191,Inputs!$B190,0)*(1+inf)^D$1 -> 0 | F18: =IF(F$2=Inputs!$B191,Inputs!$B190,0)*(1+inf)^E$1 -> 10768.906 | G18: =IF(G$2=Inputs!$B191,Inputs!$B190,0)*(1+inf)^F$1 -> 0 | H18: =IF(H$2=Inputs!$B191,Inputs!$B190,0)*(1+inf)^G$1 -> 0 | I18: =IF(I$2=Inputs!$B191,Inputs!$B190,0)*(1+inf)^H$1 -> 0 | J18: =IF(J$2=Inputs!$B191,Inputs!$B190,0)*(1+inf)^I$1 -> 0 | ... AM18: =IF(AM$2=Inputs!$B191,Inputs!$B190,0)*(1+inf)^AL$1 -> 0
A19: =TEXT(Inputs!B194,"") -> Sell Jewels | C19: =IF(C$2=Inputs!$B196,Inputs!$B195,0)*(1+inf)^B$1 -> 0 | D19: =IF(D$2=Inputs!$B196,Inputs!$B195,0)*(1+inf)^C$1 -> 0 | E19: =IF(E$2=Inputs!$B196,Inputs!$B195,0)*(1+inf)^D$1 -> 0 | F19: =IF(F$2=Inputs!$B196,Inputs!$B195,0)*(1+inf)^E$1 -> 0 | G19: =IF(G$2=Inputs!$B196,Inputs!$B195,0)*(1+inf)^F$1 -> 0 | H19: =IF(H$2=Inputs!$B196,Inputs!$B195,0)*(1+inf)^G$1 -> 0 | I19: =IF(I$2=Inputs!$B196,Inputs!$B195,0)*(1+inf)^H$1 -> 5798.4671 | J19: =IF(J$2=Inputs!$B196,Inputs!$B195,0)*(1+inf)^I$1 -> 0 | ... AM19: =IF(AM$2=Inputs!$B196,Inputs!$B195,0)*(1+inf)^AL$1 -> 0
A20: Interest on cash balances | C20: =MAX(AVERAGE(C62,C62+SUM(C5:C19)-C59)*Inputs!$B$259,0) -> 1392.7083 | D20: =MAX(AVERAGE(D62,D62+SUM(D5:D19)-D59)*Inputs!$B$259,0) -> 1691.0073 | E20: =MAX(AVERAGE(E62,E62+SUM(E5:E19)-E59)*Inputs!$B$259,0) -> 2049.0802 | F20: =MAX(AVERAGE(F62,F62+SUM(F5:F19)-F59)*Inputs!$B$259,0) -> 2266.8747 | G20: =MAX(AVERAGE(G62,G62+SUM(G5:G19)-G59)*Inputs!$B$259,0) -> 2658.3728 | H20: =MAX(AVERAGE(H62,H62+SUM(H5:H19)-H59)*Inputs!$B$259,0) -> 3524.3258 | I20: =MAX(AVERAGE(I62,I62+SUM(I5:I19)-I59)*Inputs!$B$259,0) -> 4827.2148 | J20: =MAX(AVERAGE(J62,J62+SUM(J5:J19)-J59)*Inputs!$B$259,0) -> 6533.8412 | ... AM20: =MAX(AVERAGE(AM62,AM62+SUM(AM5:AM19)-AM59)*Inputs!$B$259,0) -> 59015.801
C21: =SUM(C4:C20) -> 104309.38 | D21: =SUM(D4:D20) -> 121761.84 | E21: =SUM(E4:E20) -> 125711.79 | F21: =SUM(F4:F20) -> 140397.86 | G21: =SUM(G4:G20) -> 133830.55 | H21: =SUM(H4:H20) -> 138620.63 | I21: =SUM(I4:I20) -> 149763.56 | J21: =SUM(J4:J20) -> 149834.26 | ... AM21: =SUM(AM4:AM20) -> 198168.49
A22: Outflows
A23: Credit cards cleared | C23: =Inputs!B124 -> 1000 | D23: 0 | E23: 0 | F23: 0 | G23: 0 | H23: 0 | I23: 0 | J23: 0 | K23: 0 | L23: 0 | M23: 0 | N23: 0 | O23: 0 | P23: 0 | Q23: 0 | R23: 0 | S23: 0 | T23: 0 | U23: 0 | V23: 0 | W23: 0 | X23: 0 | Y23: 0 | Z23: 0 | AA23: 0 | AB23: 0 | AC23: 0 | AD23: 0 | AE23: 0 | AF23: 0 | AG23: 0 | AH23: 0 | AI23: 0 | AJ23: 0 | AK23: 0 | AL23: 0 | AM23: 0
A24: Home loan repayment | C24: =MIN(IF(B$1=0,MthRem,12), MAX(Inputs!$G$15-IF(B$1=0,0,B$1*12+MthOff), 0))*Inputs!$B$17 -> 8000 | D24: =MIN(IF(C$1=0,MthRem,12), MAX(Inputs!$G$15-IF(C$1=0,0,C$1*12+MthOff), 0))*Inputs!$B$17 -> 9600 | E24: =MIN(IF(D$1=0,MthRem,12), MAX(Inputs!$G$15-IF(D$1=0,0,D$1*12+MthOff), 0))*Inputs!$B$17 -> 9600 | F24: =MIN(IF(E$1=0,MthRem,12), MAX(Inputs!$G$15-IF(E$1=0,0,E$1*12+MthOff), 0))*Inputs!$B$17 -> 9600 | G24: =MIN(IF(F$1=0,MthRem,12), MAX(Inputs!$G$15-IF(F$1=0,0,F$1*12+MthOff), 0))*Inputs!$B$17 -> 9600 | H24: =MIN(IF(G$1=0,MthRem,12), MAX(Inputs!$G$15-IF(G$1=0,0,G$1*12+MthOff), 0))*Inputs!$B$17 -> 8035.6231 | I24: =MIN(IF(H$1=0,MthRem,12), MAX(Inputs!$G$15-IF(H$1=0,0,H$1*12+MthOff), 0))*Inputs!$B$17 -> 0 | J24: =MIN(IF(I$1=0,MthRem,12), MAX(Inputs!$G$15-IF(I$1=0,0,I$1*12+MthOff), 0))*Inputs!$B$17 -> 0 | ... AM24: =MIN(IF(AL$1=0,MthRem,12), MAX(Inputs!$G$15-IF(AL$1=0,0,AL$1*12+MthOff), 0))*Inputs!$B$17 -> 0
A25: Other asset loans repayments
A26: =TEXT(Inputs!$B$60,"") -> Sliema | C26: =MIN(IF(B$1=0,MthRem,12), MAX(Inputs!$G$127-IF(B$1=0,0,B$1*12+MthOff), 0))*Inputs!$B$129 -> 5000 | D26: =MIN(IF(C$1=0,MthRem,12), MAX(Inputs!$G$127-IF(C$1=0,0,C$1*12+MthOff), 0))*Inputs!$B$129 -> 6000 | E26: =MIN(IF(D$1=0,MthRem,12), MAX(Inputs!$G$127-IF(D$1=0,0,D$1*12+MthOff), 0))*Inputs!$B$129 -> 6000 | F26: =MIN(IF(E$1=0,MthRem,12), MAX(Inputs!$G$127-IF(E$1=0,0,E$1*12+MthOff), 0))*Inputs!$B$129 -> 6000 | G26: =MIN(IF(F$1=0,MthRem,12), MAX(Inputs!$G$127-IF(F$1=0,0,F$1*12+MthOff), 0))*Inputs!$B$129 -> 6000 | H26: =MIN(IF(G$1=0,MthRem,12), MAX(Inputs!$G$127-IF(G$1=0,0,G$1*12+MthOff), 0))*Inputs!$B$129 -> 6000 | I26: =MIN(IF(H$1=0,MthRem,12), MAX(Inputs!$G$127-IF(H$1=0,0,H$1*12+MthOff), 0))*Inputs!$B$129 -> 6000 | J26: =MIN(IF(I$1=0,MthRem,12), MAX(Inputs!$G$127-IF(I$1=0,0,I$1*12+MthOff), 0))*Inputs!$B$129 -> 6000 | ... AM26: =MIN(IF(AL$1=0,MthRem,12), MAX(Inputs!$G$127-IF(AL$1=0,0,AL$1*12+MthOff), 0))*Inputs!$B$129 -> 0
A27: =TEXT(Inputs!$B$65,"") -> Gzira | C27: =MIN(IF(B$1=0,MthRem,12), MAX(Inputs!$G$132-IF(B$1=0,0,B$1*12+MthOff), 0))*Inputs!$B$134 -> 2000 | D27: =MIN(IF(C$1=0,MthRem,12), MAX(Inputs!$G$132-IF(C$1=0,0,C$1*12+MthOff), 0))*Inputs!$B$134 -> 2400 | E27: =MIN(IF(D$1=0,MthRem,12), MAX(Inputs!$G$132-IF(D$1=0,0,D$1*12+MthOff), 0))*Inputs!$B$134 -> 2400 | F27: =MIN(IF(E$1=0,MthRem,12), MAX(Inputs!$G$132-IF(E$1=0,0,E$1*12+MthOff), 0))*Inputs!$B$134 -> 2023.4029 | G27: =MIN(IF(F$1=0,MthRem,12), MAX(Inputs!$G$132-IF(F$1=0,0,F$1*12+MthOff), 0))*Inputs!$B$134 -> 0 | H27: =MIN(IF(G$1=0,MthRem,12), MAX(Inputs!$G$132-IF(G$1=0,0,G$1*12+MthOff), 0))*Inputs!$B$134 -> 0 | I27: =MIN(IF(H$1=0,MthRem,12), MAX(Inputs!$G$132-IF(H$1=0,0,H$1*12+MthOff), 0))*Inputs!$B$134 -> 0 | J27: =MIN(IF(I$1=0,MthRem,12), MAX(Inputs!$G$132-IF(I$1=0,0,I$1*12+MthOff), 0))*Inputs!$B$134 -> 0 | ... AM27: =MIN(IF(AL$1=0,MthRem,12), MAX(Inputs!$G$132-IF(AL$1=0,0,AL$1*12+MthOff), 0))*Inputs!$B$134 -> 0
A28: =TEXT(Inputs!$B$70,"") -> Qormi | C28: =MIN(IF(B$1=0,MthRem,12), MAX(Inputs!$G$137-IF(B$1=0,0,B$1*12+MthOff), 0))*Inputs!$B$139 -> 2500 | D28: =MIN(IF(C$1=0,MthRem,12), MAX(Inputs!$G$137-IF(C$1=0,0,C$1*12+MthOff), 0))*Inputs!$B$139 -> 3000 | E28: =MIN(IF(D$1=0,MthRem,12), MAX(Inputs!$G$137-IF(D$1=0,0,D$1*12+MthOff), 0))*Inputs!$B$139 -> 3000 | F28: =MIN(IF(E$1=0,MthRem,12), MAX(Inputs!$G$137-IF(E$1=0,0,E$1*12+MthOff), 0))*Inputs!$B$139 -> 3000 | G28: =MIN(IF(F$1=0,MthRem,12), MAX(Inputs!$G$137-IF(F$1=0,0,F$1*12+MthOff), 0))*Inputs!$B$139 -> 3000 | H28: =MIN(IF(G$1=0,MthRem,12), MAX(Inputs!$G$137-IF(G$1=0,0,G$1*12+MthOff), 0))*Inputs!$B$139 -> 2796.8597 | I28: =MIN(IF(H$1=0,MthRem,12), MAX(Inputs!$G$137-IF(H$1=0,0,H$1*12+MthOff), 0))*Inputs!$B$139 -> 0 | J28: =MIN(IF(I$1=0,MthRem,12), MAX(Inputs!$G$137-IF(I$1=0,0,I$1*12+MthOff), 0))*Inputs!$B$139 -> 0 | ... AM28: =MIN(IF(AL$1=0,MthRem,12), MAX(Inputs!$G$137-IF(AL$1=0,0,AL$1*12+MthOff), 0))*Inputs!$B$139 -> 0
A29: =TEXT(Inputs!$B$75,"") -> Gudja | C29: =MIN(IF(B$1=0,MthRem,12), MAX(Inputs!$G$142-IF(B$1=0,0,B$1*12+MthOff), 0))*Inputs!$B$144 -> 800 | D29: =MIN(IF(C$1=0,MthRem,12), MAX(Inputs!$G$142-IF(C$1=0,0,C$1*12+MthOff), 0))*Inputs!$B$144 -> 960 | E29: =MIN(IF(D$1=0,MthRem,12), MAX(Inputs!$G$142-IF(D$1=0,0,D$1*12+MthOff), 0))*Inputs!$B$144 -> 960 | F29: =MIN(IF(E$1=0,MthRem,12), MAX(Inputs!$G$142-IF(E$1=0,0,E$1*12+MthOff), 0))*Inputs!$B$144 -> 960 | G29: =MIN(IF(F$1=0,MthRem,12), MAX(Inputs!$G$142-IF(F$1=0,0,F$1*12+MthOff), 0))*Inputs!$B$144 -> 960 | H29: =MIN(IF(G$1=0,MthRem,12), MAX(Inputs!$G$142-IF(G$1=0,0,G$1*12+MthOff), 0))*Inputs!$B$144 -> 288.25859 | I29: =MIN(IF(H$1=0,MthRem,12), MAX(Inputs!$G$142-IF(H$1=0,0,H$1*12+MthOff), 0))*Inputs!$B$144 -> 0 | J29: =MIN(IF(I$1=0,MthRem,12), MAX(Inputs!$G$142-IF(I$1=0,0,I$1*12+MthOff), 0))*Inputs!$B$144 -> 0 | ... AM29: =MIN(IF(AL$1=0,MthRem,12), MAX(Inputs!$G$142-IF(AL$1=0,0,AL$1*12+MthOff), 0))*Inputs!$B$144 -> 0
A30: =TEXT(Inputs!$B$80,"") -> Marsa | C30: =MIN(IF(B$1=0,MthRem,12), MAX(Inputs!$G$147-IF(B$1=0,0,B$1*12+MthOff), 0))*Inputs!$B$149 -> 1200 | D30: =MIN(IF(C$1=0,MthRem,12), MAX(Inputs!$G$147-IF(C$1=0,0,C$1*12+MthOff), 0))*Inputs!$B$149 -> 1440 | E30: =MIN(IF(D$1=0,MthRem,12), MAX(Inputs!$G$147-IF(D$1=0,0,D$1*12+MthOff), 0))*Inputs!$B$149 -> 1440 | F30: =MIN(IF(E$1=0,MthRem,12), MAX(Inputs!$G$147-IF(E$1=0,0,E$1*12+MthOff), 0))*Inputs!$B$149 -> 1440 | G30: =MIN(IF(F$1=0,MthRem,12), MAX(Inputs!$G$147-IF(F$1=0,0,F$1*12+MthOff), 0))*Inputs!$B$149 -> 1440 | H30: =MIN(IF(G$1=0,MthRem,12), MAX(Inputs!$G$147-IF(G$1=0,0,G$1*12+MthOff), 0))*Inputs!$B$149 -> 1440 | I30: =MIN(IF(H$1=0,MthRem,12), MAX(Inputs!$G$147-IF(H$1=0,0,H$1*12+MthOff), 0))*Inputs!$B$149 -> 1440 | J30: =MIN(IF(I$1=0,MthRem,12), MAX(Inputs!$G$147-IF(I$1=0,0,I$1*12+MthOff), 0))*Inputs!$B$149 -> 789.24881 | ... AM30: =MIN(IF(AL$1=0,MthRem,12), MAX(Inputs!$G$147-IF(AL$1=0,0,AL$1*12+MthOff), 0))*Inputs!$B$149 -> 0
A31: =TEXT(Inputs!$B$87,"") -> Jewelry | C31: =MIN(IF(B$1=0,MthRem,12), MAX(Inputs!$G$152-IF(B$1=0,0,B$1*12+MthOff), 0))*Inputs!$B$154 -> 750 | D31: =MIN(IF(C$1=0,MthRem,12), MAX(Inputs!$G$152-IF(C$1=0,0,C$1*12+MthOff), 0))*Inputs!$B$154 -> 900 | E31: =MIN(IF(D$1=0,MthRem,12), MAX(Inputs!$G$152-IF(D$1=0,0,D$1*12+MthOff), 0))*Inputs!$B$154 -> 900 | F31: =MIN(IF(E$1=0,MthRem,12), MAX(Inputs!$G$152-IF(E$1=0,0,E$1*12+MthOff), 0))*Inputs!$B$154 -> 63.602878 | G31: =MIN(IF(F$1=0,MthRem,12), MAX(Inputs!$G$152-IF(F$1=0,0,F$1*12+MthOff), 0))*Inputs!$B$154 -> 0 | H31: =MIN(IF(G$1=0,MthRem,12), MAX(Inputs!$G$152-IF(G$1=0,0,G$1*12+MthOff), 0))*Inputs!$B$154 -> 0 | I31: =MIN(IF(H$1=0,MthRem,12), MAX(Inputs!$G$152-IF(H$1=0,0,H$1*12+MthOff), 0))*Inputs!$B$154 -> 0 | J31: =MIN(IF(I$1=0,MthRem,12), MAX(Inputs!$G$152-IF(I$1=0,0,I$1*12+MthOff), 0))*Inputs!$B$154 -> 0 | ... AM31: =MIN(IF(AL$1=0,MthRem,12), MAX(Inputs!$G$152-IF(AL$1=0,0,AL$1*12+MthOff), 0))*Inputs!$B$154 -> 0
A32: =TEXT(Inputs!$B$92,"") -> Car | C32: =MIN(IF(B$1=0,MthRem,12), MAX(Inputs!$G$157-IF(B$1=0,0,B$1*12+MthOff), 0))*Inputs!$B$159 -> 860 | D32: =MIN(IF(C$1=0,MthRem,12), MAX(Inputs!$G$157-IF(C$1=0,0,C$1*12+MthOff), 0))*Inputs!$B$159 -> 1032 | E32: =MIN(IF(D$1=0,MthRem,12), MAX(Inputs!$G$157-IF(D$1=0,0,D$1*12+MthOff), 0))*Inputs!$B$159 -> 1032 | F32: =MIN(IF(E$1=0,MthRem,12), MAX(Inputs!$G$157-IF(E$1=0,0,E$1*12+MthOff), 0))*Inputs!$B$159 -> 1032 | G32: =MIN(IF(F$1=0,MthRem,12), MAX(Inputs!$G$157-IF(F$1=0,0,F$1*12+MthOff), 0))*Inputs!$B$159 -> 1032 | H32: =MIN(IF(G$1=0,MthRem,12), MAX(Inputs!$G$157-IF(G$1=0,0,G$1*12+MthOff), 0))*Inputs!$B$159 -> 1032 | I32: =MIN(IF(H$1=0,MthRem,12), MAX(Inputs!$G$157-IF(H$1=0,0,H$1*12+MthOff), 0))*Inputs!$B$159 -> 363.79405 | J32: =MIN(IF(I$1=0,MthRem,12), MAX(Inputs!$G$157-IF(I$1=0,0,I$1*12+MthOff), 0))*Inputs!$B$159 -> 0 | ... AM32: =MIN(IF(AL$1=0,MthRem,12), MAX(Inputs!$G$157-IF(AL$1=0,0,AL$1*12+MthOff), 0))*Inputs!$B$159 -> 0
A33: =TEXT(Inputs!$B$97,"") -> Painting | C33: =MIN(IF(B$1=0,MthRem,12), MAX(Inputs!$G$162-IF(B$1=0,0,B$1*12+MthOff), 0))*Inputs!$B$164 -> 1250 | D33: =MIN(IF(C$1=0,MthRem,12), MAX(Inputs!$G$162-IF(C$1=0,0,C$1*12+MthOff), 0))*Inputs!$B$164 -> 1500 | E33: =MIN(IF(D$1=0,MthRem,12), MAX(Inputs!$G$162-IF(D$1=0,0,D$1*12+MthOff), 0))*Inputs!$B$164 -> 1500 | F33: =MIN(IF(E$1=0,MthRem,12), MAX(Inputs!$G$162-IF(E$1=0,0,E$1*12+MthOff), 0))*Inputs!$B$164 -> 1500 | G33: =MIN(IF(F$1=0,MthRem,12), MAX(Inputs!$G$162-IF(F$1=0,0,F$1*12+MthOff), 0))*Inputs!$B$164 -> 1500 | H33: =MIN(IF(G$1=0,MthRem,12), MAX(Inputs!$G$162-IF(G$1=0,0,G$1*12+MthOff), 0))*Inputs!$B$164 -> 1398.4298 | I33: =MIN(IF(H$1=0,MthRem,12), MAX(Inputs!$G$162-IF(H$1=0,0,H$1*12+MthOff), 0))*Inputs!$B$164 -> 0 | J33: =MIN(IF(I$1=0,MthRem,12), MAX(Inputs!$G$162-IF(I$1=0,0,I$1*12+MthOff), 0))*Inputs!$B$164 -> 0 | ... AM33: =MIN(IF(AL$1=0,MthRem,12), MAX(Inputs!$G$162-IF(AL$1=0,0,AL$1*12+MthOff), 0))*Inputs!$B$164 -> 0
A34: =TEXT(Inputs!$B$102,"") -> Boat | C34: =MIN(IF(B$1=0,MthRem,12), MAX(Inputs!$G$167-IF(B$1=0,0,B$1*12+MthOff), 0))*Inputs!$B$169 -> 6240 | D34: =MIN(IF(C$1=0,MthRem,12), MAX(Inputs!$G$167-IF(C$1=0,0,C$1*12+MthOff), 0))*Inputs!$B$169 -> 7488 | E34: =MIN(IF(D$1=0,MthRem,12), MAX(Inputs!$G$167-IF(D$1=0,0,D$1*12+MthOff), 0))*Inputs!$B$169 -> 7488 | F34: =MIN(IF(E$1=0,MthRem,12), MAX(Inputs!$G$167-IF(E$1=0,0,E$1*12+MthOff), 0))*Inputs!$B$169 -> 7488 | G34: =MIN(IF(F$1=0,MthRem,12), MAX(Inputs!$G$167-IF(F$1=0,0,F$1*12+MthOff), 0))*Inputs!$B$169 -> 7488 | H34: =MIN(IF(G$1=0,MthRem,12), MAX(Inputs!$G$167-IF(G$1=0,0,G$1*12+MthOff), 0))*Inputs!$B$169 -> 7488 | I34: =MIN(IF(H$1=0,MthRem,12), MAX(Inputs!$G$167-IF(H$1=0,0,H$1*12+MthOff), 0))*Inputs!$B$169 -> 4665.2926 | J34: =MIN(IF(I$1=0,MthRem,12), MAX(Inputs!$G$167-IF(I$1=0,0,I$1*12+MthOff), 0))*Inputs!$B$169 -> 0 | ... AM34: =MIN(IF(AL$1=0,MthRem,12), MAX(Inputs!$G$167-IF(AL$1=0,0,AL$1*12+MthOff), 0))*Inputs!$B$169 -> 0
A35: =TEXT(Inputs!$B$107,"") -> Antiques | C35: =MIN(IF(B$1=0,MthRem,12), MAX(Inputs!$G$172-IF(B$1=0,0,B$1*12+MthOff), 0))*Inputs!$B$174 -> 1100 | D35: =MIN(IF(C$1=0,MthRem,12), MAX(Inputs!$G$172-IF(C$1=0,0,C$1*12+MthOff), 0))*Inputs!$B$174 -> 1320 | E35: =MIN(IF(D$1=0,MthRem,12), MAX(Inputs!$G$172-IF(D$1=0,0,D$1*12+MthOff), 0))*Inputs!$B$174 -> 1320 | F35: =MIN(IF(E$1=0,MthRem,12), MAX(Inputs!$G$172-IF(E$1=0,0,E$1*12+MthOff), 0))*Inputs!$B$174 -> 239.16176 | G35: =MIN(IF(F$1=0,MthRem,12), MAX(Inputs!$G$172-IF(F$1=0,0,F$1*12+MthOff), 0))*Inputs!$B$174 -> 0 | H35: =MIN(IF(G$1=0,MthRem,12), MAX(Inputs!$G$172-IF(G$1=0,0,G$1*12+MthOff), 0))*Inputs!$B$174 -> 0 | I35: =MIN(IF(H$1=0,MthRem,12), MAX(Inputs!$G$172-IF(H$1=0,0,H$1*12+MthOff), 0))*Inputs!$B$174 -> 0 | J35: =MIN(IF(I$1=0,MthRem,12), MAX(Inputs!$G$172-IF(I$1=0,0,I$1*12+MthOff), 0))*Inputs!$B$174 -> 0 | ... AM35: =MIN(IF(AL$1=0,MthRem,12), MAX(Inputs!$G$172-IF(AL$1=0,0,AL$1*12+MthOff), 0))*Inputs!$B$174 -> 0
A36: Other loan repayment | C36: =MIN(IF(B$1=0,MthRem,12), MAX(Inputs!$G$177-IF(B$1=0,0,B$1*12+MthOff), 0))*Inputs!$B$179 -> 500 | D36: =MIN(IF(C$1=0,MthRem,12), MAX(Inputs!$G$177-IF(C$1=0,0,C$1*12+MthOff), 0))*Inputs!$B$179 -> 600 | E36: =MIN(IF(D$1=0,MthRem,12), MAX(Inputs!$G$177-IF(D$1=0,0,D$1*12+MthOff), 0))*Inputs!$B$179 -> 600 | F36: =MIN(IF(E$1=0,MthRem,12), MAX(Inputs!$G$177-IF(E$1=0,0,E$1*12+MthOff), 0))*Inputs!$B$179 -> 600 | G36: =MIN(IF(F$1=0,MthRem,12), MAX(Inputs!$G$177-IF(F$1=0,0,F$1*12+MthOff), 0))*Inputs!$B$179 -> 600 | H36: =MIN(IF(G$1=0,MthRem,12), MAX(Inputs!$G$177-IF(G$1=0,0,G$1*12+MthOff), 0))*Inputs!$B$179 -> 600 | I36: =MIN(IF(H$1=0,MthRem,12), MAX(Inputs!$G$177-IF(H$1=0,0,H$1*12+MthOff), 0))*Inputs!$B$179 -> 600 | J36: =MIN(IF(I$1=0,MthRem,12), MAX(Inputs!$G$177-IF(I$1=0,0,I$1*12+MthOff), 0))*Inputs!$B$179 -> 600 | ... AM36: =MIN(IF(AL$1=0,MthRem,12), MAX(Inputs!$G$177-IF(AL$1=0,0,AL$1*12+MthOff), 0))*Inputs!$B$179 -> 0
A37: Dependents cost
A38: =TEXT(Inputs!B33,"") -> John | C38: =IF(Inputs!$B$35>=C$1,Inputs!$B$34,0)*(1+inf)^B$1*ProRate -> 1666.6667 | D38: =IF(Inputs!$B$35>=D$1,Inputs!$B$34,0)*(1+inf)^C$1 -> 2050 | E38: =IF(Inputs!$B$35>=E$1,Inputs!$B$34,0)*(1+inf)^D$1 -> 2101.25 | F38: =IF(Inputs!$B$35>=F$1,Inputs!$B$34,0)*(1+inf)^E$1 -> 0 | G38: =IF(Inputs!$B$35>=G$1,Inputs!$B$34,0)*(1+inf)^F$1 -> 0 | H38: =IF(Inputs!$B$35>=H$1,Inputs!$B$34,0)*(1+inf)^G$1 -> 0 | I38: =IF(Inputs!$B$35>=I$1,Inputs!$B$34,0)*(1+inf)^H$1 -> 0 | J38: =IF(Inputs!$B$35>=J$1,Inputs!$B$34,0)*(1+inf)^I$1 -> 0 | K38: =IF(Inputs!$B$35>=K$1,Inputs!$B$34,0)*(1+inf)^J$1 -> 0 | ... AM38: =IF(Inputs!$B$35>=AM$1,Inputs!$B$34,0)*(1+inf)^AL$1 -> 0
A39: =TEXT(Inputs!B38,"") -> Jack | C39: =IF(Inputs!$B$40>=C$1,Inputs!$B$39,0)*(1+inf)^B$1*ProRate -> 833.33333 | D39: =IF(Inputs!$B$40>=D$1,Inputs!$B$39,0)*(1+inf)^C$1 -> 1025 | E39: =IF(Inputs!$B$40>=E$1,Inputs!$B$39,0)*(1+inf)^D$1 -> 1050.625 | F39: =IF(Inputs!$B$40>=F$1,Inputs!$B$39,0)*(1+inf)^E$1 -> 1076.8906 | G39: =IF(Inputs!$B$40>=G$1,Inputs!$B$39,0)*(1+inf)^F$1 -> 1103.8129 | H39: =IF(Inputs!$B$40>=H$1,Inputs!$B$39,0)*(1+inf)^G$1 -> 0 | I39: =IF(Inputs!$B$40>=I$1,Inputs!$B$39,0)*(1+inf)^H$1 -> 0 | J39: =IF(Inputs!$B$40>=J$1,Inputs!$B$39,0)*(1+inf)^I$1 -> 0 | K39: =IF(Inputs!$B$40>=K$1,Inputs!$B$39,0)*(1+inf)^J$1 -> 0 | ... AM39: =IF(Inputs!$B$40>=AM$1,Inputs!$B$39,0)*(1+inf)^AL$1 -> 0
A40: =TEXT(Inputs!B43,"") -> Bill | C40: =IF(Inputs!$B$45>=C$1,Inputs!$B$44,0)*(1+inf)^B$1*ProRate -> 3333.3333 | D40: =IF(Inputs!$B$45>=D$1,Inputs!$B$44,0)*(1+inf)^C$1 -> 4100 | E40: =IF(Inputs!$B$45>=E$1,Inputs!$B$44,0)*(1+inf)^D$1 -> 0 | F40: =IF(Inputs!$B$45>=F$1,Inputs!$B$44,0)*(1+inf)^E$1 -> 0 | G40: =IF(Inputs!$B$45>=G$1,Inputs!$B$44,0)*(1+inf)^F$1 -> 0 | H40: =IF(Inputs!$B$45>=H$1,Inputs!$B$44,0)*(1+inf)^G$1 -> 0 | I40: =IF(Inputs!$B$45>=I$1,Inputs!$B$44,0)*(1+inf)^H$1 -> 0 | J40: =IF(Inputs!$B$45>=J$1,Inputs!$B$44,0)*(1+inf)^I$1 -> 0 | K40: =IF(Inputs!$B$45>=K$1,Inputs!$B$44,0)*(1+inf)^J$1 -> 0 | ... AM40: =IF(Inputs!$B$45>=AM$1,Inputs!$B$44,0)*(1+inf)^AL$1 -> 0
...

Sheet RetEarly_Engine
B1: 0 | C1: 1 | D1: =C1+1 -> 2 | E1: =D1+1 -> 3 | F1: =E1+1 -> 4 | G1: =F1+1 -> 5 | H1: =G1+1 -> 6 | I1: =H1+1 -> 7 | J1: =I1+1 -> 8 | K1: =J1+1 -> 9 | ... AM1: =AL1+1 -> 37
B2: Year | C2: =YEAR(TODAY()) -> 2026 | D2: =C2+1 -> 2027 | E2: =D2+1 -> 2028 | F2: =E2+1 -> 2029 | G2: =F2+1 -> 2030 | H2: =G2+1 -> 2031 | I2: =H2+1 -> 2032 | J2: =I2+1 -> 2033 | K2: =J2+1 -> 2034 | ... AM2: =AL2+1 -> 2062
B3: 51 | C3: =Inputs!B4 -> 48 | D3: =C3+1 -> 49 | E3: =D3+1 -> 50 | F3: =E3+1 -> 51 | G3: =F3+1 -> 52 | H3: =G3+1 -> 53 | I3: =H3+1 -> 54 | J3: =I3+1 -> 55 | K3: =J3+1 -> 56 | ... AM3: =AL3+1 -> 84
A4: Inflows
A5: Net employment / self-employment income | C5: =IF(AND(Inputs!$B$19>C3,$B$3>C3),Inputs!$B$6*(1+sincr)^B1,0)*ProRate -> 66666.667 | D5: =IF(AND(Inputs!$B$19>D3,$B$3>D3),Inputs!$B$6*(1+sincr)^C1,0) -> 82400 | E5: =IF(AND(Inputs!$B$19>E3,$B$3>E3),Inputs!$B$6*(1+sincr)^D1,0) -> 84872 | F5: =IF(AND(Inputs!$B$19>F3,$B$3>F3),Inputs!$B$6*(1+sincr)^E1,0) -> 0 | G5: =IF(AND(Inputs!$B$19>G3,$B$3>G3),Inputs!$B$6*(1+sincr)^F1,0) -> 0 | H5: =IF(AND(Inputs!$B$19>H3,$B$3>H3),Inputs!$B$6*(1+sincr)^G1,0) -> 0 | I5: =IF(AND(Inputs!$B$19>I3,$B$3>I3),Inputs!$B$6*(1+sincr)^H1,0) -> 0 | J5: =IF(AND(Inputs!$B$19>J3,$B$3>J3),Inputs!$B$6*(1+sincr)^I1,0) -> 0 | K5: =IF(AND(Inputs!$B$19>K3,$B$3>K3),Inputs!$B$6*(1+sincr)^J1,0) -> 0 | ... AM5: =IF(AND(Inputs!$B$19>AM3,$B$3>AM3),Inputs!$B$6*(1+sincr)^AL1,0) -> 0
A6: Net from other work | C6: =IF(C$3<=Inputs!$B$120,Inputs!$B$119,0)*(1+inf)^B$1*ProRate -> 1666.6667 | D6: =IF(D$3<=Inputs!$B$120,Inputs!$B$119,0)*(1+inf)^C$1 -> 2050 | E6: =IF(E$3<=Inputs!$B$120,Inputs!$B$119,0)*(1+inf)^D$1 -> 2101.25 | F6: =IF(F$3<=Inputs!$B$120,Inputs!$B$119,0)*(1+inf)^E$1 -> 2153.7812 | G6: =IF(G$3<=Inputs!$B$120,Inputs!$B$119,0)*(1+inf)^F$1 -> 2207.6258 | H6: =IF(H$3<=Inputs!$B$120,Inputs!$B$119,0)*(1+inf)^G$1 -> 2262.8164 | I6: =IF(I$3<=Inputs!$B$120,Inputs!$B$119,0)*(1+inf)^H$1 -> 2319.3868 | J6: =IF(J$3<=Inputs!$B$120,Inputs!$B$119,0)*(1+inf)^I$1 -> 2377.3715 | K6: =IF(K$3<=Inputs!$B$120,Inputs!$B$119,0)*(1+inf)^J$1 -> 2436.8058 | ... AM6: =IF(AM$3<=Inputs!$B$120,Inputs!$B$119,0)*(1+inf)^AL$1 -> 0
A7: Net rental income from other properties
A8: =TEXT(Inputs!$B$60,"") -> Sliema | C8: =Inputs!B113*ProRate -> 10000 | D8: =C8*(1+rinc) -> 10300 | E8: =D8*(1+rinc) -> 10609 | F8: =E8*(1+rinc) -> 10927.27 | G8: =F8*(1+rinc) -> 11255.088 | H8: =G8*(1+rinc) -> 11592.741 | I8: =H8*(1+rinc) -> 11940.523 | J8: =I8*(1+rinc) -> 12298.739 | K8: =J8*(1+rinc) -> 12667.701 | ... AM8: =AL8*(1+rinc) -> 28982.783
A9: =TEXT(Inputs!$B$65,"") -> Gzira | C9: =Inputs!B114*ProRate -> 8333.3333 | D9: =C9*(1+rinc) -> 8583.3333 | E9: =D9*(1+rinc) -> 8840.8333 | F9: =E9*(1+rinc) -> 9106.0583 | G9: =F9*(1+rinc) -> 9379.2401 | H9: =G9*(1+rinc) -> 9660.6173 | I9: =H9*(1+rinc) -> 9950.4358 | J9: =I9*(1+rinc) -> 10248.949 | K9: =J9*(1+rinc) -> 10556.417 | ... AM9: =AL9*(1+rinc) -> 24152.319
A10: =TEXT(Inputs!$B$70,"") -> Qormi | C10: =Inputs!B115*ProRate -> 6666.6667 | D10: =C10*(1+rinc) -> 6866.6667 | E10: =D10*(1+rinc) -> 7072.6667 | F10: =E10*(1+rinc) -> 7284.8467 | G10: =F10*(1+rinc) -> 7503.3921 | H10: =G10*(1+rinc) -> 7728.4938 | I10: =H10*(1+rinc) -> 7960.3486 | J10: =I10*(1+rinc) -> 8199.1591 | K10: =J10*(1+rinc) -> 8445.1339 | ... AM10: =AL10*(1+rinc) -> 19321.856
A11: =TEXT(Inputs!$B$75,"") -> Gudja | C11: =Inputs!B116*ProRate -> 4166.6667 | D11: =C11*(1+rinc) -> 4291.6667 | E11: =D11*(1+rinc) -> 4420.4167 | F11: =E11*(1+rinc) -> 4553.0292 | G11: =F11*(1+rinc) -> 4689.62 | H11: =G11*(1+rinc) -> 4830.3086 | I11: =H11*(1+rinc) -> 4975.2179 | J11: =I11*(1+rinc) -> 5124.4744 | K11: =J11*(1+rinc) -> 5278.2087 | ... AM11: =AL11*(1+rinc) -> 12076.16
A12: =TEXT(Inputs!$B$80,"") -> Marsa | C12: =Inputs!B117*ProRate -> 5416.6667 | D12: =C12*(1+rinc) -> 5579.1667 | E12: =D12*(1+rinc) -> 5746.5417 | F12: =E12*(1+rinc) -> 5918.9379 | G12: =F12*(1+rinc) -> 6096.5061 | H12: =G12*(1+rinc) -> 6279.4012 | I12: =H12*(1+rinc) -> 6467.7833 | J12: =I12*(1+rinc) -> 6661.8168 | K12: =J12*(1+rinc) -> 6861.6713 | ... AM12: =AL12*(1+rinc) -> 15699.008
A13: Full pension | C13: =IF(C$3<Inputs!$B$19,0,Inputs!$B$21)*(1+inf)^B$1*ProRate -> 0 | D13: =IF(D$3<Inputs!$B$19,0,Inputs!$B$21)*(1+inf)^C$1 -> 0 | E13: =IF(E$3<Inputs!$B$19,0,Inputs!$B$21)*(1+inf)^D$1 -> 0 | F13: =IF(F$3<Inputs!$B$19,0,Inputs!$B$21)*(1+inf)^E$1 -> 0 | G13: =IF(G$3<Inputs!$B$19,0,Inputs!$B$21)*(1+inf)^F$1 -> 0 | H13: =IF(H$3<Inputs!$B$19,0,Inputs!$B$21)*(1+inf)^G$1 -> 0 | I13: =IF(I$3<Inputs!$B$19,0,Inputs!$B$21)*(1+inf)^H$1 -> 0 | J13: =IF(J$3<Inputs!$B$19,0,Inputs!$B$21)*(1+inf)^I$1 -> 0 | K13: =IF(K$3<Inputs!$B$19,0,Inputs!$B$21)*(1+inf)^J$1 -> 0 | ... AM13: =IF(AM$3<Inputs!$B$19,0,Inputs!$B$21)*(1+inf)^AL$1 -> 38920.565
A14: Pension reduction from early retirement | C14: =MIN(0,MAX(-IF(C13=0,0,(Inputs!$B$19-INDEX(3:3,MATCH(0,5:5,0))))*Inputs!$B$267*(1+inf)^B$1*ProRate,-C13)) -> 0 | D14: =MIN(0,MAX(-IF(D13=0,0,(Inputs!$B$19-INDEX(3:3,MATCH(0,5:5,0))))*Inputs!$B$267*(1+inf)^C$1,-D13)) -> 0 | E14: =MIN(0,MAX(-IF(E13=0,0,(Inputs!$B$19-INDEX(3:3,MATCH(0,5:5,0))))*Inputs!$B$267*(1+inf)^D$1,-E13)) -> 0 | F14: =MIN(0,MAX(-IF(F13=0,0,(Inputs!$B$19-INDEX(3:3,MATCH(0,5:5,0))))*Inputs!$B$267*(1+inf)^E$1,-F13)) -> 0 | G14: =MIN(0,MAX(-IF(G13=0,0,(Inputs!$B$19-INDEX(3:3,MATCH(0,5:5,0))))*Inputs!$B$267*(1+inf)^F$1,-G13)) -> 0 | H14: =MIN(0,MAX(-IF(H13=0,0,(Inputs!$B$19-INDEX(3:3,MATCH(0,5:5,0))))*Inputs!$B$267*(1+inf)^G$1,-H13)) -> 0 | I14: =MIN(0,MAX(-IF(I13=0,0,(Inputs!$B$19-INDEX(3:3,MATCH(0,5:5,0))))*Inputs!$B$267*(1+inf)^H$1,-I13)) -> 0 | J14: =MIN(0,MAX(-IF(J13=0,0,(Inputs!$B$19-INDEX(3:3,MATCH(0,5:5,0))))*Inputs!$B$267*(1+inf)^I$1,-J13)) -> 0 | K14: =MIN(0,MAX(-IF(K13=0,0,(Inputs!$B$19-INDEX(3:3,MATCH(0,5:5,0))))*Inputs!$B$267*(1+inf)^J$1,-K13)) -> 0 | ... AM14: =MIN(0,MAX(-IF(AM13=0,0,(Inputs!$B$19-INDEX(3:3,MATCH(0,5:5,0))))*Inputs!$B$267*(1+inf)^AL$1,-AM13)) -> -10216.648
A15: Other post-retirement income | C15: =IF(AND(C$3>=Inputs!$B$252,C$3<=Inputs!$B$253),Inputs!$B$251*(1+inf)^B$1,0)*ProRate -> 0 | D15: =IF(AND(D$3>=Inputs!$B$252,D$3<=Inputs!$B$253),Inputs!$B$251*(1+inf)^C$1,0) -> 0 | E15: =IF(AND(E$3>=Inputs!$B$252,E$3<=Inputs!$B$253),Inputs!$B$251*(1+inf)^D$1,0) -> 0 | F15: =IF(AND(F$3>=Inputs!$B$252,F$3<=Inputs!$B$253),Inputs!$B$251*(1+inf)^E$1,0) -> 0 | G15: =IF(AND(G$3>=Inputs!$B$252,G$3<=Inputs!$B$253),Inputs!$B$251*(1+inf)^F$1,0) -> 0 | H15: =IF(AND(H$3>=Inputs!$B$252,H$3<=Inputs!$B$253),Inputs!$B$251*(1+inf)^G$1,0) -> 0 | I15: =IF(AND(I$3>=Inputs!$B$252,I$3<=Inputs!$B$253),Inputs!$B$251*(1+inf)^H$1,0) -> 0 | J15: =IF(AND(J$3>=Inputs!$B$252,J$3<=Inputs!$B$253),Inputs!$B$251*(1+inf)^I$1,0) -> 0 | K15: =IF(AND(K$3>=Inputs!$B$252,K$3<=Inputs!$B$253),Inputs!$B$251*(1+inf)^J$1,0) -> 0 | ... AM15: =IF(AND(AM$3>=Inputs!$B$252,AM$3<=Inputs!$B$253),Inputs!$B$251*(1+inf)^AL$1,0) -> 0
A16: Major one-off income events
A17: =TEXT(Inputs!B184,"") -> Inheritance | C17: =IF(C$2=Inputs!$B186,Inputs!$B185,0)*(1+inf)^B$1 -> 0 | D17: =IF(D$2=Inputs!$B186,Inputs!$B185,0)*(1+inf)^C$1 -> 0 | E17: =IF(E$2=Inputs!$B186,Inputs!$B185,0)*(1+inf)^D$1 -> 0 | F17: =IF(F$2=Inputs!$B186,Inputs!$B185,0)*(1+inf)^E$1 -> 0 | G17: =IF(G$2=Inputs!$B186,Inputs!$B185,0)*(1+inf)^F$1 -> 0 | H17: =IF(H$2=Inputs!$B186,Inputs!$B185,0)*(1+inf)^G$1 -> 0 | I17: =IF(I$2=Inputs!$B186,Inputs!$B185,0)*(1+inf)^H$1 -> 0 | J17: =IF(J$2=Inputs!$B186,Inputs!$B185,0)*(1+inf)^I$1 -> 0 | ... AM17: =IF(AM$2=Inputs!$B186,Inputs!$B185,0)*(1+inf)^AL$1 -> 0
A18: =TEXT(Inputs!B189,"") -> Sell Painting | C18: =IF(C$2=Inputs!$B191,Inputs!$B190,0)*(1+inf)^B$1 -> 0 | D18: =IF(D$2=Inputs!$B191,Inputs!$B190,0)*(1+inf)^C$1 -> 0 | E18: =IF(E$2=Inputs!$B191,Inputs!$B190,0)*(1+inf)^D$1 -> 0 | F18: =IF(F$2=Inputs!$B191,Inputs!$B190,0)*(1+inf)^E$1 -> 10768.906 | G18: =IF(G$2=Inputs!$B191,Inputs!$B190,0)*(1+inf)^F$1 -> 0 | H18: =IF(H$2=Inputs!$B191,Inputs!$B190,0)*(1+inf)^G$1 -> 0 | I18: =IF(I$2=Inputs!$B191,Inputs!$B190,0)*(1+inf)^H$1 -> 0 | J18: =IF(J$2=Inputs!$B191,Inputs!$B190,0)*(1+inf)^I$1 -> 0 | ... AM18: =IF(AM$2=Inputs!$B191,Inputs!$B190,0)*(1+inf)^AL$1 -> 0
A19: =TEXT(Inputs!B194,"") -> Sell Jewels | C19: =IF(C$2=Inputs!$B196,Inputs!$B195,0)*(1+inf)^B$1 -> 0 | D19: =IF(D$2=Inputs!$B196,Inputs!$B195,0)*(1+inf)^C$1 -> 0 | E19: =IF(E$2=Inputs!$B196,Inputs!$B195,0)*(1+inf)^D$1 -> 0 | F19: =IF(F$2=Inputs!$B196,Inputs!$B195,0)*(1+inf)^E$1 -> 0 | G19: =IF(G$2=Inputs!$B196,Inputs!$B195,0)*(1+inf)^F$1 -> 0 | H19: =IF(H$2=Inputs!$B196,Inputs!$B195,0)*(1+inf)^G$1 -> 0 | I19: =IF(I$2=Inputs!$B196,Inputs!$B195,0)*(1+inf)^H$1 -> 5798.4671 | J19: =IF(J$2=Inputs!$B196,Inputs!$B195,0)*(1+inf)^I$1 -> 0 | ... AM19: =IF(AM$2=Inputs!$B196,Inputs!$B195,0)*(1+inf)^AL$1 -> 0
A20: Interest on cash balances | C20: =MAX(AVERAGE(C62,C62+SUM(C5:C19)-C59)*Inputs!$B$259,0) -> 1392.7083 | D20: =MAX(AVERAGE(D62,D62+SUM(D5:D19)-D59)*Inputs!$B$259,0) -> 1691.0073 | E20: =MAX(AVERAGE(E62,E62+SUM(E5:E19)-E59)*Inputs!$B$259,0) -> 2049.0802 | F20: =MAX(AVERAGE(F62,F62+SUM(F5:F19)-F59)*Inputs!$B$259,0) -> 1174.1477 | G20: =MAX(AVERAGE(G62,G62+SUM(G5:G19)-G59)*Inputs!$B$259,0) -> 0 | H20: =MAX(AVERAGE(H62,H62+SUM(H5:H19)-H59)*Inputs!$B$259,0) -> 0 | I20: =MAX(AVERAGE(I62,I62+SUM(I5:I19)-I59)*Inputs!$B$259,0) -> 0 | J20: =MAX(AVERAGE(J62,J62+SUM(J5:J19)-J59)*Inputs!$B$259,0) -> 0 | ... AM20: =MAX(AVERAGE(AM62,AM62+SUM(AM5:AM19)-AM59)*Inputs!$B$259,0) -> 0
C21: =SUM(C4:C20) -> 104309.38 | D21: =SUM(D4:D20) -> 121761.84 | E21: =SUM(E4:E20) -> 125711.79 | F21: =SUM(F4:F20) -> 51886.977 | G21: =SUM(G4:G20) -> 41131.472 | H21: =SUM(H4:H20) -> 42354.378 | I21: =SUM(I4:I20) -> 49412.163 | J21: =SUM(J4:J20) -> 44910.509 | ... AM21: =SUM(AM4:AM20) -> 128936.04
A22: Outflows
A23: Credit cards cleared | C23: =Inputs!B124 -> 1000 | D23: 0 | E23: 0 | F23: 0 | G23: 0 | H23: 0 | I23: 0 | J23: 0 | K23: 0 | L23: 0 | M23: 0 | N23: 0 | O23: 0 | P23: 0 | Q23: 0 | R23: 0 | S23: 0 | T23: 0 | U23: 0 | V23: 0 | W23: 0 | X23: 0 | Y23: 0 | Z23: 0 | AA23: 0 | AB23: 0 | AC23: 0 | AD23: 0 | AE23: 0 | AF23: 0 | AG23: 0 | AH23: 0 | AI23: 0 | AJ23: 0 | AK23: 0 | AL23: 0 | AM23: 0
A24: Home loan repayment | C24: =MIN(IF(B$1=0,MthRem,12), MAX(Inputs!$G$15-IF(B$1=0,0,B$1*12+MthOff), 0))*Inputs!$B$17 -> 8000 | D24: =MIN(IF(C$1=0,MthRem,12), MAX(Inputs!$G$15-IF(C$1=0,0,C$1*12+MthOff), 0))*Inputs!$B$17 -> 9600 | E24: =MIN(IF(D$1=0,MthRem,12), MAX(Inputs!$G$15-IF(D$1=0,0,D$1*12+MthOff), 0))*Inputs!$B$17 -> 9600 | F24: =MIN(IF(E$1=0,MthRem,12), MAX(Inputs!$G$15-IF(E$1=0,0,E$1*12+MthOff), 0))*Inputs!$B$17 -> 9600 | G24: =MIN(IF(F$1=0,MthRem,12), MAX(Inputs!$G$15-IF(F$1=0,0,F$1*12+MthOff), 0))*Inputs!$B$17 -> 9600 | H24: =MIN(IF(G$1=0,MthRem,12), MAX(Inputs!$G$15-IF(G$1=0,0,G$1*12+MthOff), 0))*Inputs!$B$17 -> 8035.6231 | I24: =MIN(IF(H$1=0,MthRem,12), MAX(Inputs!$G$15-IF(H$1=0,0,H$1*12+MthOff), 0))*Inputs!$B$17 -> 0 | J24: =MIN(IF(I$1=0,MthRem,12), MAX(Inputs!$G$15-IF(I$1=0,0,I$1*12+MthOff), 0))*Inputs!$B$17 -> 0 | ... AM24: =MIN(IF(AL$1=0,MthRem,12), MAX(Inputs!$G$15-IF(AL$1=0,0,AL$1*12+MthOff), 0))*Inputs!$B$17 -> 0
A25: Other asset loans repayments
A26: =TEXT(Inputs!$B$60,"") -> Sliema | C26: =MIN(IF(B$1=0,MthRem,12), MAX(Inputs!$G$127-IF(B$1=0,0,B$1*12+MthOff), 0))*Inputs!$B$129 -> 5000 | D26: =MIN(IF(C$1=0,MthRem,12), MAX(Inputs!$G$127-IF(C$1=0,0,C$1*12+MthOff), 0))*Inputs!$B$129 -> 6000 | E26: =MIN(IF(D$1=0,MthRem,12), MAX(Inputs!$G$127-IF(D$1=0,0,D$1*12+MthOff), 0))*Inputs!$B$129 -> 6000 | F26: =MIN(IF(E$1=0,MthRem,12), MAX(Inputs!$G$127-IF(E$1=0,0,E$1*12+MthOff), 0))*Inputs!$B$129 -> 6000 | G26: =MIN(IF(F$1=0,MthRem,12), MAX(Inputs!$G$127-IF(F$1=0,0,F$1*12+MthOff), 0))*Inputs!$B$129 -> 6000 | H26: =MIN(IF(G$1=0,MthRem,12), MAX(Inputs!$G$127-IF(G$1=0,0,G$1*12+MthOff), 0))*Inputs!$B$129 -> 6000 | I26: =MIN(IF(H$1=0,MthRem,12), MAX(Inputs!$G$127-IF(H$1=0,0,H$1*12+MthOff), 0))*Inputs!$B$129 -> 6000 | J26: =MIN(IF(I$1=0,MthRem,12), MAX(Inputs!$G$127-IF(I$1=0,0,I$1*12+MthOff), 0))*Inputs!$B$129 -> 6000 | ... AM26: =MIN(IF(AL$1=0,MthRem,12), MAX(Inputs!$G$127-IF(AL$1=0,0,AL$1*12+MthOff), 0))*Inputs!$B$129 -> 0
A27: =TEXT(Inputs!$B$65,"") -> Gzira | C27: =MIN(IF(B$1=0,MthRem,12), MAX(Inputs!$G$132-IF(B$1=0,0,B$1*12+MthOff), 0))*Inputs!$B$134 -> 2000 | D27: =MIN(IF(C$1=0,MthRem,12), MAX(Inputs!$G$132-IF(C$1=0,0,C$1*12+MthOff), 0))*Inputs!$B$134 -> 2400 | E27: =MIN(IF(D$1=0,MthRem,12), MAX(Inputs!$G$132-IF(D$1=0,0,D$1*12+MthOff), 0))*Inputs!$B$134 -> 2400 | F27: =MIN(IF(E$1=0,MthRem,12), MAX(Inputs!$G$132-IF(E$1=0,0,E$1*12+MthOff), 0))*Inputs!$B$134 -> 2023.4029 | G27: =MIN(IF(F$1=0,MthRem,12), MAX(Inputs!$G$132-IF(F$1=0,0,F$1*12+MthOff), 0))*Inputs!$B$134 -> 0 | H27: =MIN(IF(G$1=0,MthRem,12), MAX(Inputs!$G$132-IF(G$1=0,0,G$1*12+MthOff), 0))*Inputs!$B$134 -> 0 | I27: =MIN(IF(H$1=0,MthRem,12), MAX(Inputs!$G$132-IF(H$1=0,0,H$1*12+MthOff), 0))*Inputs!$B$134 -> 0 | J27: =MIN(IF(I$1=0,MthRem,12), MAX(Inputs!$G$132-IF(I$1=0,0,I$1*12+MthOff), 0))*Inputs!$B$134 -> 0 | ... AM27: =MIN(IF(AL$1=0,MthRem,12), MAX(Inputs!$G$132-IF(AL$1=0,0,AL$1*12+MthOff), 0))*Inputs!$B$134 -> 0
A28: =TEXT(Inputs!$B$70,"") -> Qormi | C28: =MIN(IF(B$1=0,MthRem,12), MAX(Inputs!$G$137-IF(B$1=0,0,B$1*12+MthOff), 0))*Inputs!$B$139 -> 2500 | D28: =MIN(IF(C$1=0,MthRem,12), MAX(Inputs!$G$137-IF(C$1=0,0,C$1*12+MthOff), 0))*Inputs!$B$139 -> 3000 | E28: =MIN(IF(D$1=0,MthRem,12), MAX(Inputs!$G$137-IF(D$1=0,0,D$1*12+MthOff), 0))*Inputs!$B$139 -> 3000 | F28: =MIN(IF(E$1=0,MthRem,12), MAX(Inputs!$G$137-IF(E$1=0,0,E$1*12+MthOff), 0))*Inputs!$B$139 -> 3000 | G28: =MIN(IF(F$1=0,MthRem,12), MAX(Inputs!$G$137-IF(F$1=0,0,F$1*12+MthOff), 0))*Inputs!$B$139 -> 3000 | H28: =MIN(IF(G$1=0,MthRem,12), MAX(Inputs!$G$137-IF(G$1=0,0,G$1*12+MthOff), 0))*Inputs!$B$139 -> 2796.8597 | I28: =MIN(IF(H$1=0,MthRem,12), MAX(Inputs!$G$137-IF(H$1=0,0,H$1*12+MthOff), 0))*Inputs!$B$139 -> 0 | J28: =MIN(IF(I$1=0,MthRem,12), MAX(Inputs!$G$137-IF(I$1=0,0,I$1*12+MthOff), 0))*Inputs!$B$139 -> 0 | ... AM28: =MIN(IF(AL$1=0,MthRem,12), MAX(Inputs!$G$137-IF(AL$1=0,0,AL$1*12+MthOff), 0))*Inputs!$B$139 -> 0
A29: =TEXT(Inputs!$B$75,"") -> Gudja | C29: =MIN(IF(B$1=0,MthRem,12), MAX(Inputs!$G$142-IF(B$1=0,0,B$1*12+MthOff), 0))*Inputs!$B$144 -> 800 | D29: =MIN(IF(C$1=0,MthRem,12), MAX(Inputs!$G$142-IF(C$1=0,0,C$1*12+MthOff), 0))*Inputs!$B$144 -> 960 | E29: =MIN(IF(D$1=0,MthRem,12), MAX(Inputs!$G$142-IF(D$1=0,0,D$1*12+MthOff), 0))*Inputs!$B$144 -> 960 | F29: =MIN(IF(E$1=0,MthRem,12), MAX(Inputs!$G$142-IF(E$1=0,0,E$1*12+MthOff), 0))*Inputs!$B$144 -> 960 | G29: =MIN(IF(F$1=0,MthRem,12), MAX(Inputs!$G$142-IF(F$1=0,0,F$1*12+MthOff), 0))*Inputs!$B$144 -> 960 | H29: =MIN(IF(G$1=0,MthRem,12), MAX(Inputs!$G$142-IF(G$1=0,0,G$1*12+MthOff), 0))*Inputs!$B$144 -> 288.25859 | I29: =MIN(IF(H$1=0,MthRem,12), MAX(Inputs!$G$142-IF(H$1=0,0,H$1*12+MthOff), 0))*Inputs!$B$144 -> 0 | J29: =MIN(IF(I$1=0,MthRem,12), MAX(Inputs!$G$142-IF(I$1=0,0,I$1*12+MthOff), 0))*Inputs!$B$144 -> 0 | ... AM29: =MIN(IF(AL$1=0,MthRem,12), MAX(Inputs!$G$142-IF(AL$1=0,0,AL$1*12+MthOff), 0))*Inputs!$B$144 -> 0
A30: =TEXT(Inputs!$B$80,"") -> Marsa | C30: =MIN(IF(B$1=0,MthRem,12), MAX(Inputs!$G$147-IF(B$1=0,0,B$1*12+MthOff), 0))*Inputs!$B$149 -> 1200 | D30: =MIN(IF(C$1=0,MthRem,12), MAX(Inputs!$G$147-IF(C$1=0,0,C$1*12+MthOff), 0))*Inputs!$B$149 -> 1440 | E30: =MIN(IF(D$1=0,MthRem,12), MAX(Inputs!$G$147-IF(D$1=0,0,D$1*12+MthOff), 0))*Inputs!$B$149 -> 1440 | F30: =MIN(IF(E$1=0,MthRem,12), MAX(Inputs!$G$147-IF(E$1=0,0,E$1*12+MthOff), 0))*Inputs!$B$149 -> 1440 | G30: =MIN(IF(F$1=0,MthRem,12), MAX(Inputs!$G$147-IF(F$1=0,0,F$1*12+MthOff), 0))*Inputs!$B$149 -> 1440 | H30: =MIN(IF(G$1=0,MthRem,12), MAX(Inputs!$G$147-IF(G$1=0,0,G$1*12+MthOff), 0))*Inputs!$B$149 -> 1440 | I30: =MIN(IF(H$1=0,MthRem,12), MAX(Inputs!$G$147-IF(H$1=0,0,H$1*12+MthOff), 0))*Inputs!$B$149 -> 1440 | J30: =MIN(IF(I$1=0,MthRem,12), MAX(Inputs!$G$147-IF(I$1=0,0,I$1*12+MthOff), 0))*Inputs!$B$149 -> 789.24881 | ... AM30: =MIN(IF(AL$1=0,MthRem,12), MAX(Inputs!$G$147-IF(AL$1=0,0,AL$1*12+MthOff), 0))*Inputs!$B$149 -> 0
A31: =TEXT(Inputs!$B$87,"") -> Jewelry | C31: =MIN(IF(B$1=0,MthRem,12), MAX(Inputs!$G$152-IF(B$1=0,0,B$1*12+MthOff), 0))*Inputs!$B$154 -> 750 | D31: =MIN(IF(C$1=0,MthRem,12), MAX(Inputs!$G$152-IF(C$1=0,0,C$1*12+MthOff), 0))*Inputs!$B$154 -> 900 | E31: =MIN(IF(D$1=0,MthRem,12), MAX(Inputs!$G$152-IF(D$1=0,0,D$1*12+MthOff), 0))*Inputs!$B$154 -> 900 | F31: =MIN(IF(E$1=0,MthRem,12), MAX(Inputs!$G$152-IF(E$1=0,0,E$1*12+MthOff), 0))*Inputs!$B$154 -> 63.602878 | G31: =MIN(IF(F$1=0,MthRem,12), MAX(Inputs!$G$152-IF(F$1=0,0,F$1*12+MthOff), 0))*Inputs!$B$154 -> 0 | H31: =MIN(IF(G$1=0,MthRem,12), MAX(Inputs!$G$152-IF(G$1=0,0,G$1*12+MthOff), 0))*Inputs!$B$154 -> 0 | I31: =MIN(IF(H$1=0,MthRem,12), MAX(Inputs!$G$152-IF(H$1=0,0,H$1*12+MthOff), 0))*Inputs!$B$154 -> 0 | J31: =MIN(IF(I$1=0,MthRem,12), MAX(Inputs!$G$152-IF(I$1=0,0,I$1*12+MthOff), 0))*Inputs!$B$154 -> 0 | ... AM31: =MIN(IF(AL$1=0,MthRem,12), MAX(Inputs!$G$152-IF(AL$1=0,0,AL$1*12+MthOff), 0))*Inputs!$B$154 -> 0
A32: =TEXT(Inputs!$B$92,"") -> Car | C32: =MIN(IF(B$1=0,MthRem,12), MAX(Inputs!$G$157-IF(B$1=0,0,B$1*12+MthOff), 0))*Inputs!$B$159 -> 860 | D32: =MIN(IF(C$1=0,MthRem,12), MAX(Inputs!$G$157-IF(C$1=0,0,C$1*12+MthOff), 0))*Inputs!$B$159 -> 1032 | E32: =MIN(IF(D$1=0,MthRem,12), MAX(Inputs!$G$157-IF(D$1=0,0,D$1*12+MthOff), 0))*Inputs!$B$159 -> 1032 | F32: =MIN(IF(E$1=0,MthRem,12), MAX(Inputs!$G$157-IF(E$1=0,0,E$1*12+MthOff), 0))*Inputs!$B$159 -> 1032 | G32: =MIN(IF(F$1=0,MthRem,12), MAX(Inputs!$G$157-IF(F$1=0,0,F$1*12+MthOff), 0))*Inputs!$B$159 -> 1032 | H32: =MIN(IF(G$1=0,MthRem,12), MAX(Inputs!$G$157-IF(G$1=0,0,G$1*12+MthOff), 0))*Inputs!$B$159 -> 1032 | I32: =MIN(IF(H$1=0,MthRem,12), MAX(Inputs!$G$157-IF(H$1=0,0,H$1*12+MthOff), 0))*Inputs!$B$159 -> 363.79405 | J32: =MIN(IF(I$1=0,MthRem,12), MAX(Inputs!$G$157-IF(I$1=0,0,I$1*12+MthOff), 0))*Inputs!$B$159 -> 0 | ... AM32: =MIN(IF(AL$1=0,MthRem,12), MAX(Inputs!$G$157-IF(AL$1=0,0,AL$1*12+MthOff), 0))*Inputs!$B$159 -> 0
A33: =TEXT(Inputs!$B$97,"") -> Painting | C33: =MIN(IF(B$1=0,MthRem,12), MAX(Inputs!$G$162-IF(B$1=0,0,B$1*12+MthOff), 0))*Inputs!$B$164 -> 1250 | D33: =MIN(IF(C$1=0,MthRem,12), MAX(Inputs!$G$162-IF(C$1=0,0,C$1*12+MthOff), 0))*Inputs!$B$164 -> 1500 | E33: =MIN(IF(D$1=0,MthRem,12), MAX(Inputs!$G$162-IF(D$1=0,0,D$1*12+MthOff), 0))*Inputs!$B$164 -> 1500 | F33: =MIN(IF(E$1=0,MthRem,12), MAX(Inputs!$G$162-IF(E$1=0,0,E$1*12+MthOff), 0))*Inputs!$B$164 -> 1500 | G33: =MIN(IF(F$1=0,MthRem,12), MAX(Inputs!$G$162-IF(F$1=0,0,F$1*12+MthOff), 0))*Inputs!$B$164 -> 1500 | H33: =MIN(IF(G$1=0,MthRem,12), MAX(Inputs!$G$162-IF(G$1=0,0,G$1*12+MthOff), 0))*Inputs!$B$164 -> 1398.4298 | I33: =MIN(IF(H$1=0,MthRem,12), MAX(Inputs!$G$162-IF(H$1=0,0,H$1*12+MthOff), 0))*Inputs!$B$164 -> 0 | J33: =MIN(IF(I$1=0,MthRem,12), MAX(Inputs!$G$162-IF(I$1=0,0,I$1*12+MthOff), 0))*Inputs!$B$164 -> 0 | ... AM33: =MIN(IF(AL$1=0,MthRem,12), MAX(Inputs!$G$162-IF(AL$1=0,0,AL$1*12+MthOff), 0))*Inputs!$B$164 -> 0
A34: =TEXT(Inputs!$B$102,"") -> Boat | C34: =MIN(IF(B$1=0,MthRem,12), MAX(Inputs!$G$167-IF(B$1=0,0,B$1*12+MthOff), 0))*Inputs!$B$169 -> 6240 | D34: =MIN(IF(C$1=0,MthRem,12), MAX(Inputs!$G$167-IF(C$1=0,0,C$1*12+MthOff), 0))*Inputs!$B$169 -> 7488 | E34: =MIN(IF(D$1=0,MthRem,12), MAX(Inputs!$G$167-IF(D$1=0,0,D$1*12+MthOff), 0))*Inputs!$B$169 -> 7488 | F34: =MIN(IF(E$1=0,MthRem,12), MAX(Inputs!$G$167-IF(E$1=0,0,E$1*12+MthOff), 0))*Inputs!$B$169 -> 7488 | G34: =MIN(IF(F$1=0,MthRem,12), MAX(Inputs!$G$167-IF(F$1=0,0,F$1*12+MthOff), 0))*Inputs!$B$169 -> 7488 | H34: =MIN(IF(G$1=0,MthRem,12), MAX(Inputs!$G$167-IF(G$1=0,0,G$1*12+MthOff), 0))*Inputs!$B$169 -> 7488 | I34: =MIN(IF(H$1=0,MthRem,12), MAX(Inputs!$G$167-IF(H$1=0,0,H$1*12+MthOff), 0))*Inputs!$B$169 -> 4665.2926 | J34: =MIN(IF(I$1=0,MthRem,12), MAX(Inputs!$G$167-IF(I$1=0,0,I$1*12+MthOff), 0))*Inputs!$B$169 -> 0 | ... AM34: =MIN(IF(AL$1=0,MthRem,12), MAX(Inputs!$G$167-IF(AL$1=0,0,AL$1*12+MthOff), 0))*Inputs!$B$169 -> 0
A35: =TEXT(Inputs!$B$107,"") -> Antiques | C35: =MIN(IF(B$1=0,MthRem,12), MAX(Inputs!$G$172-IF(B$1=0,0,B$1*12+MthOff), 0))*Inputs!$B$174 -> 1100 | D35: =MIN(IF(C$1=0,MthRem,12), MAX(Inputs!$G$172-IF(C$1=0,0,C$1*12+MthOff), 0))*Inputs!$B$174 -> 1320 | E35: =MIN(IF(D$1=0,MthRem,12), MAX(Inputs!$G$172-IF(D$1=0,0,D$1*12+MthOff), 0))*Inputs!$B$174 -> 1320 | F35: =MIN(IF(E$1=0,MthRem,12), MAX(Inputs!$G$172-IF(E$1=0,0,E$1*12+MthOff), 0))*Inputs!$B$174 -> 239.16176 | G35: =MIN(IF(F$1=0,MthRem,12), MAX(Inputs!$G$172-IF(F$1=0,0,F$1*12+MthOff), 0))*Inputs!$B$174 -> 0 | H35: =MIN(IF(G$1=0,MthRem,12), MAX(Inputs!$G$172-IF(G$1=0,0,G$1*12+MthOff), 0))*Inputs!$B$174 -> 0 | I35: =MIN(IF(H$1=0,MthRem,12), MAX(Inputs!$G$172-IF(H$1=0,0,H$1*12+MthOff), 0))*Inputs!$B$174 -> 0 | J35: =MIN(IF(I$1=0,MthRem,12), MAX(Inputs!$G$172-IF(I$1=0,0,I$1*12+MthOff), 0))*Inputs!$B$174 -> 0 | ... AM35: =MIN(IF(AL$1=0,MthRem,12), MAX(Inputs!$G$172-IF(AL$1=0,0,AL$1*12+MthOff), 0))*Inputs!$B$174 -> 0
A36: Other loan repayment | C36: =MIN(IF(B$1=0,MthRem,12), MAX(Inputs!$G$177-IF(B$1=0,0,B$1*12+MthOff), 0))*Inputs!$B$179 -> 500 | D36: =MIN(IF(C$1=0,MthRem,12), MAX(Inputs!$G$177-IF(C$1=0,0,C$1*12+MthOff), 0))*Inputs!$B$179 -> 600 | E36: =MIN(IF(D$1=0,MthRem,12), MAX(Inputs!$G$177-IF(D$1=0,0,D$1*12+MthOff), 0))*Inputs!$B$179 -> 600 | F36: =MIN(IF(E$1=0,MthRem,12), MAX(Inputs!$G$177-IF(E$1=0,0,E$1*12+MthOff), 0))*Inputs!$B$179 -> 600 | G36: =MIN(IF(F$1=0,MthRem,12), MAX(Inputs!$G$177-IF(F$1=0,0,F$1*12+MthOff), 0))*Inputs!$B$179 -> 600 | H36: =MIN(IF(G$1=0,MthRem,12), MAX(Inputs!$G$177-IF(G$1=0,0,G$1*12+MthOff), 0))*Inputs!$B$179 -> 600 | I36: =MIN(IF(H$1=0,MthRem,12), MAX(Inputs!$G$177-IF(H$1=0,0,H$1*12+MthOff), 0))*Inputs!$B$179 -> 600 | J36: =MIN(IF(I$1=0,MthRem,12), MAX(Inputs!$G$177-IF(I$1=0,0,I$1*12+MthOff), 0))*Inputs!$B$179 -> 600 | ... AM36: =MIN(IF(AL$1=0,MthRem,12), MAX(Inputs!$G$177-IF(AL$1=0,0,AL$1*12+MthOff), 0))*Inputs!$B$179 -> 0
A37: Dependents cost
A38: =TEXT(Inputs!B33,"") -> John | C38: =IF(Inputs!$B$35>=C$1,Inputs!$B$34,0)*(1+inf)^B$1*ProRate -> 1666.6667 | D38: =IF(Inputs!$B$35>=D$1,Inputs!$B$34,0)*(1+inf)^C$1 -> 2050 | E38: =IF(Inputs!$B$35>=E$1,Inputs!$B$34,0)*(1+inf)^D$1 -> 2101.25 | F38: =IF(Inputs!$B$35>=F$1,Inputs!$B$34,0)*(1+inf)^E$1 -> 0 | G38: =IF(Inputs!$B$35>=G$1,Inputs!$B$34,0)*(1+inf)^F$1 -> 0 | H38: =IF(Inputs!$B$35>=H$1,Inputs!$B$34,0)*(1+inf)^G$1 -> 0 | I38: =IF(Inputs!$B$35>=I$1,Inputs!$B$34,0)*(1+inf)^H$1 -> 0 | J38: =IF(Inputs!$B$35>=J$1,Inputs!$B$34,0)*(1+inf)^I$1 -> 0 | K38: =IF(Inputs!$B$35>=K$1,Inputs!$B$34,0)*(1+inf)^J$1 -> 0 | ... AM38: =IF(Inputs!$B$35>=AM$1,Inputs!$B$34,0)*(1+inf)^AL$1 -> 0
A39: =TEXT(Inputs!B38,"") -> Jack | C39: =IF(Inputs!$B$40>=C$1,Inputs!$B$39,0)*(1+inf)^B$1*ProRate -> 833.33333 | D39: =IF(Inputs!$B$40>=D$1,Inputs!$B$39,0)*(1+inf)^C$1 -> 1025 | E39: =IF(Inputs!$B$40>=E$1,Inputs!$B$39,0)*(1+inf)^D$1 -> 1050.625 | F39: =IF(Inputs!$B$40>=F$1,Inputs!$B$39,0)*(1+inf)^E$1 -> 1076.8906 | G39: =IF(Inputs!$B$40>=G$1,Inputs!$B$39,0)*(1+inf)^F$1 -> 1103.8129 | H39: =IF(Inputs!$B$40>=H$1,Inputs!$B$39,0)*(1+inf)^G$1 -> 0 | I39: =IF(Inputs!$B$40>=I$1,Inputs!$B$39,0)*(1+inf)^H$1 -> 0 | J39: =IF(Inputs!$B$40>=J$1,Inputs!$B$39,0)*(1+inf)^I$1 -> 0 | K39: =IF(Inputs!$B$40>=K$1,Inputs!$B$39,0)*(1+inf)^J$1 -> 0 | ... AM39: =IF(Inputs!$B$40>=AM$1,Inputs!$B$39,0)*(1+inf)^AL$1 -> 0
A40: =TEXT(Inputs!B43,"") -> Bill | C40: =IF(Inputs!$B$45>=C$1,Inputs!$B$44,0)*(1+inf)^B$1*ProRate -> 3333.3333 | D40: =IF(Inputs!$B$45>=D$1,Inputs!$B$44,0)*(1+inf)^C$1 -> 4100 | E40: =IF(Inputs!$B$45>=E$1,Inputs!$B$44,0)*(1+inf)^D$1 -> 0 | F40: =IF(Inputs!$B$45>=F$1,Inputs!$B$44,0)*(1+inf)^E$1 -> 0 | G40: =IF(Inputs!$B$45>=G$1,Inputs!$B$44,0)*(1+inf)^F$1 -> 0 | H40: =IF(Inputs!$B$45>=H$1,Inputs!$B$44,0)*(1+inf)^G$1 -> 0 | I40: =IF(Inputs!$B$45>=I$1,Inputs!$B$44,0)*(1+inf)^H$1 -> 0 | J40: =IF(Inputs!$B$45>=J$1,Inputs!$B$44,0)*(1+inf)^I$1 -> 0 | K40: =IF(Inputs!$B$45>=K$1,Inputs!$B$44,0)*(1+inf)^J$1 -> 0 | ... AM40: =IF(Inputs!$B$45>=AM$1,Inputs!$B$44,0)*(1+inf)^AL$1 -> 0
...
