Workbook
Name A1inc: Inputs!$B$89
Name A2inc: Inputs!$B$94
Name A3inc: Inputs!$B$99
Name A4inc: Inputs!$B$104
Name A5inc: Inputs!$B$109
Name AgeRange: RetNorm_Engine!$C$3:INDEX(RetNorm_Engine!$C$3:$XFD$3, COUNTA(RetNorm_Engine!$C$3:$XFD$3))
Name AssVar: Inputs!$A$307:$C$316
Name buffer: Inputs!$B$279
Name ChartCash_Early: RetEarly_Engine!$C$381:INDEX(RetEarly_Engine!$C$381:$XFD$381, COUNTA(RetEarly_Engine!$C$381:$XFD$381))
Name ChartCash_Norm: RetNorm_Engine!$C$381:INDEX(RetNorm_Engine!$C$381:$XFD$381, COUNTA(RetNorm_Engine!$C$381:$XFD$381))
Name ChartNW_Early: RetEarly_Engine!$C$382:INDEX(RetEarly_Engine!$C$382:$XFD$382, COUNTA(RetEarly_Engine!$C$382:$XFD$382))
Name ChartNW_Norm: RetNorm_Engine!$C$382:INDEX(RetNorm_Engine!$C$382:$XFD$382, COUNTA(RetNorm_Engine!$C$382:$XFD$382))
Name DCoth: Inputs!$B$287
Name DCprop: Inputs!$B$285
Name EndAge: Inputs!$B$254
Name inf: Inputs!$B$265
Name legacy: Inputs!$B$281
Name MthOff: Inputs!$B$303
Name MthRem: Inputs!$B$302
Name princ: Inputs!$B$267
Name ProRate: Inputs!$B$304
Name RetAge: Inputs!$B$19
Name rinc: Inputs!$B$275
Name sincr: Inputs!$B$273
Name stinc: Inputs!$B$271

Sheet Inputs
B1: User inputs | D1: User Tooltips | E1: UI Notes | F1: Excel helpers
A2: QUICK START
A4: Your age | B4: 48 | D4: Must be entered
A6: Current net annual income | B6: 80000 | D6: Net of tax, from employment or self-employment
A8: Total cash balances | B8: 50000 | D8: current and savings accounts, bonds, term deposits
A10: Stock market investments | B10: 30000 | D10: Current market value of equity portfolio
A12: Home current market value | B12: 500000 | D12: Leave blank if not a home owner
A14: Home loan (mortgage)
A15: Balance | B15: 50000 | D15: Leave blank if no mortgage | F15: Months remaining | G15: =IFERROR(NPER(B16/12,-B17,B15),"") -> 215.86799
A16: Interest rate | B16: 0.03 | F16: Years remaining | G16: =IFERROR(G15/12,"") -> 17.988999
A17: Monthly repayment | B17: 300
A19: Statutory retirement age | B19: 65 | D19: Year at which pension starts
A21: Annual pension at retirement | B21: 16000 | D21: Net annual state pension entitlement
A23: Home monthly rent | D23: if not a home owner | E23: show only if not a home owner (B12="")
A25: Annual living expenses | B25: 50000
A28: DEEPER DIVE | E28: Activated only if user wants to
A30: Dependents
A32: Dependent 1
A33: Name | B33: John | D33: Leave blank if none
A34: Annual cost | B34: 2000 | D34: Food, education, healthcare, etc. | E34: Hide until user enters dependent name
A35: Years to support | B35: 3 | D35: Years from now | E35: Hide until user enters dependent name
A37: Dependent 2
A38: Name | B38: Jack | D38: Leave blank if none
A39: Annual cost | B39: 1000 | D39: Food, education, healthcare, etc. | E39: Hide until user enters dependent name
A40: Years to support | B40: 5 | D40: Years from now | E40: Hide until user enters dependent name
A42: Dependent 3
A43: Name | B43: Bill | D43: Leave blank if none
A44: Annual cost | B44: 4000 | D44: Food, education, healthcare, etc. | E44: Hide until user enters dependent name
A45: Years to support | B45: 2 | D45: Years from now | E45: Hide until user enters dependent name
A47: Dependent 4
A48: Name | B48: Stephen | D48: Leave blank if none
A49: Annual cost | B49: 2500 | D49: Food, education, healthcare, etc. | E49: Hide until user enters dependent name
A50: Years to support | B50: 3 | D50: Years from now | E50: Hide until user enters dependent name
A52: Dependent 5
A53: Name | B53: Jane | D53: Leave blank if none
A54: Annual cost | B54: 2860 | D54: Food, education, healthcare, etc. | E54: Hide until user enters dependent name
A55: Years to support | B55: 6 | D55: Years from now | E55: Hide until user enters dependent name
A57: Investment Properties
A59: Property 1
A60: Name | B60: Sliema | D60: Leave blank if none
...

Sheet Output
V2: Retire at | AA2: ="Retire at "&RetEarly_Engine!B3 -> Retire at 49
V3: =RetEarly_Engine!B3 -> 49 | AA3: ="Retire at "&RetAge -> Retire at 65

Sheet RetNorm_Engine
B1: 0 | C1: 1 | D1: =C1+1 -> 2 | E1: =D1+1 -> 3 | F1: =E1+1 -> 4 | G1: =F1+1 -> 5 | H1: =G1+1 -> 6 | I1: =H1+1 -> 7 | J1: =I1+1 -> 8 | K1: =J1+1 -> 9 | ... AM1: =AL1+1 -> 37
B2: Year | C2: =YEAR(TODAY()) -> 2026 | D2: =C2+1 -> 2027 | E2: =D2+1 -> 2028 | F2: =E2+1 -> 2029 | G2: =F2+1 -> 2030 | H2: =G2+1 -> 2031 | I2: =H2+1 -> 2032 | J2: =I2+1 -> 2033 | K2: =J2+1 -> 2034 | ... AM2: =AL2+1 -> 2062
B3: =Inputs!B19 -> 65 | C3: =Inputs!B4 -> 48 | D3: =C3+1 -> 49 | E3: =D3+1 -> 50 | F3: =E3+1 -> 51 | G3: =F3+1 -> 52 | H3: =G3+1 -> 53 | I3: =H3+1 -> 54 | J3: =I3+1 -> 55 | K3: =J3+1 -> 56 | ... AM3: =AL3+1 -> 84
A4: Inflows
A5: Net employment / self-employment income | C5: =IF(AND(Inputs!$B$19>C3,$B$3>C3),Inputs!$B$6*(1+sincr)^B1,0)*ProRate -> 60000 | D5: =IF(AND(Inputs!$B$19>D3,$B$3>D3),Inputs!$B$6*(1+sincr)^C1,0) -> 82400 | E5: =IF(AND(Inputs!$B$19>E3,$B$3>E3),Inputs!$B$6*(1+sincr)^D1,0) -> 84872 | F5: =IF(AND(Inputs!$B$19>F3,$B$3>F3),Inputs!$B$6*(1+sincr)^E1,0) -> 87418.16 | G5: =IF(AND(Inputs!$B$19>G3,$B$3>G3),Inputs!$B$6*(1+sincr)^F1,0) -> 90040.705 | H5: =IF(AND(Inputs!$B$19>H3,$B$3>H3),Inputs!$B$6*(1+sincr)^G1,0) -> 92741.926 | I5: =IF(AND(Inputs!$B$19>I3,$B$3>I3),Inputs!$B$6*(1+sincr)^H1,0) -> 95524.184 | J5: =IF(AND(Inputs!$B$19>J3,$B$3>J3),Inputs!$B$6*(1+sincr)^I1,0) -> 98389.909 | K5: =IF(AND(Inputs!$B$19>K3,$B$3>K3),Inputs!$B$6*(1+sincr)^J1,0) -> 101341.61 | ... AM5: =IF(AND(Inputs!$B$19>AM3,$B$3>AM3),Inputs!$B$6*(1+sincr)^AL1,0) -> 0
A6: Net from other work | C6: =IF(C$3<=Inputs!$B$120,Inputs!$B$119,0)*(1+inf)^B$1*ProRate -> 1500 | D6: =IF(D$3<=Inputs!$B$120,Inputs!$B$119,0)*(1+inf)^C$1 -> 2050 | E6: =IF(E$3<=Inputs!$B$120,Inputs!$B$119,0)*(1+inf)^D$1 -> 2101.25 | F6: =IF(F$3<=Inputs!$B$120,Inputs!$B$119,0)*(1+inf)^E$1 -> 2153.7812 | G6: =IF(G$3<=Inputs!$B$120,Inputs!$B$119,0)*(1+inf)^F$1 -> 2207.6258 | H6: =IF(H$3<=Inputs!$B$120,Inputs!$B$119,0)*(1+inf)^G$1 -> 2262.8164 | I6: =IF(I$3<=Inputs!$B$120,Inputs!$B$119,0)*(1+inf)^H$1 -> 2319.3868 | J6: =IF(J$3<=Inputs!$B$120,Inputs!$B$119,0)*(1+inf)^I$1 -> 2377.3715 | K6: =IF(K$3<=Inputs!$B$120,Inputs!$B$119,0)*(1+inf)^J$1 -> 2436.8058 | ... AM6: =IF(AM$3<=Inputs!$B$120,Inputs!$B$119,0)*(1+inf)^AL$1 -> 0
A7: Net rental income from other properties
A8: =TEXT(Inputs!$B$60,"") -> Sliema | C8: =Inputs!B113*ProRate -> 9000 | D8: =C8*(1+rinc) -> 9270 | E8: =D8*(1+rinc) -> 9548.1 | F8: =E8*(1+rinc) -> 9834.543 | G8: =F8*(1+rinc) -> 10129.579 | H8: =G8*(1+rinc) -> 10433.467 | I8: =H8*(1+rinc) -> 10746.471 | J8: =I8*(1+rinc) -> 11068.865 | K8: =J8*(1+rinc) -> 11400.931 | ... AM8: =AL8*(1+rinc) -> 26084.505
A9: =TEXT(Inputs!$B$65,"") -> Gzira | C9: =Inputs!B114*ProRate -> 7500 | D9: =C9*(1+rinc) -> 7725 | E9: =D9*(1+rinc) -> 7956.75 | F9: =E9*(1+rinc) -> 8195.4525 | G9: =F9*(1+rinc) -> 8441.3161 | H9: =G9*(1+rinc) -> 8694.5556 | I9: =H9*(1+rinc) -> 8955.3922 | J9: =I9*(1+rinc) -> 9224.054 | K9: =J9*(1+rinc) -> 9500.7756 | ... AM9: =AL9*(1+rinc) -> 21737.087
A10: =TEXT(Inputs!$B$70,"") -> Qormi | C10: =Inputs!B115*ProRate -> 6000 | D10: =C10*(1+rinc) -> 6180 | E10: =D10*(1+rinc) -> 6365.4 | F10: =E10*(1+rinc) -> 6556.362 | G10: =F10*(1+rinc) -> 6753.0529 | H10: =G10*(1+rinc) -> 6955.6444 | I10: =H10*(1+rinc) -> 7164.3138 | J10: =I10*(1+rinc) -> 7379.2432 | K10: =J10*(1+rinc) -> 7600.6205 | ... AM10: =AL10*(1+rinc) -> 17389.67
A11: =TEXT(Inputs!$B$75,"") -> Gudja | C11: =Inputs!B116*ProRate -> 3750 | D11: =C11*(1+rinc) -> 3862.5 | E11: =D11*(1+rinc) -> 3978.375 | F11: =E11*(1+rinc) -> 4097.7262 | G11: =F11*(1+rinc) -> 4220.658 | H11: =G11*(1+rinc) -> 4347.2778 | I11: =H11*(1+rinc) -> 4477.6961 | J11: =I11*(1+rinc) -> 4612.027 | K11: =J11*(1+rinc) -> 4750.3878 | ... AM11: =AL11*(1+rinc) -> 10868.544
A12: =TEXT(Inputs!$B$80,"") -> Marsa | C12: =Inputs!B117*ProRate -> 4875 | D12: =C12*(1+rinc) -> 5021.25 | E12: =D12*(1+rinc) -> 5171.8875 | F12: =E12*(1+rinc) -> 5327.0441 | G12: =F12*(1+rinc) -> 5486.8554 | H12: =G12*(1+rinc) -> 5651.4611 | I12: =H12*(1+rinc) -> 5821.0049 | J12: =I12*(1+rinc) -> 5995.6351 | K12: =J12*(1+rinc) -> 6175.5041 | ... AM12: =AL12*(1+rinc) -> 14129.107
A13: Full pension | C13: =IF(C$3<Inputs!$B$19,0,Inputs!$B$21)*(1+inf)^B$1*ProRate -> 0 | D13: =IF(D$3<Inputs!$B$19,0,Inputs!$B$21)*(1+inf)^C$1 -> 0 | E13: =IF(E$3<Inputs!$B$19,0,Inputs!$B$21)*(1+inf)^D$1 -> 0 | F13: =IF(F$3<Inputs!$B$19,0,Inputs!$B$21)*(1+inf)^E$1 -> 0 | G13: =IF(G$3<Inputs!$B$19,0,Inputs!$B$21)*(1+inf)^F$1 -> 0 | H13: =IF(H$3<Inputs!$B$19,0,Inputs!$B$21)*(1+inf)^G$1 -> 0 | I13: =IF(I$3<Inputs!$B$19,0,Inputs!$B$21)*(1+inf)^H$1 -> 0 | J13: =IF(J$3<Inputs!$B$19,0,Inputs!$B$21)*(1+inf)^I$1 -> 0 | K13: =IF(K$3<Inputs!$B$19,0,Inputs!$B$21)*(1+inf)^J$1 -> 0 | ... AM13: =IF(AM$3<Inputs!$B$19,0,Inputs!$B$21)*(1+inf)^AL$1 -> 38920.565
A14: Pension reduction from early retirement | C14: =MIN(0,MAX(-IF(C13=0,0,(Inputs!$B$19-INDEX(3:3,MATCH(0,5:5,0))))*Inputs!$B$277*(1+inf)^B$1*ProRate,-C13)) -> 0 | D14: =MIN(0,MAX(-IF(D13=0,0,(Inputs!$B$19-INDEX(3:3,MATCH(0,5:5,0))))*Inputs!$B$277*(1+inf)^C$1,-D13)) -> 0 | E14: =MIN(0,MAX(-IF(E13=0,0,(Inputs!$B$19-INDEX(3:3,MATCH(0,5:5,0))))*Inputs!$B$277*(1+inf)^D$1,-E13)) -> 0 | F14: =MIN(0,MAX(-IF(F13=0,0,(Inputs!$B$19-INDEX(3:3,MATCH(0,5:5,0))))*Inputs!$B$277*(1+inf)^E$1,-F13)) -> 0 | G14: =MIN(0,MAX(-IF(G13=0,0,(Inputs!$B$19-INDEX(3:3,MATCH(0,5:5,0))))*Inputs!$B$277*(1+inf)^F$1,-G13)) -> 0 | H14: =MIN(0,MAX(-IF(H13=0,0,(Inputs!$B$19-INDEX(3:3,MATCH(0,5:5,0))))*Inputs!$B$277*(1+inf)^G$1,-H13)) -> 0 | I14: =MIN(0,MAX(-IF(I13=0,0,(Inputs!$B$19-INDEX(3:3,MATCH(0,5:5,0))))*Inputs!$B$277*(1+inf)^H$1,-I13)) -> 0 | J14: =MIN(0,MAX(-IF(J13=0,0,(Inputs!$B$19-INDEX(3:3,MATCH(0,5:5,0))))*Inputs!$B$277*(1+inf)^I$1,-J13)) -> 0 | K14: =MIN(0,MAX(-IF(K13=0,0,(Inputs!$B$19-INDEX(3:3,MATCH(0,5:5,0))))*Inputs!$B$277*(1+inf)^J$1,-K13)) -> 0 | ... AM14: =MIN(0,MAX(-IF(AM13=0,0,(Inputs!$B$19-INDEX(3:3,MATCH(0,5:5,0))))*Inputs!$B$277*(1+inf)^AL$1,-AM13)) -> 0
A15: Other post-retirement income | C15: =IF(AND(C$3>=Inputs!$B$262,C$3<=Inputs!$B$263),Inputs!$B$261*(1+inf)^B$1,0)*ProRate -> 0 | D15: =IF(AND(D$3>=Inputs!$B$262,D$3<=Inputs!$B$263),Inputs!$B$261*(1+inf)^C$1,0) -> 0 | E15: =IF(AND(E$3>=Inputs!$B$262,E$3<=Inputs!$B$263),Inputs!$B$261*(1+inf)^D$1,0) -> 0 | F15: =IF(AND(F$3>=Inputs!$B$262,F$3<=Inputs!$B$263),Inputs!$B$261*(1+inf)^E$1,0) -> 0 | G15: =IF(AND(G$3>=Inputs!$B$262,G$3<=Inputs!$B$263),Inputs!$B$261*(1+inf)^F$1,0) -> 0 | H15: =IF(AND(H$3>=Inputs!$B$262,H$3<=Inputs!$B$263),Inputs!$B$261*(1+inf)^G$1,0) -> 0 | I15: =IF(AND(I$3>=Inputs!$B$262,I$3<=Inputs!$B$263),Inputs!$B$261*(1+inf)^H$1,0) -> 0 | J15: =IF(AND(J$3>=Inputs!$B$262,J$3<=Inputs!$B$263),Inputs!$B$261*(1+inf)^I$1,0) -> 0 | K15: =IF(AND(K$3>=Inputs!$B$262,K$3<=Inputs!$B$263),Inputs!$B$261*(1+inf)^J$1,0) -> 0 | ... AM15: =IF(AND(AM$3>=Inputs!$B$262,AM$3<=Inputs!$B$263),Inputs!$B$261*(1+inf)^AL$1,0) -> 0
A16: Major one-off income events
A17: =TEXT(Inputs!B184,"") -> Inheritance | C17: =IF(C$2=Inputs!$B186,Inputs!$B185,0)*(1+inf)^B$1 -> 0 | D17: =IF(D$2=Inputs!$B186,Inputs!$B185,0)*(1+inf)^C$1 -> 0 | E17: =IF(E$2=Inputs!$B186,Inputs!$B185,0)*(1+inf)^D$1 -> 0 | F17: =IF(F$2=Inputs!$B186,Inputs!$B185,0)*(1+inf)^E$1 -> 0 | G17: =IF(G$2=Inputs!$B186,Inputs!$B185,0)*(1+inf)^F$1 -> 0 | H17: =IF(H$2=Inputs!$B186,Inputs!$B185,0)*(1+inf)^G$1 -> 0 | I17: =IF(I$2=Inputs!$B186,Inputs!$B185,0)*(1+inf)^H$1 -> 0 | J17: =IF(J$2=Inputs!$B186,Inputs!$B185,0)*(1+inf)^I$1 -> 0 | ... AM17: =IF(AM$2=Inputs!$B186,Inputs!$B185,0)*(1+inf)^AL$1 -> 0
A18: =TEXT(Inputs!B189,"") -> Sell Painting | C18: =IF(C$2=Inputs!$B191,Inputs!$B190,0)*(1+inf)^B$1 -> 0 | D18: =IF(D$2=Inputs!$B191,Inputs!$B190,0)*(1+inf)^C$1 -> 0 | E18: =IF(E$2=Inputs!$B191,Inputs!$B190,0)*(1+inf)^D$1 -> 0 | F18: =IF(F$2=Inputs!$B191,Inputs!$B190,0)*(1+inf)^E$1 -> 10768.906 | G18: =IF(G$2=Inputs!$B191,Inputs!$B190,0)*(1+inf)^F$1 -> 0 | H18: =IF(H$2=Inputs!$B191,Inputs!$B190,0)*(1+inf)^G$1 -> 0 | I18: =IF(I$2=Inputs!$B191,Inputs!$B190,0)*(1+inf)^H$1 -> 0 | J18: =IF(J$2=Inputs!$B191,Inputs!$B190,0)*(1+inf)^I$1 -> 0 | ... AM18: =IF(AM$2=Inputs!$B191,Inputs!$B190,0)*(1+inf)^AL$1 -> 0
A19: =TEXT(Inputs!B194,"") -> Sell Jewels | C19: =IF(C$2=Inputs!$B196,Inputs!$B195,0)*(1+inf)^B$1 -> 0 | D19: =IF(D$2=Inputs!$B196,Inputs!$B195,0)*(1+inf)^C$1 -> 0 | E19: =IF(E$2=Inputs!$B196,Inputs!$B195,0)*(1+inf)^D$1 -> 0 | F19: =IF(F$2=Inputs!$B196,Inputs!$B195,0)*(1+inf)^E$1 -> 0 | G19: =IF(G$2=Inputs!$B196,Inputs!$B195,0)*(1+inf)^F$1 -> 0 | H19: =IF(H$2=Inputs!$B196,Inputs!$B195,0)*(1+inf)^G$1 -> 0 | I19: =IF(I$2=Inputs!$B196,Inputs!$B195,0)*(1+inf)^H$1 -> 5798.4671 | J19: =IF(J$2=Inputs!$B196,Inputs!$B195,0)*(1+inf)^I$1 -> 0 | ... AM19: =IF(AM$2=Inputs!$B196,Inputs!$B195,0)*(1+inf)^AL$1 -> 0
A20: Sale of home (downsizing) | C20: =IF(AND(Inputs!$B$217<>"",C$2=Inputs!$B$217,Inputs!$B$12>0),(IF(B$1=0,Inputs!$B$12*(1+princ)^ProRate,B69*(1+princ)))*(1-DCprop),0) -> 0 | D20: =IF(AND(Inputs!$B$217<>"",D$2=Inputs!$B$217,Inputs!$B$12>0),(IF(C$1=0,Inputs!$B$12*(1+princ)^ProRate,C69*(1+princ)))*(1-DCprop),0) -> 0 | E20: =IF(AND(Inputs!$B$217<>"",E$2=Inputs!$B$217,Inputs!$B$12>0),(IF(D$1=0,Inputs!$B$12*(1+princ)^ProRate,D69*(1+princ)))*(1-DCprop),0) -> 0 | F20: =IF(AND(Inputs!$B$217<>"",F$2=Inputs!$B$217,Inputs!$B$12>0),(IF(E$1=0,Inputs!$B$12*(1+princ)^ProRate,E69*(1+princ)))*(1-DCprop),0) -> 0 | G20: =IF(AND(Inputs!$B$217<>"",G$2=Inputs!$B$217,Inputs!$B$12>0),(IF(F$1=0,Inputs!$B$12*(1+princ)^ProRate,F69*(1+princ)))*(1-DCprop),0) -> 489064.06 | H20: =IF(AND(Inputs!$B$217<>"",H$2=Inputs!$B$217,Inputs!$B$12>0),(IF(G$1=0,Inputs!$B$12*(1+princ)^ProRate,G69*(1+princ)))*(1-DCprop),0) -> 0 | I20: =IF(AND(Inputs!$B$217<>"",I$2=Inputs!$B$217,Inputs!$B$12>0),(IF(H$1=0,Inputs!$B$12*(1+princ)^ProRate,H69*(1+princ)))*(1-DCprop),0) -> 0 | J20: =IF(AND(Inputs!$B$217<>"",J$2=Inputs!$B$217,Inputs!$B$12>0),(IF(I$1=0,Inputs!$B$12*(1+princ)^ProRate,I69*(1+princ)))*(1-DCprop),0) -> 0 | ... AM20: =IF(AND(Inputs!$B$217<>"",AM$2=Inputs!$B$217,Inputs!$B$12>0),(IF(AL$1=0,Inputs!$B$12*(1+princ)^ProRate,AL69*(1+princ)))*(1-DCprop),0) -> 0
A21: Interest on cash balances | C21: =MAX(AVERAGE(C64,C64+SUM(C5:C20)-C61)*Inputs!$B$269,0) -> 1433.4375 | D21: =MAX(AVERAGE(D64,D64+SUM(D5:D20)-D61)*Inputs!$B$269,0) -> 1803.9578 | E21: =MAX(AVERAGE(E64,E64+SUM(E5:E20)-E61)*Inputs!$B$269,0) -> 2224.4666 | F21: =MAX(AVERAGE(F64,F64+SUM(F5:F20)-F61)*Inputs!$B$269,0) -> 2498.7337 | G21: =MAX(AVERAGE(G64,G64+SUM(G5:G20)-G61)*Inputs!$B$269,0) -> 4971.3944 | H21: =MAX(AVERAGE(H64,H64+SUM(H5:H20)-H61)*Inputs!$B$269,0) -> 7993.1111 | I21: =MAX(AVERAGE(I64,I64+SUM(I5:I20)-I61)*Inputs!$B$269,0) -> 9391.8702 | J21: =MAX(AVERAGE(J64,J64+SUM(J5:J20)-J61)*Inputs!$B$269,0) -> 11096.575 | ... AM21: =MAX(AVERAGE(AM64,AM64+SUM(AM5:AM20)-AM61)*Inputs!$B$269,0) -> 61628.564
C22: =SUM(C4:C21) -> 94058.438 | D22: =SUM(D4:D21) -> 118312.71 | E22: =SUM(E4:E21) -> 122218.23 | F22: =SUM(F4:F21) -> 136850.71 | G22: =SUM(G4:G21) -> 621315.25 | H22: =SUM(H4:H21) -> 139080.26 | I22: =SUM(I4:I21) -> 150198.79 | J22: =SUM(J4:J21) -> 150143.68 | ... AM22: =SUM(AM4:AM21) -> 190758.04
A23: Outflows
A24: Credit cards cleared | C24: =Inputs!B124 -> 1000 | D24: 0 | E24: 0 | F24: 0 | G24: 0 | H24: 0 | I24: 0 | J24: 0 | K24: 0 | L24: 0 | M24: 0 | N24: 0 | O24: 0 | P24: 0 | Q24: 0 | R24: 0 | S24: 0 | T24: 0 | U24: 0 | V24: 0 | W24: 0 | X24: 0 | Y24: 0 | Z24: 0 | AA24: 0 | AB24: 0 | AC24: 0 | AD24: 0 | AE24: 0 | AF24: 0 | AG24: 0 | AH24: 0 | AI24: 0 | AJ24: 0 | AK24: 0 | AL24: 0 | AM24: 0
A25: Home loan repayment | C25: =IF(AND(Inputs!$B$217<>"",C$2=Inputs!$B$217,Inputs!$B$12>0,Inputs!$B$15>0),MIN(IF(B$1=0,MthRem,12),MAX(Inputs!$G$15-IF(B$1=0,0,B$1*12+MthOff),0))*Inputs!$B$17+MAX(FV(Inputs!$B$16/12,C$1*12+MthOff,Inputs!$B$17,-Inputs!$B$15),0),IF(AND(Inputs!$B$217<>"",C$2>Inputs!$B$217,Inputs!$B$12>0),0,MIN(IF(B$1=0,MthRem,12),MAX(Inputs!$G$15-IF(B$1=0,0,B$1*12+MthOff),0))*Inputs!$B$17)) -> 2700 | D25: =IF(AND(Inputs!$B$217<>"",D$2=Inputs!$B$217,Inputs!$B$12>0,Inputs!$B$15>0),MIN(IF(C$1=0,MthRem,12),MAX(Inputs!$G$15-IF(C$1=0,0,C$1*12+MthOff),0))*Inputs!$B$17+MAX(FV(Inputs!$B$16/12,D$1*12+MthOff,Inputs!$B$17,-Inputs!$B$15),0),IF(AND(Inputs!$B$217<>"",D$2>Inputs!$B$217,Inputs!$B$12>0),0,MIN(IF(C$1=0,MthRem,12),MAX(Inputs!$G$15-IF(C$1=0,0,C$1*12+MthOff),0))*Inputs!$B$17)) -> 3600 | E25: =IF(AND(Inputs!$B$217<>"",E$2=Inputs!$B$217,Inputs!$B$12>0,Inputs!$B$15>0),MIN(IF(D$1=0,MthRem,12),MAX(Inputs!$G$15-IF(D$1=0,0,D$1*12+MthOff),0))*Inputs!$B$17+MAX(FV(Inputs!$B$16/12,E$1*12+MthOff,Inputs!$B$17,-Inputs!$B$15),0),IF(AND(Inputs!$B$217<>"",E$2>Inputs!$B$217,Inputs!$B$12>0),0,MIN(IF(D$1=0,MthRem,12),MAX(Inputs!$G$15-IF(D$1=0,0,D$1*12+MthOff),0))*Inputs!$B$17)) -> 3600 | F25: =IF(AND(Inputs!$B$217<>"",F$2=Inputs!$B$217,Inputs!$B$12>0,Inputs!$B$15>0),MIN(IF(E$1=0,MthRem,12),MAX(Inputs!$G$15-IF(E$1=0,0,E$1*12+MthOff),0))*Inputs!$B$17+MAX(FV(Inputs!$B$16/12,F$1*12+MthOff,Inputs!$B$17,-Inputs!$B$15),0),IF(AND(Inputs!$B$217<>"",F$2>Inputs!$B$217,Inputs!$B$12>0),0,MIN(IF(E$1=0,MthRem,12),MAX(Inputs!$G$15-IF(E$1=0,0,E$1*12+MthOff),0))*Inputs!$B$17)) -> 3600 | G25: =IF(AND(Inputs!$B$217<>"",G$2=Inputs!$B$217,Inputs!$B$12>0,Inputs!$B$15>0),MIN(IF(F$1=0,MthRem,12),MAX(Inputs!$G$15-IF(F$1=0,0,F$1*12+MthOff),0))*Inputs!$B$17+MAX(FV(Inputs!$B$16/12,G$1*12+MthOff,Inputs!$B$17,-Inputs!$B$15),0),IF(AND(Inputs!$B$217<>"",G$2>Inputs!$B$217,Inputs!$B$12>0),0,MIN(IF(F$1=0,MthRem,12),MAX(Inputs!$G$15-IF(F$1=0,0,F$1*12+MthOff),0))*Inputs!$B$17)) -> 42893.638 | H25: =IF(AND(Inputs!$B$217<>"",H$2=Inputs!$B$217,Inputs!$B$12>0,Inputs!$B$15>0),MIN(IF(G$1=0,MthRem,12),MAX(Inputs!$G$15-IF(G$1=0,0,G$1*12+MthOff),0))*Inputs!$B$17+MAX(FV(Inputs!$B$16/12,H$1*12+MthOff,Inputs!$B$17,-Inputs!$B$15),0),IF(AND(Inputs!$B$217<>"",H$2>Inputs!$B$217,Inputs!$B$12>0),0,MIN(IF(G$1=0,MthRem,12),MAX(Inputs!$G$15-IF(G$1=0,0,G$1*12+MthOff),0))*Inputs!$B$17)) -> 0 | I25: =IF(AND(Inputs!$B$217<>"",I$2=Inputs!$B$217,Inputs!$B$12>0,Inputs!$B$15>0),MIN(IF(H$1=0,MthRem,12),MAX(Inputs!$G$15-IF(H$1=0,0,H$1*12+MthOff),0))*Inputs!$B$17+MAX(FV(Inputs!$B$16/12,I$1*12+MthOff,Inputs!$B$17,-Inputs!$B$15),0),IF(AND(Inputs!$B$217<>"",I$2>Inputs!$B$217,Inputs!$B$12>0),0,MIN(IF(H$1=0,MthRem,12),MAX(Inputs!$G$15-IF(H$1=0,0,H$1*12+MthOff),0))*Inputs!$B$17)) -> 0 | J25: =IF(AND(Inputs!$B$217<>"",J$2=Inputs!$B$217,Inputs!$B$12>0,Inputs!$B$15>0),MIN(IF(I$1=0,MthRem,12),MAX(Inputs!$G$15-IF(I$1=0,0,I$1*12+MthOff),0))*Inputs!$B$17+MAX(FV(Inputs!$B$16/12,J$1*12+MthOff,Inputs!$B$17,-Inputs!$B$15),0),IF(AND(Inputs!$B$217<>"",J$2>Inputs!$B$217,Inputs!$B$12>0),0,MIN(IF(I$1=0,MthRem,12),MAX(Inputs!$G$15-IF(I$1=0,0,I$1*12+MthOff),0))*Inputs!$B$17)) -> 0 | ... AM25: =IF(AND(Inputs!$B$217<>"",AM$2=Inputs!$B$217,Inputs!$B$12>0,Inputs!$B$15>0),MIN(IF(AL$1=0,MthRem,12),MAX(Inputs!$G$15-IF(AL$1=0,0,AL$1*12+MthOff),0))*Inputs!$B$17+MAX(FV(Inputs!$B$16/12,AM$1*12+MthOff,Inputs!$B$17,-Inputs!$B$15),0),IF(AND(Inputs!$B$217<>"",AM$2>Inputs!$B$217,Inputs!$B$12>0),0,MIN(IF(AL$1=0,MthRem,12),MAX(Inputs!$G$15-IF(AL$1=0,0,AL$1*12+MthOff),0))*Inputs!$B$17)) -> 0
A26: Other asset loans repayments
A27: =TEXT(Inputs!$B$60,"") -> Sliema | C27: =MIN(IF(B$1=0,MthRem,12), MAX(Inputs!$G$127-IF(B$1=0,0,B$1*12+MthOff), 0))*Inputs!$B$129 -> 4500 | D27: =MIN(IF(C$1=0,MthRem,12), MAX(Inputs!$G$127-IF(C$1=0,0,C$1*12+MthOff), 0))*Inputs!$B$129 -> 6000 | E27: =MIN(IF(D$1=0,MthRem,12), MAX(Inputs!$G$127-IF(D$1=0,0,D$1*12+MthOff), 0))*Inputs!$B$129 -> 6000 | F27: =MIN(IF(E$1=0,MthRem,12), MAX(Inputs!$G$127-IF(E$1=0,0,E$1*12+MthOff), 0))*Inputs!$B$129 -> 6000 | G27: =MIN(IF(F$1=0,MthRem,12), MAX(Inputs!$G$127-IF(F$1=0,0,F$1*12+MthOff), 0))*Inputs!$B$129 -> 6000 | H27: =MIN(IF(G$1=0,MthRem,12), MAX(Inputs!$G$127-IF(G$1=0,0,G$1*12+MthOff), 0))*Inputs!$B$129 -> 6000 | I27: =MIN(IF(H$1=0,MthRem,12), MAX(Inputs!$G$127-IF(H$1=0,0,H$1*12+MthOff), 0))*Inputs!$B$129 -> 6000 | J27: =MIN(IF(I$1=0,MthRem,12), MAX(Inputs!$G$127-IF(I$1=0,0,I$1*12+MthOff), 0))*Inputs!$B$129 -> 6000 | ... AM27: =MIN(IF(AL$1=0,MthRem,12), MAX(Inputs!$G$127-IF(AL$1=0,0,AL$1*12+MthOff), 0))*Inputs!$B$129 -> 0
A28: =TEXT(Inputs!$B$65,"") -> Gzira | C28: =MIN(IF(B$1=0,MthRem,12), MAX(Inputs!$G$132-IF(B$1=0,0,B$1*12+MthOff), 0))*Inputs!$B$134 -> 1800 | D28: =MIN(IF(C$1=0,MthRem,12), MAX(Inputs!$G$132-IF(C$1=0,0,C$1*12+MthOff), 0))*Inputs!$B$134 -> 2400 | E28: =MIN(IF(D$1=0,MthRem,12), MAX(Inputs!$G$132-IF(D$1=0,0,D$1*12+MthOff), 0))*Inputs!$B$134 -> 2400 | F28: =MIN(IF(E$1=0,MthRem,12), MAX(Inputs!$G$132-IF(E$1=0,0,E$1*12+MthOff), 0))*Inputs!$B$134 -> 2223.4029 | G28: =MIN(IF(F$1=0,MthRem,12), MAX(Inputs!$G$132-IF(F$1=0,0,F$1*12+MthOff), 0))*Inputs!$B$134 -> 0 | H28: =MIN(IF(G$1=0,MthRem,12), MAX(Inputs!$G$132-IF(G$1=0,0,G$1*12+MthOff), 0))*Inputs!$B$134 -> 0 | I28: =MIN(IF(H$1=0,MthRem,12), MAX(Inputs!$G$132-IF(H$1=0,0,H$1*12+MthOff), 0))*Inputs!$B$134 -> 0 | J28: =MIN(IF(I$1=0,MthRem,12), MAX(Inputs!$G$132-IF(I$1=0,0,I$1*12+MthOff), 0))*Inputs!$B$134 -> 0 | ... AM28: =MIN(IF(AL$1=0,MthRem,12), MAX(Inputs!$G$132-IF(AL$1=0,0,AL$1*12+MthOff), 0))*Inputs!$B$134 -> 0
A29: =TEXT(Inputs!$B$70,"") -> Qormi | C29: =MIN(IF(B$1=0,MthRem,12), MAX(Inputs!$G$137-IF(B$1=0,0,B$1*12+MthOff), 0))*Inputs!$B$139 -> 2250 | D29: =MIN(IF(C$1=0,MthRem,12), MAX(Inputs!$G$137-IF(C$1=0,0,C$1*12+MthOff), 0))*Inputs!$B$139 -> 3000 | E29: =MIN(IF(D$1=0,MthRem,12), MAX(Inputs!$G$137-IF(D$1=0,0,D$1*12+MthOff), 0))*Inputs!$B$139 -> 3000 | F29: =MIN(IF(E$1=0,MthRem,12), MAX(Inputs!$G$137-IF(E$1=0,0,E$1*12+MthOff), 0))*Inputs!$B$139 -> 3000 | G29: =MIN(IF(F$1=0,MthRem,12), MAX(Inputs!$G$137-IF(F$1=0,0,F$1*12+MthOff), 0))*Inputs!$B$139 -> 3000 | H29: =MIN(IF(G$1=0,MthRem,12), MAX(Inputs!$G$137-IF(G$1=0,0,G$1*12+MthOff), 0))*Inputs!$B$139 -> 3000 | I29: =MIN(IF(H$1=0,MthRem,12), MAX(Inputs!$G$137-IF(H$1=0,0,H$1*12+MthOff), 0))*Inputs!$B$139 -> 46.859686 | J29: =MIN(IF(I$1=0,MthRem,12), MAX(Inputs!$G$137-IF(I$1=0,0,I$1*12+MthOff), 0))*Inputs!$B$139 -> 0 | ... AM29: =MIN(IF(AL$1=0,MthRem,12), MAX(Inputs!$G$137-IF(AL$1=0,0,AL$1*12+MthOff), 0))*Inputs!$B$139 -> 0
A30: =TEXT(Inputs!$B$75,"") -> Gudja | C30: =MIN(IF(B$1=0,MthRem,12), MAX(Inputs!$G$142-IF(B$1=0,0,B$1*12+MthOff), 0))*Inputs!$B$144 -> 720 | D30: =MIN(IF(C$1=0,MthRem,12), MAX(Inputs!$G$142-IF(C$1=0,0,C$1*12+MthOff), 0))*Inputs!$B$144 -> 960 | E30: =MIN(IF(D$1=0,MthRem,12), MAX(Inputs!$G$142-IF(D$1=0,0,D$1*12+MthOff), 0))*Inputs!$B$144 -> 960 | F30: =MIN(IF(E$1=0,MthRem,12), MAX(Inputs!$G$142-IF(E$1=0,0,E$1*12+MthOff), 0))*Inputs!$B$144 -> 960 | G30: =MIN(IF(F$1=0,MthRem,12), MAX(Inputs!$G$142-IF(F$1=0,0,F$1*12+MthOff), 0))*Inputs!$B$144 -> 960 | H30: =MIN(IF(G$1=0,MthRem,12), MAX(Inputs!$G$142-IF(G$1=0,0,G$1*12+MthOff), 0))*Inputs!$B$144 -> 368.25859 | I30: =MIN(IF(H$1=0,MthRem,12), MAX(Inputs!$G$142-IF(H$1=0,0,H$1*12+MthOff), 0))*Inputs!$B$144 -> 0 | J30: =MIN(IF(I$1=0,MthRem,12), MAX(Inputs!$G$142-IF(I$1=0,0,I$1*12+MthOff), 0))*Inputs!$B$144 -> 0 | ... AM30: =MIN(IF(AL$1=0,MthRem,12), MAX(Inputs!$G$142-IF(AL$1=0,0,AL$1*12+MthOff), 0))*Inputs!$B$144 -> 0
A31: =TEXT(Inputs!$B$80,"") -> Marsa | C31: =MIN(IF(B$1=0,MthRem,12), MAX(Inputs!$G$147-IF(B$1=0,0,B$1*12+MthOff), 0))*Inputs!$B$149 -> 1080 | D31: =MIN(IF(C$1=0,MthRem,12), MAX(Inputs!$G$147-IF(C$1=0,0,C$1*12+MthOff), 0))*Inputs!$B$149 -> 1440 | E31: =MIN(IF(D$1=0,MthRem,12), MAX(Inputs!$G$147-IF(D$1=0,0,D$1*12+MthOff), 0))*Inputs!$B$149 -> 1440 | F31: =MIN(IF(E$1=0,MthRem,12), MAX(Inputs!$G$147-IF(E$1=0,0,E$1*12+MthOff), 0))*Inputs!$B$149 -> 1440 | G31: =MIN(IF(F$1=0,MthRem,12), MAX(Inputs!$G$147-IF(F$1=0,0,F$1*12+MthOff), 0))*Inputs!$B$149 -> 1440 | H31: =MIN(IF(G$1=0,MthRem,12), MAX(Inputs!$G$147-IF(G$1=0,0,G$1*12+MthOff), 0))*Inputs!$B$149 -> 1440 | I31: =MIN(IF(H$1=0,MthRem,12), MAX(Inputs!$G$147-IF(H$1=0,0,H$1*12+MthOff), 0))*Inputs!$B$149 -> 1440 | J31: =MIN(IF(I$1=0,MthRem,12), MAX(Inputs!$G$147-IF(I$1=0,0,I$1*12+MthOff), 0))*Inputs!$B$149 -> 909.24881 | ... AM31: =MIN(IF(AL$1=0,MthRem,12), MAX(Inputs!$G$147-IF(AL$1=0,0,AL$1*12+MthOff), 0))*Inputs!$B$149 -> 0
A32: =TEXT(Inputs!$B$87,"") -> Jewelry | C32: =MIN(IF(B$1=0,MthRem,12), MAX(Inputs!$G$152-IF(B$1=0,0,B$1*12+MthOff), 0))*Inputs!$B$154 -> 675 | D32: =MIN(IF(C$1=0,MthRem,12), MAX(Inputs!$G$152-IF(C$1=0,0,C$1*12+MthOff), 0))*Inputs!$B$154 -> 900 | E32: =MIN(IF(D$1=0,MthRem,12), MAX(Inputs!$G$152-IF(D$1=0,0,D$1*12+MthOff), 0))*Inputs!$B$154 -> 900 | F32: =MIN(IF(E$1=0,MthRem,12), MAX(Inputs!$G$152-IF(E$1=0,0,E$1*12+MthOff), 0))*Inputs!$B$154 -> 138.60288 | G32: =MIN(IF(F$1=0,MthRem,12), MAX(Inputs!$G$152-IF(F$1=0,0,F$1*12+MthOff), 0))*Inputs!$B$154 -> 0 | H32: =MIN(IF(G$1=0,MthRem,12), MAX(Inputs!$G$152-IF(G$1=0,0,G$1*12+MthOff), 0))*Inputs!$B$154 -> 0 | I32: =MIN(IF(H$1=0,MthRem,12), MAX(Inputs!$G$152-IF(H$1=0,0,H$1*12+MthOff), 0))*Inputs!$B$154 -> 0 | J32: =MIN(IF(I$1=0,MthRem,12), MAX(Inputs!$G$152-IF(I$1=0,0,I$1*12+MthOff), 0))*Inputs!$B$154 -> 0 | ... AM32: =MIN(IF(AL$1=0,MthRem,12), MAX(Inputs!$G$152-IF(AL$1=0,0,AL$1*12+MthOff), 0))*Inputs!$B$154 -> 0
A33: =TEXT(Inputs!$B$92,"") -> Car | C33: =MIN(IF(B$1=0,MthRem,12), MAX(Inputs!$G$157-IF(B$1=0,0,B$1*12+MthOff), 0))*Inputs!$B$159 -> 774 | D33: =MIN(IF(C$1=0,MthRem,12), MAX(Inputs!$G$157-IF(C$1=0,0,C$1*12+MthOff), 0))*Inputs!$B$159 -> 1032 | E33: =MIN(IF(D$1=0,MthRem,12), MAX(Inputs!$G$157-IF(D$1=0,0,D$1*12+MthOff), 0))*Inputs!$B$159 -> 1032 | F33: =MIN(IF(E$1=0,MthRem,12), MAX(Inputs!$G$157-IF(E$1=0,0,E$1*12+MthOff), 0))*Inputs!$B$159 -> 1032 | G33: =MIN(IF(F$1=0,MthRem,12), MAX(Inputs!$G$157-IF(F$1=0,0,F$1*12+MthOff), 0))*Inputs!$B$159 -> 1032 | H33: =MIN(IF(G$1=0,MthRem,12), MAX(Inputs!$G$157-IF(G$1=0,0,G$1*12+MthOff), 0))*Inputs!$B$159 -> 1032 | I33: =MIN(IF(H$1=0,MthRem,12), MAX(Inputs!$G$157-IF(H$1=0,0,H$1*12+MthOff), 0))*Inputs!$B$159 -> 449.79405 | J33: =MIN(IF(I$1=0,MthRem,12), MAX(Inputs!$G$157-IF(I$1=0,0,I$1*12+MthOff), 0))*Inputs!$B$159 -> 0 | ... AM33: =MIN(IF(AL$1=0,MthRem,12), MAX(Inputs!$G$157-IF(AL$1=0,0,AL$1*12+MthOff), 0))*Inputs!$B$159 -> 0
A34: =TEXT(Inputs!$B$97,"") -> Painting | C34: =MIN(IF(B$1=0,MthRem,12), MAX(Inputs!$G$162-IF(B$1=0,0,B$1*12+MthOff), 0))*Inputs!$B$164 -> 1125 | D34: =MIN(IF(C$1=0,MthRem,12), MAX(Inputs!$G$162-IF(C$1=0,0,C$1*12+MthOff), 0))*Inputs!$B$164 -> 1500 | E34: =MIN(IF(D$1=0,MthRem,12), MAX(Inputs!$G$162-IF(D$1=0,0,D$1*12+MthOff), 0))*Inputs!$B$164 -> 1500 | F34: =MIN(IF(E$1=0,MthRem,12), MAX(Inputs!$G$162-IF(E$1=0,0,E$1*12+MthOff), 0))*Inputs!$B$164 -> 1500 | G34: =MIN(IF(F$1=0,MthRem,12), MAX(Inputs!$G$162-IF(F$1=0,0,F$1*12+MthOff), 0))*Inputs!$B$164 -> 1500 | H34: =MIN(IF(G$1=0,MthRem,12), MAX(Inputs!$G$162-IF(G$1=0,0,G$1*12+MthOff), 0))*Inputs!$B$164 -> 1500 | I34: =MIN(IF(H$1=0,MthRem,12), MAX(Inputs!$G$162-IF(H$1=0,0,H$1*12+MthOff), 0))*Inputs!$B$164 -> 23.429843 | J34: =MIN(IF(I$1=0,MthRem,12), MAX(Inputs!$G$162-IF(I$1=0,0,I$1*12+MthOff), 0))*Inputs!$B$164 -> 0 | ... AM34: =MIN(IF(AL$1=0,MthRem,12), MAX(Inputs!$G$162-IF(AL$1=0,0,AL$1*12+MthOff), 0))*Inputs!$B$164 -> 0
A35: =TEXT(Inputs!$B$102,"") -> Boat | C35: =MIN(IF(B$1=0,MthRem,12), MAX(Inputs!$G$167-IF(B$1=0,0,B$1*12+MthOff), 0))*Inputs!$B$169 -> 5616 | D35: =MIN(IF(C$1=0,MthRem,12), MAX(Inputs!$G$167-IF(C$1=0,0,C$1*12+MthOff), 0))*Inputs!$B$169 -> 7488 | E35: =MIN(IF(D$1=0,MthRem,12), MAX(Inputs!$G$167-IF(D$1=0,0,D$1*12+MthOff), 0))*Inputs!$B$169 -> 7488 | F35: =MIN(IF(E$1=0,MthRem,12), MAX(Inputs!$G$167-IF(E$1=0,0,E$1*12+MthOff), 0))*Inputs!$B$169 -> 7488 | G35: =MIN(IF(F$1=0,MthRem,12), MAX(Inputs!$G$167-IF(F$1=0,0,F$1*12+MthOff), 0))*Inputs!$B$169 -> 7488 | H35: =MIN(IF(G$1=0,MthRem,12), MAX(Inputs!$G$167-IF(G$1=0,0,G$1*12+MthOff), 0))*Inputs!$B$169 -> 7488 | I35: =MIN(IF(H$1=0,MthRem,12), MAX(Inputs!$G$167-IF(H$1=0,0,H$1*12+MthOff), 0))*Inputs!$B$169 -> 5289.2926 | J35: =MIN(IF(I$1=0,MthRem,12), MAX(Inputs!$G$167-IF(I$1=0,0,I$1*12+MthOff), 0))*Inputs!$B$169 -> 0 | ... AM35: =MIN(IF(AL$1=0,MthRem,12), MAX(Inputs!$G$167-IF(AL$1=0,0,AL$1*12+MthOff), 0))*Inputs!$B$169 -> 0
A36: =TEXT(Inputs!$B$107,"") -> Antiques | C36: =MIN(IF(B$1=0,MthRem,12), MAX(Inputs!$G$172-IF(B$1=0,0,B$1*12+MthOff), 0))*Inputs!$B$174 -> 990 | D36: =MIN(IF(C$1=0,MthRem,12), MAX(Inputs!$G$172-IF(C$1=0,0,C$1*12+MthOff), 0))*Inputs!$B$174 -> 1320 | E36: =MIN(IF(D$1=0,MthRem,12), MAX(Inputs!$G$172-IF(D$1=0,0,D$1*12+MthOff), 0))*Inputs!$B$174 -> 1320 | F36: =MIN(IF(E$1=0,MthRem,12), MAX(Inputs!$G$172-IF(E$1=0,0,E$1*12+MthOff), 0))*Inputs!$B$174 -> 349.16176 | G36: =MIN(IF(F$1=0,MthRem,12), MAX(Inputs!$G$172-IF(F$1=0,0,F$1*12+MthOff), 0))*Inputs!$B$174 -> 0 | H36: =MIN(IF(G$1=0,MthRem,12), MAX(Inputs!$G$172-IF(G$1=0,0,G$1*12+MthOff), 0))*Inputs!$B$174 -> 0 | I36: =MIN(IF(H$1=0,MthRem,12), MAX(Inputs!$G$172-IF(H$1=0,0,H$1*12+MthOff), 0))*Inputs!$B$174 -> 0 | J36: =MIN(IF(I$1=0,MthRem,12), MAX(Inputs!$G$172-IF(I$1=0,0,I$1*12+MthOff), 0))*Inputs!$B$174 -> 0 | ... AM36: =MIN(IF(AL$1=0,MthRem,12), MAX(Inputs!$G$172-IF(AL$1=0,0,AL$1*12+MthOff), 0))*Inputs!$B$174 -> 0
A37: Other loan repayment | C37: =MIN(IF(B$1=0,MthRem,12), MAX(Inputs!$G$177-IF(B$1=0,0,B$1*12+MthOff), 0))*Inputs!$B$179 -> 450 | D37: =MIN(IF(C$1=0,MthRem,12), MAX(Inputs!$G$177-IF(C$1=0,0,C$1*12+MthOff), 0))*Inputs!$B$179 -> 600 | E37: =MIN(IF(D$1=0,MthRem,12), MAX(Inputs!$G$177-IF(D$1=0,0,D$1*12+MthOff), 0))*Inputs!$B$179 -> 600 | F37: =MIN(IF(E$1=0,MthRem,12), MAX(Inputs!$G$177-IF(E$1=0,0,E$1*12+MthOff), 0))*Inputs!$B$179 -> 600 | G37: =MIN(IF(F$1=0,MthRem,12), MAX(Inputs!$G$177-IF(F$1=0,0,F$1*12+MthOff), 0))*Inputs!$B$179 -> 600 | H37: =MIN(IF(G$1=0,MthRem,12), MAX(Inputs!$G$177-IF(G$1=0,0,G$1*12+MthOff), 0))*Inputs!$B$179 -> 600 | I37: =MIN(IF(H$1=0,MthRem,12), MAX(Inputs!$G$177-IF(H$1=0,0,H$1*12+MthOff), 0))*Inputs!$B$179 -> 600 | J37: =MIN(IF(I$1=0,MthRem,12), MAX(Inputs!$G$177-IF(I$1=0,0,I$1*12+MthOff), 0))*Inputs!$B$179 -> 600 | ... AM37: =MIN(IF(AL$1=0,MthRem,12), MAX(Inputs!$G$177-IF(AL$1=0,0,AL$1*12+MthOff), 0))*Inputs!$B$179 -> 0
A38: Dependents cost
A39: =TEXT(Inputs!B33,"") -> John | C39: =IF(Inputs!$B$35>=C$1,Inputs!$B$34,0)*(1+inf)^B$1*ProRate -> 1500 | D39: =IF(Inputs!$B$35>=D$1,Inputs!$B$34,0)*(1+inf)^C$1 -> 2050 | E39: =IF(Inputs!$B$35>=E$1,Inputs!$B$34,0)*(1+inf)^D$1 -> 2101.25 | F39: =IF(Inputs!$B$35>=F$1,Inputs!$B$34,0)*(1+inf)^E$1 -> 0 | G39: =IF(Inputs!$B$35>=G$1,Inputs!$B$34,0)*(1+inf)^F$1 -> 0 | H39: =IF(Inputs!$B$35>=H$1,Inputs!$B$34,0)*(1+inf)^G$1 -> 0 | I39: =IF(Inputs!$B$35>=I$1,Inputs!$B$34,0)*(1+inf)^H$1 -> 0 | J39: =IF(Inputs!$B$35>=J$1,Inputs!$B$34,0)*(1+inf)^I$1 -> 0 | K39: =IF(Inputs!$B$35>=K$1,Inputs!$B$34,0)*(1+inf)^J$1 -> 0 | ... AM39: =IF(Inputs!$B$35>=AM$1,Inputs!$B$34,0)*(1+inf)^AL$1 -> 0
A40: =TEXT(Inputs!B38,"") -> Jack | C40: =IF(Inputs!$B$40>=C$1,Inputs!$B$39,0)*(1+inf)^B$1*ProRate -> 750 | D40: =IF(Inputs!$B$40>=D$1,Inputs!$B$39,0)*(1+inf)^C$1 -> 1025 | E40: =IF(Inputs!$B$40>=E$1,Inputs!$B$39,0)*(1+inf)^D$1 -> 1050.625 | F40: =IF(Inputs!$B$40>=F$1,Inputs!$B$39,0)*(1+inf)^E$1 -> 1076.8906 | G40: =IF(Inputs!$B$40>=G$1,Inputs!$B$39,0)*(1+inf)^F$1 -> 1103.8129 | H40: =IF(Inputs!$B$40>=H$1,Inputs!$B$39,0)*(1+inf)^G$1 -> 0 | I40: =IF(Inputs!$B$40>=I$1,Inputs!$B$39,0)*(1+inf)^H$1 -> 0 | J40: =IF(Inputs!$B$40>=J$1,Inputs!$B$39,0)*(1+inf)^I$1 -> 0 | K40: =IF(Inputs!$B$40>=K$1,Inputs!$B$39,0)*(1+inf)^J$1 -> 0 | ... AM40: =IF(Inputs!$B$40>=AM$1,Inputs!$B$39,0)*(1+inf)^AL$1 -> 0
...

Sheet RetEarly_Engine
B1: 0 | C1: 1 | D1: =C1+1 -> 2 | E1: =D1+1 -> 3 | F1: =E1+1 -> 4 | G1: =F1+1 -> 5 | H1: =G1+1 -> 6 | I1: =H1+1 -> 7 | J1: =I1+1 -> 8 | K1: =J1+1 -> 9 | ... AM1: =AL1+1 -> 37
B2: Year | C2: =YEAR(TODAY()) -> 2026 | D2: =C2+1 -> 2027 | E2: =D2+1 -> 2028 | F2: =E2+1 -> 2029 | G2: =F2+1 -> 2030 | H2: =G2+1 -> 2031 | I2: =H2+1 -> 2032 | J2: =I2+1 -> 2033 | K2: =J2+1 -> 2034 | ... AM2: =AL2+1 -> 2062
B3: 49 | C3: =Inputs!B4 -> 48 | D3: =C3+1 -> 49 | E3: =D3+1 -> 50 | F3: =E3+1 -> 51 | G3: =F3+1 -> 52 | H3: =G3+1 -> 53 | I3: =H3+1 -> 54 | J3: =I3+1 -> 55 | K3: =J3+1 -> 56 | ... AM3: =AL3+1 -> 84
A4: Inflows
A5: Net employment / self-employment income | C5: =IF(AND(Inputs!$B$19>C3,$B$3>C3),Inputs!$B$6*(1+sincr)^B1,0)*ProRate -> 60000 | D5: =IF(AND(Inputs!$B$19>D3,$B$3>D3),Inputs!$B$6*(1+sincr)^C1,0) -> 0 | E5: =IF(AND(Inputs!$B$19>E3,$B$3>E3),Inputs!$B$6*(1+sincr)^D1,0) -> 0 | F5: =IF(AND(Inputs!$B$19>F3,$B$3>F3),Inputs!$B$6*(1+sincr)^E1,0) -> 0 | G5: =IF(AND(Inputs!$B$19>G3,$B$3>G3),Inputs!$B$6*(1+sincr)^F1,0) -> 0 | H5: =IF(AND(Inputs!$B$19>H3,$B$3>H3),Inputs!$B$6*(1+sincr)^G1,0) -> 0 | I5: =IF(AND(Inputs!$B$19>I3,$B$3>I3),Inputs!$B$6*(1+sincr)^H1,0) -> 0 | J5: =IF(AND(Inputs!$B$19>J3,$B$3>J3),Inputs!$B$6*(1+sincr)^I1,0) -> 0 | K5: =IF(AND(Inputs!$B$19>K3,$B$3>K3),Inputs!$B$6*(1+sincr)^J1,0) -> 0 | ... AM5: =IF(AND(Inputs!$B$19>AM3,$B$3>AM3),Inputs!$B$6*(1+sincr)^AL1,0) -> 0
A6: Net from other work | C6: =IF(C$3<=Inputs!$B$120,Inputs!$B$119,0)*(1+inf)^B$1*ProRate -> 1500 | D6: =IF(D$3<=Inputs!$B$120,Inputs!$B$119,0)*(1+inf)^C$1 -> 2050 | E6: =IF(E$3<=Inputs!$B$120,Inputs!$B$119,0)*(1+inf)^D$1 -> 2101.25 | F6: =IF(F$3<=Inputs!$B$120,Inputs!$B$119,0)*(1+inf)^E$1 -> 2153.7812 | G6: =IF(G$3<=Inputs!$B$120,Inputs!$B$119,0)*(1+inf)^F$1 -> 2207.6258 | H6: =IF(H$3<=Inputs!$B$120,Inputs!$B$119,0)*(1+inf)^G$1 -> 2262.8164 | I6: =IF(I$3<=Inputs!$B$120,Inputs!$B$119,0)*(1+inf)^H$1 -> 2319.3868 | J6: =IF(J$3<=Inputs!$B$120,Inputs!$B$119,0)*(1+inf)^I$1 -> 2377.3715 | K6: =IF(K$3<=Inputs!$B$120,Inputs!$B$119,0)*(1+inf)^J$1 -> 2436.8058 | ... AM6: =IF(AM$3<=Inputs!$B$120,Inputs!$B$119,0)*(1+inf)^AL$1 -> 0
A7: Net rental income from other properties
A8: =TEXT(Inputs!$B$60,"") -> Sliema | C8: =Inputs!B113*ProRate -> 9000 | D8: =C8*(1+rinc) -> 9270 | E8: =D8*(1+rinc) -> 9548.1 | F8: =E8*(1+rinc) -> 9834.543 | G8: =F8*(1+rinc) -> 10129.579 | H8: =G8*(1+rinc) -> 10433.467 | I8: =H8*(1+rinc) -> 10746.471 | J8: =I8*(1+rinc) -> 11068.865 | K8: =J8*(1+rinc) -> 11400.931 | ... AM8: =AL8*(1+rinc) -> 26084.505
A9: =TEXT(Inputs!$B$65,"") -> Gzira | C9: =Inputs!B114*ProRate -> 7500 | D9: =C9*(1+rinc) -> 7725 | E9: =D9*(1+rinc) -> 7956.75 | F9: =E9*(1+rinc) -> 8195.4525 | G9: =F9*(1+rinc) -> 8441.3161 | H9: =G9*(1+rinc) -> 8694.5556 | I9: =H9*(1+rinc) -> 8955.3922 | J9: =I9*(1+rinc) -> 9224.054 | K9: =J9*(1+rinc) -> 9500.7756 | ... AM9: =AL9*(1+rinc) -> 21737.087
A10: =TEXT(Inputs!$B$70,"") -> Qormi | C10: =Inputs!B115*ProRate -> 6000 | D10: =C10*(1+rinc) -> 6180 | E10: =D10*(1+rinc) -> 6365.4 | F10: =E10*(1+rinc) -> 6556.362 | G10: =F10*(1+rinc) -> 6753.0529 | H10: =G10*(1+rinc) -> 6955.6444 | I10: =H10*(1+rinc) -> 7164.3138 | J10: =I10*(1+rinc) -> 7379.2432 | K10: =J10*(1+rinc) -> 7600.6205 | ... AM10: =AL10*(1+rinc) -> 17389.67
A11: =TEXT(Inputs!$B$75,"") -> Gudja | C11: =Inputs!B116*ProRate -> 3750 | D11: =C11*(1+rinc) -> 3862.5 | E11: =D11*(1+rinc) -> 3978.375 | F11: =E11*(1+rinc) -> 4097.7262 | G11: =F11*(1+rinc) -> 4220.658 | H11: =G11*(1+rinc) -> 4347.2778 | I11: =H11*(1+rinc) -> 4477.6961 | J11: =I11*(1+rinc) -> 4612.027 | K11: =J11*(1+rinc) -> 4750.3878 | ... AM11: =AL11*(1+rinc) -> 10868.544
A12: =TEXT(Inputs!$B$80,"") -> Marsa | C12: =Inputs!B117*ProRate -> 4875 | D12: =C12*(1+rinc) -> 5021.25 | E12: =D12*(1+rinc) -> 5171.8875 | F12: =E12*(1+rinc) -> 5327.0441 | G12: =F12*(1+rinc) -> 5486.8554 | H12: =G12*(1+rinc) -> 5651.4611 | I12: =H12*(1+rinc) -> 5821.0049 | J12: =I12*(1+rinc) -> 5995.6351 | K12: =J12*(1+rinc) -> 6175.5041 | ... AM12: =AL12*(1+rinc) -> 14129.107
A13: Full pension | C13: =IF(C$3<Inputs!$B$19,0,Inputs!$B$21)*(1+inf)^B$1*ProRate -> 0 | D13: =IF(D$3<Inputs!$B$19,0,Inputs!$B$21)*(1+inf)^C$1 -> 0 | E13: =IF(E$3<Inputs!$B$19,0,Inputs!$B$21)*(1+inf)^D$1 -> 0 | F13: =IF(F$3<Inputs!$B$19,0,Inputs!$B$21)*(1+inf)^E$1 -> 0 | G13: =IF(G$3<Inputs!$B$19,0,Inputs!$B$21)*(1+inf)^F$1 -> 0 | H13: =IF(H$3<Inputs!$B$19,0,Inputs!$B$21)*(1+inf)^G$1 -> 0 | I13: =IF(I$3<Inputs!$B$19,0,Inputs!$B$21)*(1+inf)^H$1 -> 0 | J13: =IF(J$3<Inputs!$B$19,0,Inputs!$B$21)*(1+inf)^I$1 -> 0 | K13: =IF(K$3<Inputs!$B$19,0,Inputs!$B$21)*(1+inf)^J$1 -> 0 | ... AM13: =IF(AM$3<Inputs!$B$19,0,Inputs!$B$21)*(1+inf)^AL$1 -> 38920.565
A14: Pension reduction from early retirement | C14: =MIN(0,MAX(-IF(C13=0,0,(Inputs!$B$19-INDEX(3:3,MATCH(0,5:5,0))))*Inputs!$B$277*(1+inf)^B$1*ProRate,-C13)) -> 0 | D14: =MIN(0,MAX(-IF(D13=0,0,(Inputs!$B$19-INDEX(3:3,MATCH(0,5:5,0))))*Inputs!$B$277*(1+inf)^C$1,-D13)) -> 0 | E14: =MIN(0,MAX(-IF(E13=0,0,(Inputs!$B$19-INDEX(3:3,MATCH(0,5:5,0))))*Inputs!$B$277*(1+inf)^D$1,-E13)) -> 0 | F14: =MIN(0,MAX(-IF(F13=0,0,(Inputs!$B$19-INDEX(3:3,MATCH(0,5:5,0))))*Inputs!$B$277*(1+inf)^E$1,-F13)) -> 0 | G14: =MIN(0,MAX(-IF(G13=0,0,(Inputs!$B$19-INDEX(3:3,MATCH(0,5:5,0))))*Inputs!$B$277*(1+inf)^F$1,-G13)) -> 0 | H14: =MIN(0,MAX(-IF(H13=0,0,(Inputs!$B$19-INDEX(3:3,MATCH(0,5:5,0))))*Inputs!$B$277*(1+inf)^G$1,-H13)) -> 0 | I14: =MIN(0,MAX(-IF(I13=0,0,(Inputs!$B$19-INDEX(3:3,MATCH(0,5:5,0))))*Inputs!$B$277*(1+inf)^H$1,-I13)) -> 0 | J14: =MIN(0,MAX(-IF(J13=0,0,(Inputs!$B$19-INDEX(3:3,MATCH(0,5:5,0))))*Inputs!$B$277*(1+inf)^I$1,-J13)) -> 0 | K14: =MIN(0,MAX(-IF(K13=0,0,(Inputs!$B$19-INDEX(3:3,MATCH(0,5:5,0))))*Inputs!$B$277*(1+inf)^J$1,-K13)) -> 0 | ... AM14: =MIN(0,MAX(-IF(AM13=0,0,(Inputs!$B$19-INDEX(3:3,MATCH(0,5:5,0))))*Inputs!$B$277*(1+inf)^AL$1,-AM13)) -> -11676.17
A15: Other post-retirement income | C15: =IF(AND(C$3>=Inputs!$B$262,C$3<=Inputs!$B$263),Inputs!$B$261*(1+inf)^B$1,0)*ProRate -> 0 | D15: =IF(AND(D$3>=Inputs!$B$262,D$3<=Inputs!$B$263),Inputs!$B$261*(1+inf)^C$1,0) -> 0 | E15: =IF(AND(E$3>=Inputs!$B$262,E$3<=Inputs!$B$263),Inputs!$B$261*(1+inf)^D$1,0) -> 0 | F15: =IF(AND(F$3>=Inputs!$B$262,F$3<=Inputs!$B$263),Inputs!$B$261*(1+inf)^E$1,0) -> 0 | G15: =IF(AND(G$3>=Inputs!$B$262,G$3<=Inputs!$B$263),Inputs!$B$261*(1+inf)^F$1,0) -> 0 | H15: =IF(AND(H$3>=Inputs!$B$262,H$3<=Inputs!$B$263),Inputs!$B$261*(1+inf)^G$1,0) -> 0 | I15: =IF(AND(I$3>=Inputs!$B$262,I$3<=Inputs!$B$263),Inputs!$B$261*(1+inf)^H$1,0) -> 0 | J15: =IF(AND(J$3>=Inputs!$B$262,J$3<=Inputs!$B$263),Inputs!$B$261*(1+inf)^I$1,0) -> 0 | K15: =IF(AND(K$3>=Inputs!$B$262,K$3<=Inputs!$B$263),Inputs!$B$261*(1+inf)^J$1,0) -> 0 | ... AM15: =IF(AND(AM$3>=Inputs!$B$262,AM$3<=Inputs!$B$263),Inputs!$B$261*(1+inf)^AL$1,0) -> 0
A16: Major one-off income events
A17: =TEXT(Inputs!B184,"") -> Inheritance | C17: =IF(C$2=Inputs!$B186,Inputs!$B185,0)*(1+inf)^B$1 -> 0 | D17: =IF(D$2=Inputs!$B186,Inputs!$B185,0)*(1+inf)^C$1 -> 0 | E17: =IF(E$2=Inputs!$B186,Inputs!$B185,0)*(1+inf)^D$1 -> 0 | F17: =IF(F$2=Inputs!$B186,Inputs!$B185,0)*(1+inf)^E$1 -> 0 | G17: =IF(G$2=Inputs!$B186,Inputs!$B185,0)*(1+inf)^F$1 -> 0 | H17: =IF(H$2=Inputs!$B186,Inputs!$B185,0)*(1+inf)^G$1 -> 0 | I17: =IF(I$2=Inputs!$B186,Inputs!$B185,0)*(1+inf)^H$1 -> 0 | J17: =IF(J$2=Inputs!$B186,Inputs!$B185,0)*(1+inf)^I$1 -> 0 | ... AM17: =IF(AM$2=Inputs!$B186,Inputs!$B185,0)*(1+inf)^AL$1 -> 0
A18: =TEXT(Inputs!B189,"") -> Sell Painting | C18: =IF(C$2=Inputs!$B191,Inputs!$B190,0)*(1+inf)^B$1 -> 0 | D18: =IF(D$2=Inputs!$B191,Inputs!$B190,0)*(1+inf)^C$1 -> 0 | E18: =IF(E$2=Inputs!$B191,Inputs!$B190,0)*(1+inf)^D$1 -> 0 | F18: =IF(F$2=Inputs!$B191,Inputs!$B190,0)*(1+inf)^E$1 -> 10768.906 | G18: =IF(G$2=Inputs!$B191,Inputs!$B190,0)*(1+inf)^F$1 -> 0 | H18: =IF(H$2=Inputs!$B191,Inputs!$B190,0)*(1+inf)^G$1 -> 0 | I18: =IF(I$2=Inputs!$B191,Inputs!$B190,0)*(1+inf)^H$1 -> 0 | J18: =IF(J$2=Inputs!$B191,Inputs!$B190,0)*(1+inf)^I$1 -> 0 | ... AM18: =IF(AM$2=Inputs!$B191,Inputs!$B190,0)*(1+inf)^AL$1 -> 0
A19: =TEXT(Inputs!B194,"") -> Sell Jewels | C19: =IF(C$2=Inputs!$B196,Inputs!$B195,0)*(1+inf)^B$1 -> 0 | D19: =IF(D$2=Inputs!$B196,Inputs!$B195,0)*(1+inf)^C$1 -> 0 | E19: =IF(E$2=Inputs!$B196,Inputs!$B195,0)*(1+inf)^D$1 -> 0 | F19: =IF(F$2=Inputs!$B196,Inputs!$B195,0)*(1+inf)^E$1 -> 0 | G19: =IF(G$2=Inputs!$B196,Inputs!$B195,0)*(1+inf)^F$1 -> 0 | H19: =IF(H$2=Inputs!$B196,Inputs!$B195,0)*(1+inf)^G$1 -> 0 | I19: =IF(I$2=Inputs!$B196,Inputs!$B195,0)*(1+inf)^H$1 -> 5798.4671 | J19: =IF(J$2=Inputs!$B196,Inputs!$B195,0)*(1+inf)^I$1 -> 0 | ... AM19: =IF(AM$2=Inputs!$B196,Inputs!$B195,0)*(1+inf)^AL$1 -> 0
A20: Sale of home (downsizing) | C20: =IF(AND(Inputs!$B$217<>"",C$2=Inputs!$B$217,Inputs!$B$12>0),(IF(B$1=0,Inputs!$B$12*(1+princ)^ProRate,B69*(1+princ)))*(1-DCprop),0) -> 0 | D20: =IF(AND(Inputs!$B$217<>"",D$2=Inputs!$B$217,Inputs!$B$12>0),(IF(C$1=0,Inputs!$B$12*(1+princ)^ProRate,C69*(1+princ)))*(1-DCprop),0) -> 0 | E20: =IF(AND(Inputs!$B$217<>"",E$2=Inputs!$B$217,Inputs!$B$12>0),(IF(D$1=0,Inputs!$B$12*(1+princ)^ProRate,D69*(1+princ)))*(1-DCprop),0) -> 0 | F20: =IF(AND(Inputs!$B$217<>"",F$2=Inputs!$B$217,Inputs!$B$12>0),(IF(E$1=0,Inputs!$B$12*(1+princ)^ProRate,E69*(1+princ)))*(1-DCprop),0) -> 0 | G20: =IF(AND(Inputs!$B$217<>"",G$2=Inputs!$B$217,Inputs!$B$12>0),(IF(F$1=0,Inputs!$B$12*(1+princ)^ProRate,F69*(1+princ)))*(1-DCprop),0) -> 489064.06 | H20: =IF(AND(Inputs!$B$217<>"",H$2=Inputs!$B$217,Inputs!$B$12>0),(IF(G$1=0,Inputs!$B$12*(1+princ)^ProRate,G69*(1+princ)))*(1-DCprop),0) -> 0 | I20: =IF(AND(Inputs!$B$217<>"",I$2=Inputs!$B$217,Inputs!$B$12>0),(IF(H$1=0,Inputs!$B$12*(1+princ)^ProRate,H69*(1+princ)))*(1-DCprop),0) -> 0 | J20: =IF(AND(Inputs!$B$217<>"",J$2=Inputs!$B$217,Inputs!$B$12>0),(IF(I$1=0,Inputs!$B$12*(1+princ)^ProRate,I69*(1+princ)))*(1-DCprop),0) -> 0 | ... AM20: =IF(AND(Inputs!$B$217<>"",AM$2=Inputs!$B$217,Inputs!$B$12>0),(IF(AL$1=0,Inputs!$B$12*(1+princ)^ProRate,AL69*(1+princ)))*(1-DCprop),0) -> 0
A21: Interest on cash balances | C21: =MAX(AVERAGE(C64,C64+SUM(C5:C20)-C61)*Inputs!$B$269,0) -> 1433.4375 | D21: =MAX(AVERAGE(D64,D64+SUM(D5:D20)-D61)*Inputs!$B$269,0) -> 773.95781 | E21: =MAX(AVERAGE(E64,E64+SUM(E5:E20)-E61)*Inputs!$B$269,0) -> 0 | F21: =MAX(AVERAGE(F64,F64+SUM(F5:F20)-F61)*Inputs!$B$269,0) -> 0 | G21: =MAX(AVERAGE(G64,G64+SUM(G5:G20)-G61)*Inputs!$B$269,0) -> 0 | H21: =MAX(AVERAGE(H64,H64+SUM(H5:H20)-H61)*Inputs!$B$269,0) -> 0 | I21: =MAX(AVERAGE(I64,I64+SUM(I5:I20)-I61)*Inputs!$B$269,0) -> 0 | J21: =MAX(AVERAGE(J64,J64+SUM(J5:J20)-J61)*Inputs!$B$269,0) -> 0 | ... AM21: =MAX(AVERAGE(AM64,AM64+SUM(AM5:AM20)-AM61)*Inputs!$B$269,0) -> 0
C22: =SUM(C4:C21) -> 94058.438 | D22: =SUM(D4:D21) -> 34882.708 | E22: =SUM(E4:E21) -> 35121.762 | F22: =SUM(F4:F21) -> 46933.815 | G22: =SUM(G4:G21) -> 526303.15 | H22: =SUM(H4:H21) -> 38345.222 | I22: =SUM(I4:I21) -> 45282.732 | J22: =SUM(J4:J21) -> 40657.196 | ... AM22: =SUM(AM4:AM21) -> 117453.31
A23: Outflows
A24: Credit cards cleared | C24: =Inputs!B124 -> 1000 | D24: 0 | E24: 0 | F24: 0 | G24: 0 | H24: 0 | I24: 0 | J24: 0 | K24: 0 | L24: 0 | M24: 0 | N24: 0 | O24: 0 | P24: 0 | Q24: 0 | R24: 0 | S24: 0 | T24: 0 | U24: 0 | V24: 0 | W24: 0 | X24: 0 | Y24: 0 | Z24: 0 | AA24: 0 | AB24: 0 | AC24: 0 | AD24: 0 | AE24: 0 | AF24: 0 | AG24: 0 | AH24: 0 | AI24: 0 | AJ24: 0 | AK24: 0 | AL24: 0 | AM24: 0
A25: Home loan repayment | C25: =IF(AND(Inputs!$B$217<>"",C$2=Inputs!$B$217,Inputs!$B$12>0,Inputs!$B$15>0),MIN(IF(B$1=0,MthRem,12),MAX(Inputs!$G$15-IF(B$1=0,0,B$1*12+MthOff),0))*Inputs!$B$17+MAX(FV(Inputs!$B$16/12,C$1*12+MthOff,Inputs!$B$17,-Inputs!$B$15),0),IF(AND(Inputs!$B$217<>"",C$2>Inputs!$B$217,Inputs!$B$12>0),0,MIN(IF(B$1=0,MthRem,12),MAX(Inputs!$G$15-IF(B$1=0,0,B$1*12+MthOff),0))*Inputs!$B$17)) -> 2700 | D25: =IF(AND(Inputs!$B$217<>"",D$2=Inputs!$B$217,Inputs!$B$12>0,Inputs!$B$15>0),MIN(IF(C$1=0,MthRem,12),MAX(Inputs!$G$15-IF(C$1=0,0,C$1*12+MthOff),0))*Inputs!$B$17+MAX(FV(Inputs!$B$16/12,D$1*12+MthOff,Inputs!$B$17,-Inputs!$B$15),0),IF(AND(Inputs!$B$217<>"",D$2>Inputs!$B$217,Inputs!$B$12>0),0,MIN(IF(C$1=0,MthRem,12),MAX(Inputs!$G$15-IF(C$1=0,0,C$1*12+MthOff),0))*Inputs!$B$17)) -> 3600 | E25: =IF(AND(Inputs!$B$217<>"",E$2=Inputs!$B$217,Inputs!$B$12>0,Inputs!$B$15>0),MIN(IF(D$1=0,MthRem,12),MAX(Inputs!$G$15-IF(D$1=0,0,D$1*12+MthOff),0))*Inputs!$B$17+MAX(FV(Inputs!$B$16/12,E$1*12+MthOff,Inputs!$B$17,-Inputs!$B$15),0),IF(AND(Inputs!$B$217<>"",E$2>Inputs!$B$217,Inputs!$B$12>0),0,MIN(IF(D$1=0,MthRem,12),MAX(Inputs!$G$15-IF(D$1=0,0,D$1*12+MthOff),0))*Inputs!$B$17)) -> 3600 | F25: =IF(AND(Inputs!$B$217<>"",F$2=Inputs!$B$217,Inputs!$B$12>0,Inputs!$B$15>0),MIN(IF(E$1=0,MthRem,12),MAX(Inputs!$G$15-IF(E$1=0,0,E$1*12+MthOff),0))*Inputs!$B$17+MAX(FV(Inputs!$B$16/12,F$1*12+MthOff,Inputs!$B$17,-Inputs!$B$15),0),IF(AND(Inputs!$B$217<>"",F$2>Inputs!$B$217,Inputs!$B$12>0),0,MIN(IF(E$1=0,MthRem,12),MAX(Inputs!$G$15-IF(E$1=0,0,E$1*12+MthOff),0))*Inputs!$B$17)) -> 3600 | G25: =IF(AND(Inputs!$B$217<>"",G$2=Inputs!$B$217,Inputs!$B$12>0,Inputs!$B$15>0),MIN(IF(F$1=0,MthRem,12),MAX(Inputs!$G$15-IF(F$1=0,0,F$1*12+MthOff),0))*Inputs!$B$17+MAX(FV(Inputs!$B$16/12,G$1*12+MthOff,Inputs!$B$17,-Inputs!$B$15),0),IF(AND(Inputs!$B$217<>"",G$2>Inputs!$B$217,Inputs!$B$12>0),0,MIN(IF(F$1=0,MthRem,12),MAX(Inputs!$G$15-IF(F$1=0,0,F$1*12+MthOff),0))*Inputs!$B$17)) -> 42893.638 | H25: =IF(AND(Inputs!$B$217<>"",H$2=Inputs!$B$217,Inputs!$B$12>0,Inputs!$B$15>0),MIN(IF(G$1=0,MthRem,12),MAX(Inputs!$G$15-IF(G$1=0,0,G$1*12+MthOff),0))*Inputs!$B$17+MAX(FV(Inputs!$B$16/12,H$1*12+MthOff,Inputs!$B$17,-Inputs!$B$15),0),IF(AND(Inputs!$B$217<>"",H$2>Inputs!$B$217,Inputs!$B$12>0),0,MIN(IF(G$1=0,MthRem,12),MAX(Inputs!$G$15-IF(G$1=0,0,G$1*12+MthOff),0))*Inputs!$B$17)) -> 0 | I25: =IF(AND(Inputs!$B$217<>"",I$2=Inputs!$B$217,Inputs!$B$12>0,Inputs!$B$15>0),MIN(IF(H$1=0,MthRem,12),MAX(Inputs!$G$15-IF(H$1=0,0,H$1*12+MthOff),0))*Inputs!$B$17+MAX(FV(Inputs!$B$16/12,I$1*12+MthOff,Inputs!$B$17,-Inputs!$B$15),0),IF(AND(Inputs!$B$217<>"",I$2>Inputs!$B$217,Inputs!$B$12>0),0,MIN(IF(H$1=0,MthRem,12),MAX(Inputs!$G$15-IF(H$1=0,0,H$1*12+MthOff),0))*Inputs!$B$17)) -> 0 | J25: =IF(AND(Inputs!$B$217<>"",J$2=Inputs!$B$217,Inputs!$B$12>0,Inputs!$B$15>0),MIN(IF(I$1=0,MthRem,12),MAX(Inputs!$G$15-IF(I$1=0,0,I$1*12+MthOff),0))*Inputs!$B$17+MAX(FV(Inputs!$B$16/12,J$1*12+MthOff,Inputs!$B$17,-Inputs!$B$15),0),IF(AND(Inputs!$B$217<>"",J$2>Inputs!$B$217,Inputs!$B$12>0),0,MIN(IF(I$1=0,MthRem,12),MAX(Inputs!$G$15-IF(I$1=0,0,I$1*12+MthOff),0))*Inputs!$B$17)) -> 0 | ... AM25: =IF(AND(Inputs!$B$217<>"",AM$2=Inputs!$B$217,Inputs!$B$12>0,Inputs!$B$15>0),MIN(IF(AL$1=0,MthRem,12),MAX(Inputs!$G$15-IF(AL$1=0,0,AL$1*12+MthOff),0))*Inputs!$B$17+MAX(FV(Inputs!$B$16/12,AM$1*12+MthOff,Inputs!$B$17,-Inputs!$B$15),0),IF(AND(Inputs!$B$217<>"",AM$2>Inputs!$B$217,Inputs!$B$12>0),0,MIN(IF(AL$1=0,MthRem,12),MAX(Inputs!$G$15-IF(AL$1=0,0,AL$1*12+MthOff),0))*Inputs!$B$17)) -> 0
A26: Other asset loans repayments
A27: =TEXT(Inputs!$B$60,"") -> Sliema | C27: =MIN(IF(B$1=0,MthRem,12), MAX(Inputs!$G$127-IF(B$1=0,0,B$1*12+MthOff), 0))*Inputs!$B$129 -> 4500 | D27: =MIN(IF(C$1=0,MthRem,12), MAX(Inputs!$G$127-IF(C$1=0,0,C$1*12+MthOff), 0))*Inputs!$B$129 -> 6000 | E27: =MIN(IF(D$1=0,MthRem,12), MAX(Inputs!$G$127-IF(D$1=0,0,D$1*12+MthOff), 0))*Inputs!$B$129 -> 6000 | F27: =MIN(IF(E$1=0,MthRem,12), MAX(Inputs!$G$127-IF(E$1=0,0,E$1*12+MthOff), 0))*Inputs!$B$129 -> 6000 | G27: =MIN(IF(F$1=0,MthRem,12), MAX(Inputs!$G$127-IF(F$1=0,0,F$1*12+MthOff), 0))*Inputs!$B$129 -> 6000 | H27: =MIN(IF(G$1=0,MthRem,12), MAX(Inputs!$G$127-IF(G$1=0,0,G$1*12+MthOff), 0))*Inputs!$B$129 -> 6000 | I27: =MIN(IF(H$1=0,MthRem,12), MAX(Inputs!$G$127-IF(H$1=0,0,H$1*12+MthOff), 0))*Inputs!$B$129 -> 6000 | J27: =MIN(IF(I$1=0,MthRem,12), MAX(Inputs!$G$127-IF(I$1=0,0,I$1*12+MthOff), 0))*Inputs!$B$129 -> 6000 | ... AM27: =MIN(IF(AL$1=0,MthRem,12), MAX(Inputs!$G$127-IF(AL$1=0,0,AL$1*12+MthOff), 0))*Inputs!$B$129 -> 0
A28: =TEXT(Inputs!$B$65,"") -> Gzira | C28: =MIN(IF(B$1=0,MthRem,12), MAX(Inputs!$G$132-IF(B$1=0,0,B$1*12+MthOff), 0))*Inputs!$B$134 -> 1800 | D28: =MIN(IF(C$1=0,MthRem,12), MAX(Inputs!$G$132-IF(C$1=0,0,C$1*12+MthOff), 0))*Inputs!$B$134 -> 2400 | E28: =MIN(IF(D$1=0,MthRem,12), MAX(Inputs!$G$132-IF(D$1=0,0,D$1*12+MthOff), 0))*Inputs!$B$134 -> 2400 | F28: =MIN(IF(E$1=0,MthRem,12), MAX(Inputs!$G$132-IF(E$1=0,0,E$1*12+MthOff), 0))*Inputs!$B$134 -> 2223.4029 | G28: =MIN(IF(F$1=0,MthRem,12), MAX(Inputs!$G$132-IF(F$1=0,0,F$1*12+MthOff), 0))*Inputs!$B$134 -> 0 | H28: =MIN(IF(G$1=0,MthRem,12), MAX(Inputs!$G$132-IF(G$1=0,0,G$1*12+MthOff), 0))*Inputs!$B$134 -> 0 | I28: =MIN(IF(H$1=0,MthRem,12), MAX(Inputs!$G$132-IF(H$1=0,0,H$1*12+MthOff), 0))*Inputs!$B$134 -> 0 | J28: =MIN(IF(I$1=0,MthRem,12), MAX(Inputs!$G$132-IF(I$1=0,0,I$1*12+MthOff), 0))*Inputs!$B$134 -> 0 | ... AM28: =MIN(IF(AL$1=0,MthRem,12), MAX(Inputs!$G$132-IF(AL$1=0,0,AL$1*12+MthOff), 0))*Inputs!$B$134 -> 0
A29: =TEXT(Inputs!$B$70,"") -> Qormi | C29: =MIN(IF(B$1=0,MthRem,12), MAX(Inputs!$G$137-IF(B$1=0,0,B$1*12+MthOff), 0))*Inputs!$B$139 -> 2250 | D29: =MIN(IF(C$1=0,MthRem,12), MAX(Inputs!$G$137-IF(C$1=0,0,C$1*12+MthOff), 0))*Inputs!$B$139 -> 3000 | E29: =MIN(IF(D$1=0,MthRem,12), MAX(Inputs!$G$137-IF(D$1=0,0,D$1*12+MthOff), 0))*Inputs!$B$139 -> 3000 | F29: =MIN(IF(E$1=0,MthRem,12), MAX(Inputs!$G$137-IF(E$1=0,0,E$1*12+MthOff), 0))*Inputs!$B$139 -> 3000 | G29: =MIN(IF(F$1=0,MthRem,12), MAX(Inputs!$G$137-IF(F$1=0,0,F$1*12+MthOff), 0))*Inputs!$B$139 -> 3000 | H29: =MIN(IF(G$1=0,MthRem,12), MAX(Inputs!$G$137-IF(G$1=0,0,G$1*12+MthOff), 0))*Inputs!$B$139 -> 3000 | I29: =MIN(IF(H$1=0,MthRem,12), MAX(Inputs!$G$137-IF(H$1=0,0,H$1*12+MthOff), 0))*Inputs!$B$139 -> 46.859686 | J29: =MIN(IF(I$1=0,MthRem,12), MAX(Inputs!$G$137-IF(I$1=0,0,I$1*12+MthOff), 0))*Inputs!$B$139 -> 0 | ... AM29: =MIN(IF(AL$1=0,MthRem,12), MAX(Inputs!$G$137-IF(AL$1=0,0,AL$1*12+MthOff), 0))*Inputs!$B$139 -> 0
A30: =TEXT(Inputs!$B$75,"") -> Gudja | C30: =MIN(IF(B$1=0,MthRem,12), MAX(Inputs!$G$142-IF(B$1=0,0,B$1*12+MthOff), 0))*Inputs!$B$144 -> 720 | D30: =MIN(IF(C$1=0,MthRem,12), MAX(Inputs!$G$142-IF(C$1=0,0,C$1*12+MthOff), 0))*Inputs!$B$144 -> 960 | E30: =MIN(IF(D$1=0,MthRem,12), MAX(Inputs!$G$142-IF(D$1=0,0,D$1*12+MthOff), 0))*Inputs!$B$144 -> 960 | F30: =MIN(IF(E$1=0,MthRem,12), MAX(Inputs!$G$142-IF(E$1=0,0,E$1*12+MthOff), 0))*Inputs!$B$144 -> 960 | G30: =MIN(IF(F$1=0,MthRem,12), MAX(Inputs!$G$142-IF(F$1=0,0,F$1*12+MthOff), 0))*Inputs!$B$144 -> 960 | H30: =MIN(IF(G$1=0,MthRem,12), MAX(Inputs!$G$142-IF(G$1=0,0,G$1*12+MthOff), 0))*Inputs!$B$144 -> 368.25859 | I30: =MIN(IF(H$1=0,MthRem,12), MAX(Inputs!$G$142-IF(H$1=0,0,H$1*12+MthOff), 0))*Inputs!$B$144 -> 0 | J30: =MIN(IF(I$1=0,MthRem,12), MAX(Inputs!$G$142-IF(I$1=0,0,I$1*12+MthOff), 0))*Inputs!$B$144 -> 0 | ... AM30: =MIN(IF(AL$1=0,MthRem,12), MAX(Inputs!$G$142-IF(AL$1=0,0,AL$1*12+MthOff), 0))*Inputs!$B$144 -> 0
A31: =TEXT(Inputs!$B$80,"") -> Marsa | C31: =MIN(IF(B$1=0,MthRem,12), MAX(Inputs!$G$147-IF(B$1=0,0,B$1*12+MthOff), 0))*Inputs!$B$149 -> 1080 | D31: =MIN(IF(C$1=0,MthRem,12), MAX(Inputs!$G$147-IF(C$1=0,0,C$1*12+MthOff), 0))*Inputs!$B$149 -> 1440 | E31: =MIN(IF(D$1=0,MthRem,12), MAX(Inputs!$G$147-IF(D$1=0,0,D$1*12+MthOff), 0))*Inputs!$B$149 -> 1440 | F31: =MIN(IF(E$1=0,MthRem,12), MAX(Inputs!$G$147-IF(E$1=0,0,E$1*12+MthOff), 0))*Inputs!$B$149 -> 1440 | G31: =MIN(IF(F$1=0,MthRem,12), MAX(Inputs!$G$147-IF(F$1=0,0,F$1*12+MthOff), 0))*Inputs!$B$149 -> 1440 | H31: =MIN(IF(G$1=0,MthRem,12), MAX(Inputs!$G$147-IF(G$1=0,0,G$1*12+MthOff), 0))*Inputs!$B$149 -> 1440 | I31: =MIN(IF(H$1=0,MthRem,12), MAX(Inputs!$G$147-IF(H$1=0,0,H$1*12+MthOff), 0))*Inputs!$B$149 -> 1440 | J31: =MIN(IF(I$1=0,MthRem,12), MAX(Inputs!$G$147-IF(I$1=0,0,I$1*12+MthOff), 0))*Inputs!$B$149 -> 909.24881 | ... AM31: =MIN(IF(AL$1=0,MthRem,12), MAX(Inputs!$G$147-IF(AL$1=0,0,AL$1*12+MthOff), 0))*Inputs!$B$149 -> 0
A32: =TEXT(Inputs!$B$87,"") -> Jewelry | C32: =MIN(IF(B$1=0,MthRem,12), MAX(Inputs!$G$152-IF(B$1=0,0,B$1*12+MthOff), 0))*Inputs!$B$154 -> 675 | D32: =MIN(IF(C$1=0,MthRem,12), MAX(Inputs!$G$152-IF(C$1=0,0,C$1*12+MthOff), 0))*Inputs!$B$154 -> 900 | E32: =MIN(IF(D$1=0,MthRem,12), MAX(Inputs!$G$152-IF(D$1=0,0,D$1*12+MthOff), 0))*Inputs!$B$154 -> 900 | F32: =MIN(IF(E$1=0,MthRem,12), MAX(Inputs!$G$152-IF(E$1=0,0,E$1*12+MthOff), 0))*Inputs!$B$154 -> 138.60288 | G32: =MIN(IF(F$1=0,MthRem,12), MAX(Inputs!$G$152-IF(F$1=0,0,F$1*12+MthOff), 0))*Inputs!$B$154 -> 0 | H32: =MIN(IF(G$1=0,MthRem,12), MAX(Inputs!$G$152-IF(G$1=0,0,G$1*12+MthOff), 0))*Inputs!$B$154 -> 0 | I32: =MIN(IF(H$1=0,MthRem,12), MAX(Inputs!$G$152-IF(H$1=0,0,H$1*12+MthOff), 0))*Inputs!$B$154 -> 0 | J32: =MIN(IF(I$1=0,MthRem,12), MAX(Inputs!$G$152-IF(I$1=0,0,I$1*12+MthOff), 0))*Inputs!$B$154 -> 0 | ... AM32: =MIN(IF(AL$1=0,MthRem,12), MAX(Inputs!$G$152-IF(AL$1=0,0,AL$1*12+MthOff), 0))*Inputs!$B$154 -> 0
A33: =TEXT(Inputs!$B$92,"") -> Car | C33: =MIN(IF(B$1=0,MthRem,12), MAX(Inputs!$G$157-IF(B$1=0,0,B$1*12+MthOff), 0))*Inputs!$B$159 -> 774 | D33: =MIN(IF(C$1=0,MthRem,12), MAX(Inputs!$G$157-IF(C$1=0,0,C$1*12+MthOff), 0))*Inputs!$B$159 -> 1032 | E33: =MIN(IF(D$1=0,MthRem,12), MAX(Inputs!$G$157-IF(D$1=0,0,D$1*12+MthOff), 0))*Inputs!$B$159 -> 1032 | F33: =MIN(IF(E$1=0,MthRem,12), MAX(Inputs!$G$157-IF(E$1=0,0,E$1*12+MthOff), 0))*Inputs!$B$159 -> 1032 | G33: =MIN(IF(F$1=0,MthRem,12), MAX(Inputs!$G$157-IF(F$1=0,0,F$1*12+MthOff), 0))*Inputs!$B$159 -> 1032 | H33: =MIN(IF(G$1=0,MthRem,12), MAX(Inputs!$G$157-IF(G$1=0,0,G$1*12+MthOff), 0))*Inputs!$B$159 -> 1032 | I33: =MIN(IF(H$1=0,MthRem,12), MAX(Inputs!$G$157-IF(H$1=0,0,H$1*12+MthOff), 0))*Inputs!$B$159 -> 449.79405 | J33: =MIN(IF(I$1=0,MthRem,12), MAX(Inputs!$G$157-IF(I$1=0,0,I$1*12+MthOff), 0))*Inputs!$B$159 -> 0 | ... AM33: =MIN(IF(AL$1=0,MthRem,12), MAX(Inputs!$G$157-IF(AL$1=0,0,AL$1*12+MthOff), 0))*Inputs!$B$159 -> 0
A34: =TEXT(Inputs!$B$97,"") -> Painting | C34: =MIN(IF(B$1=0,MthRem,12), MAX(Inputs!$G$162-IF(B$1=0,0,B$1*12+MthOff), 0))*Inputs!$B$164 -> 1125 | D34: =MIN(IF(C$1=0,MthRem,12), MAX(Inputs!$G$162-IF(C$1=0,0,C$1*12+MthOff), 0))*Inputs!$B$164 -> 1500 | E34: =MIN(IF(D$1=0,MthRem,12), MAX(Inputs!$G$162-IF(D$1=0,0,D$1*12+MthOff), 0))*Inputs!$B$164 -> 1500 | F34: =MIN(IF(E$1=0,MthRem,12), MAX(Inputs!$G$162-IF(E$1=0,0,E$1*12+MthOff), 0))*Inputs!$B$164 -> 1500 | G34: =MIN(IF(F$1=0,MthRem,12), MAX(Inputs!$G$162-IF(F$1=0,0,F$1*12+MthOff), 0))*Inputs!$B$164 -> 1500 | H34: =MIN(IF(G$1=0,MthRem,12), MAX(Inputs!$G$162-IF(G$1=0,0,G$1*12+MthOff), 0))*Inputs!$B$164 -> 1500 | I34: =MIN(IF(H$1=0,MthRem,12), MAX(Inputs!$G$162-IF(H$1=0,0,H$1*12+MthOff), 0))*Inputs!$B$164 -> 23.429843 | J34: =MIN(IF(I$1=0,MthRem,12), MAX(Inputs!$G$162-IF(I$1=0,0,I$1*12+MthOff), 0))*Inputs!$B$164 -> 0 | ... AM34: =MIN(IF(AL$1=0,MthRem,12), MAX(Inputs!$G$162-IF(AL$1=0,0,AL$1*12+MthOff), 0))*Inputs!$B$164 -> 0
A35: =TEXT(Inputs!$B$102,"") -> Boat | C35: =MIN(IF(B$1=0,MthRem,12), MAX(Inputs!$G$167-IF(B$1=0,0,B$1*12+MthOff), 0))*Inputs!$B$169 -> 5616 | D35: =MIN(IF(C$1=0,MthRem,12), MAX(Inputs!$G$167-IF(C$1=0,0,C$1*12+MthOff), 0))*Inputs!$B$169 -> 7488 | E35: =MIN(IF(D$1=0,MthRem,12), MAX(Inputs!$G$167-IF(D$1=0,0,D$1*12+MthOff), 0))*Inputs!$B$169 -> 7488 | F35: =MIN(IF(E$1=0,MthRem,12), MAX(Inputs!$G$167-IF(E$1=0,0,E$1*12+MthOff), 0))*Inputs!$B$169 -> 7488 | G35: =MIN(IF(F$1=0,MthRem,12), MAX(Inputs!$G$167-IF(F$1=0,0,F$1*12+MthOff), 0))*Inputs!$B$169 -> 7488 | H35: =MIN(IF(G$1=0,MthRem,12), MAX(Inputs!$G$167-IF(G$1=0,0,G$1*12+MthOff), 0))*Inputs!$B$169 -> 7488 | I35: =MIN(IF(H$1=0,MthRem,12), MAX(Inputs!$G$167-IF(H$1=0,0,H$1*12+MthOff), 0))*Inputs!$B$169 -> 5289.2926 | J35: =MIN(IF(I$1=0,MthRem,12), MAX(Inputs!$G$167-IF(I$1=0,0,I$1*12+MthOff), 0))*Inputs!$B$169 -> 0 | ... AM35: =MIN(IF(AL$1=0,MthRem,12), MAX(Inputs!$G$167-IF(AL$1=0,0,AL$1*12+MthOff), 0))*Inputs!$B$169 -> 0
A36: =TEXT(Inputs!$B$107,"") -> Antiques | C36: =MIN(IF(B$1=0,MthRem,12), MAX(Inputs!$G$172-IF(B$1=0,0,B$1*12+MthOff), 0))*Inputs!$B$174 -> 990 | D36: =MIN(IF(C$1=0,MthRem,12), MAX(Inputs!$G$172-IF(C$1=0,0,C$1*12+MthOff), 0))*Inputs!$B$174 -> 1320 | E36: =MIN(IF(D$1=0,MthRem,12), MAX(Inputs!$G$172-IF(D$1=0,0,D$1*12+MthOff), 0))*Inputs!$B$174 -> 1320 | F36: =MIN(IF(E$1=0,MthRem,12), MAX(Inputs!$G$172-IF(E$1=0,0,E$1*12+MthOff), 0))*Inputs!$B$174 -> 349.16176 | G36: =MIN(IF(F$1=0,MthRem,12), MAX(Inputs!$G$172-IF(F$1=0,0,F$1*12+MthOff), 0))*Inputs!$B$174 -> 0 | H36: =MIN(IF(G$1=0,MthRem,12), MAX(Inputs!$G$172-IF(G$1=0,0,G$1*12+MthOff), 0))*Inputs!$B$174 -> 0 | I36: =MIN(IF(H$1=0,MthRem,12), MAX(Inputs!$G$172-IF(H$1=0,0,H$1*12+MthOff), 0))*Inputs!$B$174 -> 0 | J36: =MIN(IF(I$1=0,MthRem,12), MAX(Inputs!$G$172-IF(I$1=0,0,I$1*12+MthOff), 0))*Inputs!$B$174 -> 0 | ... AM36: =MIN(IF(AL$1=0,MthRem,12), MAX(Inputs!$G$172-IF(AL$1=0,0,AL$1*12+MthOff), 0))*Inputs!$B$174 -> 0
A37: Other loan repayment | C37: =MIN(IF(B$1=0,MthRem,12), MAX(Inputs!$G$177-IF(B$1=0,0,B$1*12+MthOff), 0))*Inputs!$B$179 -> 450 | D37: =MIN(IF(C$1=0,MthRem,12), MAX(Inputs!$G$177-IF(C$1=0,0,C$1*12+MthOff), 0))*Inputs!$B$179 -> 600 | E37: =MIN(IF(D$1=0,MthRem,12), MAX(Inputs!$G$177-IF(D$1=0,0,D$1*12+MthOff), 0))*Inputs!$B$179 -> 600 | F37: =MIN(IF(E$1=0,MthRem,12), MAX(Inputs!$G$177-IF(E$1=0,0,E$1*12+MthOff), 0))*Inputs!$B$179 -> 600 | G37: =MIN(IF(F$1=0,MthRem,12), MAX(Inputs!$G$177-IF(F$1=0,0,F$1*12+MthOff), 0))*Inputs!$B$179 -> 600 | H37: =MIN(IF(G$1=0,MthRem,12), MAX(Inputs!$G$177-IF(G$1=0,0,G$1*12+MthOff), 0))*Inputs!$B$179 -> 600 | I37: =MIN(IF(H$1=0,MthRem,12), MAX(Inputs!$G$177-IF(H$1=0,0,H$1*12+MthOff), 0))*Inputs!$B$179 -> 600 | J37: =MIN(IF(I$1=0,MthRem,12), MAX(Inputs!$G$177-IF(I$1=0,0,I$1*12+MthOff), 0))*Inputs!$B$179 -> 600 | ... AM37: =MIN(IF(AL$1=0,MthRem,12), MAX(Inputs!$G$177-IF(AL$1=0,0,AL$1*12+MthOff), 0))*Inputs!$B$179 -> 0
A38: Dependents cost
A39: =TEXT(Inputs!B33,"") -> John | C39: =IF(Inputs!$B$35>=C$1,Inputs!$B$34,0)*(1+inf)^B$1*ProRate -> 1500 | D39: =IF(Inputs!$B$35>=D$1,Inputs!$B$34,0)*(1+inf)^C$1 -> 2050 | E39: =IF(Inputs!$B$35>=E$1,Inputs!$B$34,0)*(1+inf)^D$1 -> 2101.25 | F39: =IF(Inputs!$B$35>=F$1,Inputs!$B$34,0)*(1+inf)^E$1 -> 0 | G39: =IF(Inputs!$B$35>=G$1,Inputs!$B$34,0)*(1+inf)^F$1 -> 0 | H39: =IF(Inputs!$B$35>=H$1,Inputs!$B$34,0)*(1+inf)^G$1 -> 0 | I39: =IF(Inputs!$B$35>=I$1,Inputs!$B$34,0)*(1+inf)^H$1 -> 0 | J39: =IF(Inputs!$B$35>=J$1,Inputs!$B$34,0)*(1+inf)^I$1 -> 0 | K39: =IF(Inputs!$B$35>=K$1,Inputs!$B$34,0)*(1+inf)^J$1 -> 0 | ... AM39: =IF(Inputs!$B$35>=AM$1,Inputs!$B$34,0)*(1+inf)^AL$1 -> 0
A40: =TEXT(Inputs!B38,"") -> Jack | C40: =IF(Inputs!$B$40>=C$1,Inputs!$B$39,0)*(1+inf)^B$1*ProRate -> 750 | D40: =IF(Inputs!$B$40>=D$1,Inputs!$B$39,0)*(1+inf)^C$1 -> 1025 | E40: =IF(Inputs!$B$40>=E$1,Inputs!$B$39,0)*(1+inf)^D$1 -> 1050.625 | F40: =IF(Inputs!$B$40>=F$1,Inputs!$B$39,0)*(1+inf)^E$1 -> 1076.8906 | G40: =IF(Inputs!$B$40>=G$1,Inputs!$B$39,0)*(1+inf)^F$1 -> 1103.8129 | H40: =IF(Inputs!$B$40>=H$1,Inputs!$B$39,0)*(1+inf)^G$1 -> 0 | I40: =IF(Inputs!$B$40>=I$1,Inputs!$B$39,0)*(1+inf)^H$1 -> 0 | J40: =IF(Inputs!$B$40>=J$1,Inputs!$B$39,0)*(1+inf)^I$1 -> 0 | K40: =IF(Inputs!$B$40>=K$1,Inputs!$B$39,0)*(1+inf)^J$1 -> 0 | ... AM40: =IF(Inputs!$B$40>=AM$1,Inputs!$B$39,0)*(1+inf)^AL$1 -> 0
...
